Workbook

Sheet Eventos
A1: CONTROLE DE EVENTOS E TREINAMENTOS/CURSOS FECHADOS
A2: 1. EVENTOS | F2: ANO:
A4: UNIDADE | B4: TÍTULO | C4: PERÍODO | D4: MÊS | E4: Nº DE PARTICIPANTES | F4: Nº DE RESPONDENTES | G4: % DE SATISFAÇÃO | H4: Número de respondentes X % satisfação | I4: Observações
H5: =IFERROR(G5*F5,"-") -> 0
H6: =IFERROR(G6*F6,"-") -> 0
H7: =IFERROR(G7*F7,"-") -> 0
H8: =IFERROR(G8*F8,"-") -> 0
H9: =IFERROR(G9*F9,"-") -> 0
H10: =IFERROR(G10*F10,"-") -> 0
H11: =IFERROR(G11*F11,"-") -> 0
H12: =IFERROR(G12*F12,"-") -> 0
H13: =IFERROR(G13*F13,"-") -> 0
H14: =IFERROR(G14*F14,"-") -> 0
H15: =IFERROR(G15*F15,"-") -> 0
H16: =IFERROR(G16*F16,"-") -> 0
... H51: =IFERROR(G51*F51,"-") -> 0
A53: FQ-08.39 (anexo à IT-07.01.03) - RA - revisão 00 de 02/08/21 - Página 1/5

Sheet Treinamentos Fechados
A1: CONTROLE DE EVENTOS E TREINAMENTOS/CURSOS FECHADOS
A2: 2. TREINAMENTOS/CURSOS FECHADOS | F2: =Eventos!F2 -> ANO:
A4: UNIDADE | B4: TÍTULO | C4: PERÍODO | D4: MÊS | E4: Nº DE PARTICIPANTES | F4: Nº DE RESPONDENTES | G4: % DE SATISFAÇÃO | H4: Número de respondentes X % satisfação | I4: Observações
H5: =IFERROR(G5*F5,"-") -> 0
H6: =IFERROR(G6*F6,"-") -> 0
H7: =IFERROR(G7*F7,"-") -> 0
H8: =IFERROR(G8*F8,"-") -> 0
H9: =IFERROR(G9*F9,"-") -> 0
H10: =IFERROR(G10*F10,"-") -> 0
H11: =IFERROR(G11*F11,"-") -> 0
H12: =IFERROR(G12*F12,"-") -> 0
H13: =IFERROR(G13*F13,"-") -> 0
H14: =IFERROR(G14*F14,"-") -> 0
H15: =IFERROR(G15*F15,"-") -> 0
H16: =IFERROR(G16*F16,"-") -> 0
... H51: =IFERROR(G51*F51,"-") -> 0
A53: FQ-08.39 (anexo à IT-07.01.03) - RA - revisão 00 de 02/08/21 - Página 2/5

Sheet I17, I19 e I24
A1: CÁLCULO DOS INDICADORES
A2: =Eventos!F2 -> ANO:
A4: I17 - Satisfação de eventos
A6: Unidade | B6: Número de respondentes X % satisfação | C6: Quantidade de respondentes | D6: I17 (%) | E6: Quantidade de participantes | F6: Janeiro | G6: Fevereiro | H6: Março | I6: Abril | J6: Maio | K6: Junho | L6: Julho | M6: Agosto | N6: Setembro | O6: Outubro | P6: Novembro | Q6: Dezembro | R6: Ano
A7: Cereal Chocotec | B7: =SUMIF(Eventos!A5:A51,"C.Chocotec",Eventos!H5:H51) -> 0 | C7: =SUMIF(Eventos!A5:A51,"C.Chocotec",Eventos!F5:F51) -> 0 | D7: =IFERROR(B7/C7,"---") -> --- | E7: =SUMIF(Eventos!A5:A51,"C.Chocotec",Eventos!E5:E51) -> 0 | F7: =IFERROR((SUMIFS(Eventos!H5:H51,Eventos!D5:D51,"Janeiro",Eventos!A5:A51,"C.Chocotec"))/(SUMIFS(Eventos!F5:F51,Eventos!D5:D51,"Janeiro",Eventos!A5:A51,"C.Chocotec")),"-") -> - | G7: =IFERROR((SUMIFS(Eventos!H5:H51,Eventos!D5:D51,"Fevereiro",Eventos!A5:A51,"C.Chocotec"))/(SUMIFS(Eventos!F5:F51,Eventos!D5:D51,"Fevereiro",Eventos!A5:A51,"C.Chocotec")),"-") -> - | H7: =IFERROR((SUMIFS(Eventos!H5:H51,Eventos!D5:D51,"Março",Eventos!A5:A51,"C.Chocotec"))/(SUMIFS(Eventos!F5:F51,Eventos!D5:D51,"Março",Eventos!A5:A51,"C.Chocotec")),"-") -> - | I7: =IFERROR((SUMIFS(Eventos!H5:H51,Eventos!D5:D51,"Abril",Eventos!A5:A51,"C.Chocotec"))/(SUMIFS(Eventos!F5:F51,Eventos!D5:D51,"Abril",Eventos!A5:A51,"C.Chocotec")),"-") -> - | J7: =IFERROR((SUMIFS(Eventos!H5:H51,Eventos!D5:D51,"Maio",Eventos!A5:A51,"C.Chocotec"))/(SUMIFS(Eventos!F5:F51,Eventos!D5:D51,"Maio",Eventos!A5:A51,"C.Chocotec")),"-") -> - | K7: =IFERROR((SUMIFS(Eventos!H5:H51,Eventos!D5:D51,"Junho",Eventos!A5:A51,"C.Chocotec"))/(SUMIFS(Eventos!F5:F51,Eventos!D5:D51,"Junho",Eventos!A5:A51,"C.Chocotec")),"-") -> - | L7: =IFERROR((SUMIFS(Eventos!H5:H51,Eventos!D5:D51,"Julho",Eventos!A5:A51,"C.Chocotec"))/(SUMIFS(Eventos!F5:F51,Eventos!D5:D51,"Julho",Eventos!A5:A51,"C.Chocotec")),"-") -> - | M7: =IFERROR((SUMIFS(Eventos!H5:H51,Eventos!D5:D51,"Agosto",Eventos!A5:A51,"C.Chocotec"))/(SUMIFS(Eventos!F5:F51,Eventos!D5:D51,"Agosto",Eventos!A5:A51,"C.Chocotec")),"-") -> - | N7: =IFERROR((SUMIFS(Eventos!H5:H51,Eventos!D5:D51,"Setembro",Eventos!A5:A51,"C.Chocotec"))/(SUMIFS(Eventos!F5:F51,Eventos!D5:D51,"Setembro",Eventos!A5:A51,"C.Chocotec")),"-") -> - | O7: =IFERROR((SUMIFS(Eventos!H5:H51,Eventos!D5:D51,"Outubro",Eventos!A5:A51,"C.Chocotec"))/(SUMIFS(Eventos!F5:F51,Eventos!D5:D51,"Outubro",Eventos!A5:A51,"C.Chocotec")),"-") -> - | P7: =IFERROR((SUMIFS(Eventos!H5:H51,Eventos!D5:D51,"Novembro",Eventos!A5:A51,"C.Chocotec"))/(SUMIFS(Eventos!F5:F51,Eventos!D5:D51,"Novembro",Eventos!A5:A51,"C.Chocotec")),"-") -> - | Q7: =IFERROR((SUMIFS(Eventos!H5:H51,Eventos!D5:D51,"Dezembro",Eventos!A5:A51,"C.Chocotec"))/(SUMIFS(Eventos!F5:F51,Eventos!D5:D51,"Dezembro",Eventos!A5:A51,"C.Chocotec")),"-") -> - | R7: =D7 -> ---
A8: CCQA | B8: =SUMIF(Eventos!A5:A51,"CCQA",Eventos!H5:H51) -> 0 | C8: =SUMIF(Eventos!A5:A51,"CCQA",Eventos!F5:F51) -> 0 | D8: =IFERROR(B8/C8,"---") -> --- | E8: =SUMIF(Eventos!A5:A51,"CCQA",Eventos!E5:E51) -> 0 | F8: =IFERROR((SUMIFS(Eventos!H5:H51,Eventos!D5:D51,"Janeiro",Eventos!A5:A51,"CCQA"))/(SUMIFS(Eventos!F5:F51,Eventos!D5:D51,"Janeiro",Eventos!A5:A51,"CCQA")),"-") -> - | G8: =IFERROR((SUMIFS(Eventos!H5:H51,Eventos!D5:D51,"Fevereiro",Eventos!A5:A51,"CCQA"))/(SUMIFS(Eventos!F5:F51,Eventos!D5:D51,"Fevereiro",Eventos!A5:A51,"CCQA")),"-") -> - | H8: =IFERROR((SUMIFS(Eventos!H5:H51,Eventos!D5:D51,"Março",Eventos!A5:A51,"CCQA"))/(SUMIFS(Eventos!F5:F51,Eventos!D5:D51,"Março",Eventos!A5:A51,"CCQA")),"-") -> - | I8: =IFERROR((SUMIFS(Eventos!H5:H51,Eventos!D5:D51,"Abril",Eventos!A5:A51,"CCQA"))/(SUMIFS(Eventos!F5:F51,Eventos!D5:D51,"Abril",Eventos!A5:A51,"CCQA")),"-") -> - | J8: =IFERROR((SUMIFS(Eventos!H5:H51,Eventos!D5:D51,"Maio",Eventos!A5:A51,"CCQA"))/(SUMIFS(Eventos!F5:F51,Eventos!D5:D51,"Maio",Eventos!A5:A51,"CCQA")),"-") -> - | K8: =IFERROR((SUMIFS(Eventos!H5:H51,Eventos!D5:D51,"Junho",Eventos!A5:A51,"CCQA"))/(SUMIFS(Eventos!F5:F51,Eventos!D5:D51,"Junho",Eventos!A5:A51,"CCQA")),"-") -> - | L8: =IFERROR((SUMIFS(Eventos!H5:H51,Eventos!D5:D51,"Julho",Eventos!A5:A51,"CCQA"))/(SUMIFS(Eventos!F5:F51,Eventos!D5:D51,"Julho",Eventos!A5:A51,"CCQA")),"-") -> - | M8: =IFERROR((SUMIFS(Eventos!H5:H51,Eventos!D5:D51,"Agosto",Eventos!A5:A51,"CCQA"))/(SUMIFS(Eventos!F5:F51,Eventos!D5:D51,"Agosto",Eventos!A5:A51,"CCQA")),"-") -> - | N8: =IFERROR((SUMIFS(Eventos!H5:H51,Eventos!D5:D51,"Setembro",Eventos!A5:A51,"CCQA"))/(SUMIFS(Eventos!F5:F51,Eventos!D5:D51,"Setembro",Eventos!A5:A51,"CCQA")),"-") -> - | O8: =IFERROR((SUMIFS(Eventos!H5:H51,Eventos!D5:D51,"Outubro",Eventos!A5:A51,"CCQA"))/(SUMIFS(Eventos!F5:F51,Eventos!D5:D51,"Outubro",Eventos!A5:A51,"CCQA")),"-") -> - | P8: =IFERROR((SUMIFS(Eventos!H5:H51,Eventos!D5:D51,"Novembro",Eventos!A5:A51,"CCQA"))/(SUMIFS(Eventos!F5:F51,Eventos!D5:D51,"Novembro",Eventos!A5:A51,"CCQA")),"-") -> - | Q8: =IFERROR((SUMIFS(Eventos!H5:H51,Eventos!D5:D51,"Dezembro",Eventos!A5:A51,"CCQA"))/(SUMIFS(Eventos!F5:F51,Eventos!D5:D51,"Dezembro",Eventos!A5:A51,"CCQA")),"-") -> - | R8: =D8 -> ---
A9: Cetea | B9: =SUMIF(Eventos!A5:A51,"Cetea",Eventos!H5:H51) -> 0 | C9: =SUMIF(Eventos!A5:A51,"Cetea",Eventos!F5:F51) -> 0 | D9: =IFERROR(B9/C9,"---") -> --- | E9: =SUMIF(Eventos!A5:A51,"Cetea",Eventos!E5:E51) -> 0 | F9: =IFERROR((SUMIFS(Eventos!H5:H51,Eventos!D5:D51,"Janeiro",Eventos!A5:A51,"Cetea"))/(SUMIFS(Eventos!F5:F51,Eventos!D5:D51,"Janeiro",Eventos!A5:A51,"Cetea")),"-") -> - | G9: =IFERROR((SUMIFS(Eventos!H5:H51,Eventos!D5:D51,"Fevereiro",Eventos!A5:A51,"Cetea"))/(SUMIFS(Eventos!F5:F51,Eventos!D5:D51,"Fevereiro",Eventos!A5:A51,"Cetea")),"-") -> - | H9: =IFERROR((SUMIFS(Eventos!H5:H51,Eventos!D5:D51,"Março",Eventos!A5:A51,"Cetea"))/(SUMIFS(Eventos!F5:F51,Eventos!D5:D51,"Março",Eventos!A5:A51,"Cetea")),"-") -> - | I9: =IFERROR((SUMIFS(Eventos!H5:H51,Eventos!D5:D51,"Abril",Eventos!A5:A51,"Cetea"))/(SUMIFS(Eventos!F5:F51,Eventos!D5:D51,"Abril",Eventos!A5:A51,"Cetea")),"-") -> - | J9: =IFERROR((SUMIFS(Eventos!H5:H51,Eventos!D5:D51,"Maio",Eventos!A5:A51,"Cetea"))/(SUMIFS(Eventos!F5:F51,Eventos!D5:D51,"Maio",Eventos!A5:A51,"Cetea")),"-") -> - | K9: =IFERROR((SUMIFS(Eventos!H5:H51,Eventos!D5:D51,"Junho",Eventos!A5:A51,"Cetea"))/(SUMIFS(Eventos!F5:F51,Eventos!D5:D51,"Junho",Eventos!A5:A51,"Cetea")),"-") -> - | L9: =IFERROR((SUMIFS(Eventos!H5:H51,Eventos!D5:D51,"Julho",Eventos!A5:A51,"Cetea"))/(SUMIFS(Eventos!F5:F51,Eventos!D5:D51,"Julho",Eventos!A5:A51,"Cetea")),"-") -> - | M9: =IFERROR((SUMIFS(Eventos!H5:H51,Eventos!D5:D51,"Agosto",Eventos!A5:A51,"Cetea"))/(SUMIFS(Eventos!F5:F51,Eventos!D5:D51,"Agosto",Eventos!A5:A51,"Cetea")),"-") -> - | N9: =IFERROR((SUMIFS(Eventos!H5:H51,Eventos!D5:D51,"Setembro",Eventos!A5:A51,"Cetea"))/(SUMIFS(Eventos!F5:F51,Eventos!D5:D51,"Setembro",Eventos!A5:A51,"Cetea")),"-") -> - | O9: =IFERROR((SUMIFS(Eventos!H5:H51,Eventos!D5:D51,"Outubro",Eventos!A5:A51,"Cetea"))/(SUMIFS(Eventos!F5:F51,Eventos!D5:D51,"Outubro",Eventos!A5:A51,"Cetea")),"-") -> - | P9: =IFERROR((SUMIFS(Eventos!H5:H51,Eventos!D5:D51,"Novembro",Eventos!A5:A51,"Cetea"))/(SUMIFS(Eventos!F5:F51,Eventos!D5:D51,"Novembro",Eventos!A5:A51,"Cetea")),"-") -> - | Q9: =IFERROR((SUMIFS(Eventos!H5:H51,Eventos!D5:D51,"Dezembro",Eventos!A5:A51,"Cetea"))/(SUMIFS(Eventos!F5:F51,Eventos!D5:D51,"Dezembro",Eventos!A5:A51,"Cetea")),"-") -> - | R9: =D9 -> ---
A10: CTC | B10: =SUMIF(Eventos!A5:A51,"CTC",Eventos!H5:H51) -> 0 | C10: =SUMIF(Eventos!A5:A51,"CTC",Eventos!F5:F51) -> 0 | D10: =IFERROR(B10/C10,"---") -> --- | E10: =SUMIF(Eventos!A5:A51,"CTC",Eventos!E5:E51) -> 0 | F10: =IFERROR((SUMIFS(Eventos!H5:H51,Eventos!D5:D51,"Janeiro",Eventos!A5:A51,"CTC"))/(SUMIFS(Eventos!F5:F51,Eventos!D5:D51,"Janeiro",Eventos!A5:A51,"CTC")),"-") -> - | G10: =IFERROR((SUMIFS(Eventos!H5:H51,Eventos!D5:D51,"Fevereiro",Eventos!A5:A51,"CTC"))/(SUMIFS(Eventos!F5:F51,Eventos!D5:D51,"Fevereiro",Eventos!A5:A51,"CTC")),"-") -> - | H10: =IFERROR((SUMIFS(Eventos!H5:H51,Eventos!D5:D51,"Março",Eventos!A5:A51,"CTC"))/(SUMIFS(Eventos!F5:F51,Eventos!D5:D51,"Março",Eventos!A5:A51,"CTC")),"-") -> - | I10: =IFERROR((SUMIFS(Eventos!H5:H51,Eventos!D5:D51,"Abril",Eventos!A5:A51,"CTC"))/(SUMIFS(Eventos!F5:F51,Eventos!D5:D51,"Abril",Eventos!A5:A51,"CTC")),"-") -> - | J10: =IFERROR((SUMIFS(Eventos!H5:H51,Eventos!D5:D51,"Maio",Eventos!A5:A51,"CTC"))/(SUMIFS(Eventos!F5:F51,Eventos!D5:D51,"Maio",Eventos!A5:A51,"CTC")),"-") -> - | K10: =IFERROR((SUMIFS(Eventos!H5:H51,Eventos!D5:D51,"Junho",Eventos!A5:A51,"CTC"))/(SUMIFS(Eventos!F5:F51,Eventos!D5:D51,"Junho",Eventos!A5:A51,"CTC")),"-") -> - | L10: =IFERROR((SUMIFS(Eventos!H5:H51,Eventos!D5:D51,"Julho",Eventos!A5:A51,"CTC"))/(SUMIFS(Eventos!F5:F51,Eventos!D5:D51,"Julho",Eventos!A5:A51,"CTC")),"-") -> - | M10: =IFERROR((SUMIFS(Eventos!H5:H51,Eventos!D5:D51,"Agosto",Eventos!A5:A51,"CTC"))/(SUMIFS(Eventos!F5:F51,Eventos!D5:D51,"Agosto",Eventos!A5:A51,"CTC")),"-") -> - | N10: =IFERROR((SUMIFS(Eventos!H5:H51,Eventos!D5:D51,"Setembro",Eventos!A5:A51,"CTC"))/(SUMIFS(Eventos!F5:F51,Eventos!D5:D51,"Setembro",Eventos!A5:A51,"CTC")),"-") -> - | O10: =IFERROR((SUMIFS(Eventos!H5:H51,Eventos!D5:D51,"Outubro",Eventos!A5:A51,"CTC"))/(SUMIFS(Eventos!F5:F51,Eventos!D5:D51,"Outubro",Eventos!A5:A51,"CTC")),"-") -> - | P10: =IFERROR((SUMIFS(Eventos!H5:H51,Eventos!D5:D51,"Novembro",Eventos!A5:A51,"CTC"))/(SUMIFS(Eventos!F5:F51,Eventos!D5:D51,"Novembro",Eventos!A5:A51,"CTC")),"-") -> - | Q10: =IFERROR((SUMIFS(Eventos!H5:H51,Eventos!D5:D51,"Dezembro",Eventos!A5:A51,"CTC"))/(SUMIFS(Eventos!F5:F51,Eventos!D5:D51,"Dezembro",Eventos!A5:A51,"CTC")),"-") -> - | R10: =D10 -> ---
A11: DG | B11: =SUMIF(Eventos!A5:A51,"DG",Eventos!H5:H51) -> 0 | C11: =SUMIF(Eventos!A5:A51,"DG",Eventos!F5:F51) -> 0 | D11: =IFERROR(B11/C11,"---") -> --- | E11: =SUMIF(Eventos!A5:A51,"DG",Eventos!E5:E51) -> 0 | F11: =IFERROR((SUMIFS(Eventos!H5:H51,Eventos!D5:D51,"Janeiro",Eventos!A5:A51,"DG"))/(SUMIFS(Eventos!F5:F51,Eventos!D5:D51,"Janeiro",Eventos!A5:A51,"DG")),"-") -> - | G11: =IFERROR((SUMIFS(Eventos!H5:H51,Eventos!D5:D51,"Fevereiro",Eventos!A5:A51,"DG"))/(SUMIFS(Eventos!F5:F51,Eventos!D5:D51,"Fevereiro",Eventos!A5:A51,"DG")),"-") -> - | H11: =IFERROR((SUMIFS(Eventos!H5:H51,Eventos!D5:D51,"Março",Eventos!A5:A51,"DG"))/(SUMIFS(Eventos!F5:F51,Eventos!D5:D51,"Março",Eventos!A5:A51,"DG")),"-") -> - | I11: =IFERROR((SUMIFS(Eventos!H5:H51,Eventos!D5:D51,"Abril",Eventos!A5:A51,"DG"))/(SUMIFS(Eventos!F5:F51,Eventos!D5:D51,"Abril",Eventos!A5:A51,"DG")),"-") -> - | J11: =IFERROR((SUMIFS(Eventos!H5:H51,Eventos!D5:D51,"Maio",Eventos!A5:A51,"DG"))/(SUMIFS(Eventos!F5:F51,Eventos!D5:D51,"Maio",Eventos!A5:A51,"DG")),"-") -> - | K11: =IFERROR((SUMIFS(Eventos!H5:H51,Eventos!D5:D51,"Junho",Eventos!A5:A51,"DG"))/(SUMIFS(Eventos!F5:F51,Eventos!D5:D51,"Junho",Eventos!A5:A51,"DG")),"-") -> - | L11: =IFERROR((SUMIFS(Eventos!H5:H51,Eventos!D5:D51,"Julho",Eventos!A5:A51,"DG"))/(SUMIFS(Eventos!F5:F51,Eventos!D5:D51,"Julho",Eventos!A5:A51,"DG")),"-") -> - | M11: =IFERROR((SUMIFS(Eventos!H5:H51,Eventos!D5:D51,"Agosto",Eventos!A5:A51,"DG"))/(SUMIFS(Eventos!F5:F51,Eventos!D5:D51,"Agosto",Eventos!A5:A51,"DG")),"-") -> - | N11: =IFERROR((SUMIFS(Eventos!H5:H51,Eventos!D5:D51,"Setembro",Eventos!A5:A51,"DG"))/(SUMIFS(Eventos!F5:F51,Eventos!D5:D51,"Setembro",Eventos!A5:A51,"DG")),"-") -> - | O11: =IFERROR((SUMIFS(Eventos!H5:H51,Eventos!D5:D51,"Outubro",Eventos!A5:A51,"DG"))/(SUMIFS(Eventos!F5:F51,Eventos!D5:D51,"Outubro",Eventos!A5:A51,"DG")),"-") -> - | P11: =IFERROR((SUMIFS(Eventos!H5:H51,Eventos!D5:D51,"Novembro",Eventos!A5:A51,"DG"))/(SUMIFS(Eventos!F5:F51,Eventos!D5:D51,"Novembro",Eventos!A5:A51,"DG")),"-") -> - | Q11: =IFERROR((SUMIFS(Eventos!H5:H51,Eventos!D5:D51,"Dezembro",Eventos!A5:A51,"DG"))/(SUMIFS(Eventos!F5:F51,Eventos!D5:D51,"Dezembro",Eventos!A5:A51,"DG")),"-") -> - | R11: =D11 -> ---
A12: Fruthotec | B12: =SUMIF(Eventos!A5:A51,"Fruthotec",Eventos!H5:H51) -> 0 | C12: =SUMIF(Eventos!A5:A51,"Fruthotec",Eventos!F5:F51) -> 0 | D12: =IFERROR(B12/C12,"---") -> --- | E12: =SUMIF(Eventos!A5:A51,"Fruthotec",Eventos!E5:E51) -> 0 | F12: =IFERROR((SUMIFS(Eventos!H5:H51,Eventos!D5:D51,"Janeiro",Eventos!A5:A51,"Fruthotec"))/(SUMIFS(Eventos!F5:F51,Eventos!D5:D51,"Janeiro",Eventos!A5:A51,"Fruthotec")),"-") -> - | G12: =IFERROR((SUMIFS(Eventos!H5:H51,Eventos!D5:D51,"Fevereiro",Eventos!A5:A51,"Fruthotec"))/(SUMIFS(Eventos!F5:F51,Eventos!D5:D51,"Fevereiro",Eventos!A5:A51,"Fruthotec")),"-") -> - | H12: =IFERROR((SUMIFS(Eventos!H5:H51,Eventos!D5:D51,"Março",Eventos!A5:A51,"Fruthotec"))/(SUMIFS(Eventos!F5:F51,Eventos!D5:D51,"Março",Eventos!A5:A51,"Fruthotec")),"-") -> - | I12: =IFERROR((SUMIFS(Eventos!H5:H51,Eventos!D5:D51,"Abril",Eventos!A5:A51,"Fruthotec"))/(SUMIFS(Eventos!F5:F51,Eventos!D5:D51,"Abril",Eventos!A5:A51,"Fruthotec")),"-") -> - | J12: =IFERROR((SUMIFS(Eventos!H5:H51,Eventos!D5:D51,"Maio",Eventos!A5:A51,"Fruthotec"))/(SUMIFS(Eventos!F5:F51,Eventos!D5:D51,"Maio",Eventos!A5:A51,"Fruthotec")),"-") -> - | K12: =IFERROR((SUMIFS(Eventos!H5:H51,Eventos!D5:D51,"Junho",Eventos!A5:A51,"Fruthotec"))/(SUMIFS(Eventos!F5:F51,Eventos!D5:D51,"Junho",Eventos!A5:A51,"Fruthotec")),"-") -> - | L12: =IFERROR((SUMIFS(Eventos!H5:H51,Eventos!D5:D51,"Julho",Eventos!A5:A51,"Fruthotec"))/(SUMIFS(Eventos!F5:F51,Eventos!D5:D51,"Julho",Eventos!A5:A51,"Fruthotec")),"-") -> - | M12: =IFERROR((SUMIFS(Eventos!H5:H51,Eventos!D5:D51,"Agosto",Eventos!A5:A51,"Fruthotec"))/(SUMIFS(Eventos!F5:F51,Eventos!D5:D51,"Agosto",Eventos!A5:A51,"Fruthotec")),"-") -> - | N12: =IFERROR((SUMIFS(Eventos!H5:H51,Eventos!D5:D51,"Setembro",Eventos!A5:A51,"Fruthotec"))/(SUMIFS(Eventos!F5:F51,Eventos!D5:D51,"Setembro",Eventos!A5:A51,"Fruthotec")),"-") -> - | O12: =IFERROR((SUMIFS(Eventos!H5:H51,Eventos!D5:D51,"Outubro",Eventos!A5:A51,"Fruthotec"))/(SUMIFS(Eventos!F5:F51,Eventos!D5:D51,"Outubro",Eventos!A5:A51,"Fruthotec")),"-") -> - | P12: =IFERROR((SUMIFS(Eventos!H5:H51,Eventos!D5:D51,"Novembro",Eventos!A5:A51,"Fruthotec"))/(SUMIFS(Eventos!F5:F51,Eventos!D5:D51,"Novembro",Eventos!A5:A51,"Fruthotec")),"-") -> - | Q12: =IFERROR((SUMIFS(Eventos!H5:H51,Eventos!D5:D51,"Dezembro",Eventos!A5:A51,"Fruthotec"))/(SUMIFS(Eventos!F5:F51,Eventos!D5:D51,"Dezembro",Eventos!A5:A51,"Fruthotec")),"-") -> - | R12: =D12 -> ---
A13: Tecnolat | B13: =SUMIF(Eventos!A5:A51,"Tecnolat",Eventos!H5:H51) -> 0 | C13: =SUMIF(Eventos!A5:A51,"Tecnolat",Eventos!F5:F51) -> 0 | D13: =IFERROR(B13/C13,"---") -> --- | E13: =SUMIF(Eventos!A5:A51,"Tecnolat",Eventos!E5:E51) -> 0 | F13: =IFERROR((SUMIFS(Eventos!H5:H51,Eventos!D5:D51,"Tecnolat",Eventos!A5:A51,"Cetea"))/(SUMIFS(Eventos!F5:F51,Eventos!D5:D51,"Janeiro",Eventos!A5:A51,"Tecnolat")),"-") -> - | G13: =IFERROR((SUMIFS(Eventos!H5:H51,Eventos!D5:D51,"Fevereiro",Eventos!A5:A51,"Tecnolat"))/(SUMIFS(Eventos!F5:F51,Eventos!D5:D51,"Fevereiro",Eventos!A5:A51,"Tecnolat")),"-") -> - | H13: =IFERROR((SUMIFS(Eventos!H5:H51,Eventos!D5:D51,"Março",Eventos!A5:A51,"Tecnolat"))/(SUMIFS(Eventos!F5:F51,Eventos!D5:D51,"Março",Eventos!A5:A51,"Tecnolat")),"-") -> - | I13: =IFERROR((SUMIFS(Eventos!H5:H51,Eventos!D5:D51,"Abril",Eventos!A5:A51,"Tecnolat"))/(SUMIFS(Eventos!F5:F51,Eventos!D5:D51,"Abril",Eventos!A5:A51,"Tecnolat")),"-") -> - | J13: =IFERROR((SUMIFS(Eventos!H5:H51,Eventos!D5:D51,"Maio",Eventos!A5:A51,"Tecnolat"))/(SUMIFS(Eventos!F5:F51,Eventos!D5:D51,"Maio",Eventos!A5:A51,"Tecnolat")),"-") -> - | K13: =IFERROR((SUMIFS(Eventos!H5:H51,Eventos!D5:D51,"Junho",Eventos!A5:A51,"Tecnolat"))/(SUMIFS(Eventos!F5:F51,Eventos!D5:D51,"Junho",Eventos!A5:A51,"Tecnolat")),"-") -> - | L13: =IFERROR((SUMIFS(Eventos!H5:H51,Eventos!D5:D51,"Julho",Eventos!A5:A51,"Tecnolat"))/(SUMIFS(Eventos!F5:F51,Eventos!D5:D51,"Julho",Eventos!A5:A51,"Tecnolat")),"-") -> - | M13: =IFERROR((SUMIFS(Eventos!H5:H51,Eventos!D5:D51,"Agosto",Eventos!A5:A51,"Tecnolat"))/(SUMIFS(Eventos!F5:F51,Eventos!D5:D51,"Agosto",Eventos!A5:A51,"Tecnolat")),"-") -> - | N13: =IFERROR((SUMIFS(Eventos!H5:H51,Eventos!D5:D51,"Setembro",Eventos!A5:A51,"Tecnolat"))/(SUMIFS(Eventos!F5:F51,Eventos!D5:D51,"Setembro",Eventos!A5:A51,"Tecnolat")),"-") -> - | O13: =IFERROR((SUMIFS(Eventos!H5:H51,Eventos!D5:D51,"Outubro",Eventos!A5:A51,"Tecnolat"))/(SUMIFS(Eventos!F5:F51,Eventos!D5:D51,"Outubro",Eventos!A5:A51,"Tecnolat")),"-") -> - | P13: =IFERROR((SUMIFS(Eventos!H5:H51,Eventos!D5:D51,"Novembro",Eventos!A5:A51,"Tecnolat"))/(SUMIFS(Eventos!F5:F51,Eventos!D5:D51,"Novembro",Eventos!A5:A51,"Tecnolat")),"-") -> - | Q13: =IFERROR((SUMIFS(Eventos!H5:H51,Eventos!D5:D51,"Dezembro",Eventos!A5:A51,"Tecnolat"))/(SUMIFS(Eventos!F5:F51,Eventos!D5:D51,"Dezembro",Eventos!A5:A51,"Tecnolat")),"-") -> - | R13: =D13 -> ---
A14: Ital | B14: =SUM(B7:B13) -> 0 | C14: =SUM(C7:C13) -> 0 | D14: =IFERROR(B14/C14,"---") -> --- | E14: =SUM(E7:E13) -> 0 | F14: =IFERROR((SUMIF(Eventos!D5:D51,"Janeiro",Eventos!H5:H51))/(SUMIF(Eventos!D5:D51,"Janeiro",Eventos!F5:F51)),"-") -> - | G14: =IFERROR((SUMIF(Eventos!D5:D51,"Fevereiro",Eventos!H5:H51))/(SUMIF(Eventos!D5:D51,"Fevereiro",Eventos!F5:F51)),"-") -> - | H14: =IFERROR((SUMIF(Eventos!D5:D51,"Março",Eventos!H5:H51))/(SUMIF(Eventos!D5:D51,"Março",Eventos!F5:F51)),"-") -> - | I14: =IFERROR((SUMIF(Eventos!D5:D51,"Abril",Eventos!H5:H51))/(SUMIF(Eventos!D5:D51,"Abril",Eventos!F5:F51)),"-") -> - | J14: =IFERROR((SUMIF(Eventos!D5:D51,"Maio",Eventos!H5:H51))/(SUMIF(Eventos!D5:D51,"Maio",Eventos!F5:F51)),"-") -> - | K14: =IFERROR((SUMIF(Eventos!D5:D51,"Junho",Eventos!H5:H51))/(SUMIF(Eventos!D5:D51,"Junho",Eventos!F5:F51)),"-") -> - | L14: =IFERROR((SUMIF(Eventos!D5:D51,"Julho",Eventos!H5:H51))/(SUMIF(Eventos!D5:D51,"Julho",Eventos!F5:F51)),"-") -> - | M14: =IFERROR((SUMIF(Eventos!D5:D51,"Agosto",Eventos!H5:H51))/(SUMIF(Eventos!D5:D51,"Agosto",Eventos!F5:F51)),"-") -> - | N14: =IFERROR((SUMIF(Eventos!D5:D51,"Setembro",Eventos!H5:H51))/(SUMIF(Eventos!D5:D51,"Setembro",Eventos!F5:F51)),"-") -> - | O14: =IFERROR((SUMIF(Eventos!D5:D51,"Outubro",Eventos!H5:H51))/(SUMIF(Eventos!D5:D51,"Outubro",Eventos!F5:F51)),"-") -> - | P14: =IFERROR((SUMIF(Eventos!D5:D51,"Novembro",Eventos!H5:H51))/(SUMIF(Eventos!D5:D51,"Novembro",Eventos!F5:F51)),"-") -> - | Q14: =IFERROR((SUMIF(Eventos!D5:D51,"Dezembro",Eventos!H5:H51))/(SUMIF(Eventos!D5:D51,"Dezembro",Eventos!F5:F51)),"-") -> - | R14: =D14 -> ---
A16: I19 - Satisfação de treinamento/curso in company
A18: Unidade | B18: Número de respondentes X % satisfação | C18: Quantidade de respondentes | D18: I19 (%) | E18: Quantidade de participantes | F18: Janeiro | G18: Fevereiro | H18: Março | I18: Abril | J18: Maio | K18: Junho | L18: Julho | M18: Agosto | N18: Setembro | O18: Outubro | P18: Novembro | Q18: Dezembro | R18: Ano
A19: Cereal Chocotec | B19: =SUMIF('Treinamentos Fechados'!A5:A51,"C.Chocotec",'Treinamentos Fechados'!H5:H51) -> 0 | C19: =SUMIF('Treinamentos Fechados'!A5:A51,"C.Chocotec",'Treinamentos Fechados'!F5:F51) -> 0 | D19: =IFERROR(B19/C19,"---") -> --- | E19: =SUMIF('Treinamentos Fechados'!A5:A51,"C.Chocotec",'Treinamentos Fechados'!E5:E51) -> 0 | F19: =IFERROR(SUMIFS('Treinamentos Fechados'!H5:H51,'Treinamentos Fechados'!D5:D51,"Janeiro",'Treinamentos Fechados'!A5:A51,"C.Chocotec")/(SUMIFS('Treinamentos Fechados'!F5:F51,'Treinamentos Fechados'!A5:A51,"C.Chocotec",'Treinamentos Fechados'!D5:D51,"Janeiro")),"-") -> - | G19: =IFERROR(SUMIFS('Treinamentos Fechados'!H5:H51,'Treinamentos Fechados'!D5:D51,"Fevereiro",'Treinamentos Fechados'!A5:A51,"C.Chocotec")/(SUMIFS('Treinamentos Fechados'!F5:F51,'Treinamentos Fechados'!A5:A51,"C.Chocotec",'Treinamentos Fechados'!D5:D51,"Fevereiro")),"-") -> - | H19: =IFERROR(SUMIFS('Treinamentos Fechados'!H5:H51,'Treinamentos Fechados'!D5:D51,"Março",'Treinamentos Fechados'!A5:A51,"C.Chocotec")/(SUMIFS('Treinamentos Fechados'!F5:F51,'Treinamentos Fechados'!A5:A51,"C.Chocotec",'Treinamentos Fechados'!D5:D51,"Março")),"-") -> - | I19: =IFERROR(SUMIFS('Treinamentos Fechados'!H5:H51,'Treinamentos Fechados'!D5:D51,"Abril",'Treinamentos Fechados'!A5:A51,"C.Chocotec")/(SUMIFS('Treinamentos Fechados'!F5:F51,'Treinamentos Fechados'!A5:A51,"C.Chocotec",'Treinamentos Fechados'!D5:D51,"Abril")),"-") -> - | J19: =IFERROR(SUMIFS('Treinamentos Fechados'!H5:H51,'Treinamentos Fechados'!D5:D51,"Maio",'Treinamentos Fechados'!A5:A51,"C.Chocotec")/(SUMIFS('Treinamentos Fechados'!F5:F51,'Treinamentos Fechados'!A5:A51,"C.Chocotec",'Treinamentos Fechados'!D5:D51,"Maio")),"-") -> - | K19: =IFERROR(SUMIFS('Treinamentos Fechados'!H5:H51,'Treinamentos Fechados'!D5:D51,"Junho",'Treinamentos Fechados'!A5:A51,"C.Chocotec")/(SUMIFS('Treinamentos Fechados'!F5:F51,'Treinamentos Fechados'!A5:A51,"C.Chocotec",'Treinamentos Fechados'!D5:D51,"Junho")),"-") -> - | L19: =IFERROR(SUMIFS('Treinamentos Fechados'!H5:H51,'Treinamentos Fechados'!D5:D51,"Julho",'Treinamentos Fechados'!A5:A51,"C.Chocotec")/(SUMIFS('Treinamentos Fechados'!F5:F51,'Treinamentos Fechados'!A5:A51,"C.Chocotec",'Treinamentos Fechados'!D5:D51,"Julho")),"-") -> - | M19: =IFERROR(SUMIFS('Treinamentos Fechados'!H5:H51,'Treinamentos Fechados'!D5:D51,"Agosto",'Treinamentos Fechados'!A5:A51,"C.Chocotec")/(SUMIFS('Treinamentos Fechados'!F5:F51,'Treinamentos Fechados'!A5:A51,"C.Chocotec",'Treinamentos Fechados'!D5:D51,"Agosto")),"-") -> - | N19: =IFERROR(SUMIFS('Treinamentos Fechados'!H5:H51,'Treinamentos Fechados'!D5:D51,"Setembro",'Treinamentos Fechados'!A5:A51,"C.Chocotec")/(SUMIFS('Treinamentos Fechados'!F5:F51,'Treinamentos Fechados'!A5:A51,"C.Chocotec",'Treinamentos Fechados'!D5:D51,"Setembro")),"-") -> - | O19: =IFERROR(SUMIFS('Treinamentos Fechados'!H5:H51,'Treinamentos Fechados'!D5:D51,"Outubro",'Treinamentos Fechados'!A5:A51,"C.Chocotec")/(SUMIFS('Treinamentos Fechados'!F5:F51,'Treinamentos Fechados'!A5:A51,"C.Chocotec",'Treinamentos Fechados'!D5:D51,"Outubro")),"-") -> - | P19: =IFERROR(SUMIFS('Treinamentos Fechados'!H5:H51,'Treinamentos Fechados'!D5:D51,"Novembro",'Treinamentos Fechados'!A5:A51,"C.Chocotec")/(SUMIFS('Treinamentos Fechados'!F5:F51,'Treinamentos Fechados'!A5:A51,"C.Chocotec",'Treinamentos Fechados'!D5:D51,"Novembro")),"-") -> - | Q19: =IFERROR(SUMIFS('Treinamentos Fechados'!H5:H51,'Treinamentos Fechados'!D5:D51,"Dezembro",'Treinamentos Fechados'!A5:A51,"C.Chocotec")/(SUMIFS('Treinamentos Fechados'!F5:F51,'Treinamentos Fechados'!A5:A51,"C.Chocotec",'Treinamentos Fechados'!D5:D51,"Dezembro")),"-") -> - | R19: =D19 -> ---
A20: CCQA | B20: =SUMIF('Treinamentos Fechados'!A5:A51,"CCQA",'Treinamentos Fechados'!H5:H51) -> 0 | C20: =SUMIF('Treinamentos Fechados'!A5:A51,"CCQA",'Treinamentos Fechados'!F5:F51) -> 0 | D20: =IFERROR(B20/C20,"---") -> --- | E20: =SUMIF('Treinamentos Fechados'!A5:A51,"CCQA",'Treinamentos Fechados'!E5:E51) -> 0 | F20: =IFERROR(SUMIFS('Treinamentos Fechados'!H5:H51,'Treinamentos Fechados'!D5:D51,"Janeiro",'Treinamentos Fechados'!A5:A51,"CCQA")/(SUMIFS('Treinamentos Fechados'!F5:F51,'Treinamentos Fechados'!A5:A51,"CCQA",'Treinamentos Fechados'!D5:D51,"Janeiro")),"-") -> - | G20: =IFERROR(SUMIFS('Treinamentos Fechados'!H5:H51,'Treinamentos Fechados'!D5:D51,"Fevereiro",'Treinamentos Fechados'!A5:A51,"CCQA")/(SUMIFS('Treinamentos Fechados'!F5:F51,'Treinamentos Fechados'!A5:A51,"CCQA",'Treinamentos Fechados'!D5:D51,"Fevereiro")),"-") -> - | H20: =IFERROR(SUMIFS('Treinamentos Fechados'!H5:H51,'Treinamentos Fechados'!D5:D51,"Março",'Treinamentos Fechados'!A5:A51,"CCQA")/(SUMIFS('Treinamentos Fechados'!F5:F51,'Treinamentos Fechados'!A5:A51,"CCQA",'Treinamentos Fechados'!D5:D51,"Março")),"-") -> - | I20: =IFERROR(SUMIFS('Treinamentos Fechados'!H5:H51,'Treinamentos Fechados'!D5:D51,"Abril",'Treinamentos Fechados'!A5:A51,"CCQA")/(SUMIFS('Treinamentos Fechados'!F5:F51,'Treinamentos Fechados'!A5:A51,"CCQA",'Treinamentos Fechados'!D5:D51,"Abril")),"-") -> - | J20: =IFERROR(SUMIFS('Treinamentos Fechados'!H5:H51,'Treinamentos Fechados'!D5:D51,"Maio",'Treinamentos Fechados'!A5:A51,"CCQA")/(SUMIFS('Treinamentos Fechados'!F5:F51,'Treinamentos Fechados'!A5:A51,"CCQA",'Treinamentos Fechados'!D5:D51,"Maio")),"-") -> - | K20: =IFERROR(SUMIFS('Treinamentos Fechados'!H5:H51,'Treinamentos Fechados'!D5:D51,"Junho",'Treinamentos Fechados'!A5:A51,"CCQA")/(SUMIFS('Treinamentos Fechados'!F5:F51,'Treinamentos Fechados'!A5:A51,"CCQA",'Treinamentos Fechados'!D5:D51,"Junho")),"-") -> - | L20: =IFERROR(SUMIFS('Treinamentos Fechados'!H5:H51,'Treinamentos Fechados'!D5:D51,"Julho",'Treinamentos Fechados'!A5:A51,"CCQA")/(SUMIFS('Treinamentos Fechados'!F5:F51,'Treinamentos Fechados'!A5:A51,"CCQA",'Treinamentos Fechados'!D5:D51,"Julho")),"-") -> - | M20: =IFERROR(SUMIFS('Treinamentos Fechados'!H5:H51,'Treinamentos Fechados'!D5:D51,"Agosto",'Treinamentos Fechados'!A5:A51,"CCQA")/(SUMIFS('Treinamentos Fechados'!F5:F51,'Treinamentos Fechados'!A5:A51,"CCQA",'Treinamentos Fechados'!D5:D51,"Agosto")),"-") -> - | N20: =IFERROR(SUMIFS('Treinamentos Fechados'!H5:H51,'Treinamentos Fechados'!D5:D51,"Setembro",'Treinamentos Fechados'!A5:A51,"CCQA")/(SUMIFS('Treinamentos Fechados'!F5:F51,'Treinamentos Fechados'!A5:A51,"CCQA",'Treinamentos Fechados'!D5:D51,"Setembro")),"-") -> - | O20: =IFERROR(SUMIFS('Treinamentos Fechados'!H5:H51,'Treinamentos Fechados'!D5:D51,"Outubro",'Treinamentos Fechados'!A5:A51,"CCQA")/(SUMIFS('Treinamentos Fechados'!F5:F51,'Treinamentos Fechados'!A5:A51,"CCQA",'Treinamentos Fechados'!D5:D51,"Outubro")),"-") -> - | P20: =IFERROR(SUMIFS('Treinamentos Fechados'!H5:H51,'Treinamentos Fechados'!D5:D51,"Novembro",'Treinamentos Fechados'!A5:A51,"CCQA")/(SUMIFS('Treinamentos Fechados'!F5:F51,'Treinamentos Fechados'!A5:A51,"CCQA",'Treinamentos Fechados'!D5:D51,"Novembro")),"-") -> - | Q20: =IFERROR(SUMIFS('Treinamentos Fechados'!H5:H51,'Treinamentos Fechados'!D5:D51,"Dezembro",'Treinamentos Fechados'!A5:A51,"CCQA")/(SUMIFS('Treinamentos Fechados'!F5:F51,'Treinamentos Fechados'!A5:A51,"CCQA",'Treinamentos Fechados'!D5:D51,"Dezembro")),"-") -> - | R20: =D20 -> ---
A21: Cetea | B21: =SUMIF('Treinamentos Fechados'!A5:A51,"Cetea",'Treinamentos Fechados'!H5:H51) -> 0 | C21: =SUMIF('Treinamentos Fechados'!A5:A51,"Cetea",'Treinamentos Fechados'!F5:F51) -> 0 | D21: =IFERROR(B21/C21,"---") -> --- | E21: =SUMIF('Treinamentos Fechados'!A5:A51,"Cetea",'Treinamentos Fechados'!E5:E51) -> 0 | F21: =IFERROR(SUMIFS('Treinamentos Fechados'!H5:H51,'Treinamentos Fechados'!D5:D51,"Janeiro",'Treinamentos Fechados'!A5:A51,"Cetea")/(SUMIFS('Treinamentos Fechados'!F5:F51,'Treinamentos Fechados'!A5:A51,"Cetea",'Treinamentos Fechados'!D5:D51,"Janeiro")),"-") -> - | G21: =IFERROR(SUMIFS('Treinamentos Fechados'!H5:H51,'Treinamentos Fechados'!D5:D51,"Fevereiro",'Treinamentos Fechados'!A5:A51,"Cetea")/(SUMIFS('Treinamentos Fechados'!F5:F51,'Treinamentos Fechados'!A5:A51,"Cetea",'Treinamentos Fechados'!D5:D51,"Fevereiro")),"-") -> - | H21: =IFERROR(SUMIFS('Treinamentos Fechados'!H5:H51,'Treinamentos Fechados'!D5:D51,"Março",'Treinamentos Fechados'!A5:A51,"Cetea")/(SUMIFS('Treinamentos Fechados'!F5:F51,'Treinamentos Fechados'!A5:A51,"Cetea",'Treinamentos Fechados'!D5:D51,"Março")),"-") -> - | I21: =IFERROR(SUMIFS('Treinamentos Fechados'!H5:H51,'Treinamentos Fechados'!D5:D51,"Abril",'Treinamentos Fechados'!A5:A51,"Cetea")/(SUMIFS('Treinamentos Fechados'!F5:F51,'Treinamentos Fechados'!A5:A51,"Cetea",'Treinamentos Fechados'!D5:D51,"Abril")),"-") -> - | J21: =IFERROR(SUMIFS('Treinamentos Fechados'!H5:H51,'Treinamentos Fechados'!D5:D51,"Maio",'Treinamentos Fechados'!A5:A51,"Cetea")/(SUMIFS('Treinamentos Fechados'!F5:F51,'Treinamentos Fechados'!A5:A51,"Cetea",'Treinamentos Fechados'!D5:D51,"Maio")),"-") -> - | K21: =IFERROR(SUMIFS('Treinamentos Fechados'!H5:H51,'Treinamentos Fechados'!D5:D51,"Junho",'Treinamentos Fechados'!A5:A51,"Cetea")/(SUMIFS('Treinamentos Fechados'!F5:F51,'Treinamentos Fechados'!A5:A51,"Cetea",'Treinamentos Fechados'!D5:D51,"Junho")),"-") -> - | L21: =IFERROR(SUMIFS('Treinamentos Fechados'!H5:H51,'Treinamentos Fechados'!D5:D51,"Julho",'Treinamentos Fechados'!A5:A51,"Cetea")/(SUMIFS('Treinamentos Fechados'!F5:F51,'Treinamentos Fechados'!A5:A51,"Cetea",'Treinamentos Fechados'!D5:D51,"Julho")),"-") -> - | M21: =IFERROR(SUMIFS('Treinamentos Fechados'!H5:H51,'Treinamentos Fechados'!D5:D51,"Agosto",'Treinamentos Fechados'!A5:A51,"Cetea")/(SUMIFS('Treinamentos Fechados'!F5:F51,'Treinamentos Fechados'!A5:A51,"Cetea",'Treinamentos Fechados'!D5:D51,"Agosto")),"-") -> - | N21: =IFERROR(SUMIFS('Treinamentos Fechados'!H5:H51,'Treinamentos Fechados'!D5:D51,"Setembro",'Treinamentos Fechados'!A5:A51,"Cetea")/(SUMIFS('Treinamentos Fechados'!F5:F51,'Treinamentos Fechados'!A5:A51,"Cetea",'Treinamentos Fechados'!D5:D51,"Setembro")),"-") -> - | O21: =IFERROR(SUMIFS('Treinamentos Fechados'!H5:H51,'Treinamentos Fechados'!D5:D51,"Outubro",'Treinamentos Fechados'!A5:A51,"Cetea")/(SUMIFS('Treinamentos Fechados'!F5:F51,'Treinamentos Fechados'!A5:A51,"Cetea",'Treinamentos Fechados'!D5:D51,"Outubro")),"-") -> - | P21: =IFERROR(SUMIFS('Treinamentos Fechados'!H5:H51,'Treinamentos Fechados'!D5:D51,"Novembro",'Treinamentos Fechados'!A5:A51,"Cetea")/(SUMIFS('Treinamentos Fechados'!F5:F51,'Treinamentos Fechados'!A5:A51,"Cetea",'Treinamentos Fechados'!D5:D51,"Novembro")),"-") -> - | Q21: =IFERROR(SUMIFS('Treinamentos Fechados'!H5:H51,'Treinamentos Fechados'!D5:D51,"Dezembro",'Treinamentos Fechados'!A5:A51,"Cetea")/(SUMIFS('Treinamentos Fechados'!F5:F51,'Treinamentos Fechados'!A5:A51,"Cetea",'Treinamentos Fechados'!D5:D51,"Dezembro")),"-") -> - | R21: =D21 -> ---
A22: CTC | B22: =SUMIF('Treinamentos Fechados'!A5:A51,"CTC",'Treinamentos Fechados'!H5:H51) -> 0 | C22: =SUMIF('Treinamentos Fechados'!A5:A51,"CTC",'Treinamentos Fechados'!F5:F51) -> 0 | D22: =IFERROR(B22/C22,"---") -> --- | E22: =SUMIF('Treinamentos Fechados'!A5:A51,"CTC",'Treinamentos Fechados'!E5:E51) -> 0 | F22: =IFERROR(SUMIFS('Treinamentos Fechados'!H5:H51,'Treinamentos Fechados'!D5:D51,"Janeiro",'Treinamentos Fechados'!A5:A51,"CTC")/(SUMIFS('Treinamentos Fechados'!F5:F51,'Treinamentos Fechados'!A5:A51,"CTC",'Treinamentos Fechados'!D5:D51,"Janeiro")),"-") -> - | G22: =IFERROR(SUMIFS('Treinamentos Fechados'!H5:H51,'Treinamentos Fechados'!D5:D51,"Fevereiro",'Treinamentos Fechados'!A5:A51,"CTC")/(SUMIFS('Treinamentos Fechados'!F5:F51,'Treinamentos Fechados'!A5:A51,"CTC",'Treinamentos Fechados'!D5:D51,"Fevereiro")),"-") -> - | H22: =IFERROR(SUMIFS('Treinamentos Fechados'!H5:H51,'Treinamentos Fechados'!D5:D51,"Março",'Treinamentos Fechados'!A5:A51,"CTC")/(SUMIFS('Treinamentos Fechados'!F5:F51,'Treinamentos Fechados'!A5:A51,"CTC",'Treinamentos Fechados'!D5:D51,"Março")),"-") -> - | I22: =IFERROR(SUMIFS('Treinamentos Fechados'!H5:H51,'Treinamentos Fechados'!D5:D51,"Abril",'Treinamentos Fechados'!A5:A51,"CTC")/(SUMIFS('Treinamentos Fechados'!F5:F51,'Treinamentos Fechados'!A5:A51,"CTC",'Treinamentos Fechados'!D5:D51,"Abril")),"-") -> - | J22: =IFERROR(SUMIFS('Treinamentos Fechados'!H5:H51,'Treinamentos Fechados'!D5:D51,"Maio",'Treinamentos Fechados'!A5:A51,"CTC")/(SUMIFS('Treinamentos Fechados'!F5:F51,'Treinamentos Fechados'!A5:A51,"CTC",'Treinamentos Fechados'!D5:D51,"Maio")),"-") -> - | K22: =IFERROR(SUMIFS('Treinamentos Fechados'!H5:H51,'Treinamentos Fechados'!D5:D51,"Junho",'Treinamentos Fechados'!A5:A51,"CTC")/(SUMIFS('Treinamentos Fechados'!F5:F51,'Treinamentos Fechados'!A5:A51,"CTC",'Treinamentos Fechados'!D5:D51,"Junho")),"-") -> - | L22: =IFERROR(SUMIFS('Treinamentos Fechados'!H5:H51,'Treinamentos Fechados'!D5:D51,"Julho",'Treinamentos Fechados'!A5:A51,"CTC")/(SUMIFS('Treinamentos Fechados'!F5:F51,'Treinamentos Fechados'!A5:A51,"CTC",'Treinamentos Fechados'!D5:D51,"Julho")),"-") -> - | M22: =IFERROR(SUMIFS('Treinamentos Fechados'!H5:H51,'Treinamentos Fechados'!D5:D51,"Agosto",'Treinamentos Fechados'!A5:A51,"CTC")/(SUMIFS('Treinamentos Fechados'!F5:F51,'Treinamentos Fechados'!A5:A51,"CTC",'Treinamentos Fechados'!D5:D51,"Agosto")),"-") -> - | N22: =IFERROR(SUMIFS('Treinamentos Fechados'!H5:H51,'Treinamentos Fechados'!D5:D51,"Setembro",'Treinamentos Fechados'!A5:A51,"CTC")/(SUMIFS('Treinamentos Fechados'!F5:F51,'Treinamentos Fechados'!A5:A51,"CTC",'Treinamentos Fechados'!D5:D51,"Setembro")),"-") -> - | O22: =IFERROR(SUMIFS('Treinamentos Fechados'!H5:H51,'Treinamentos Fechados'!D5:D51,"Outubro",'Treinamentos Fechados'!A5:A51,"CTC")/(SUMIFS('Treinamentos Fechados'!F5:F51,'Treinamentos Fechados'!A5:A51,"CTC",'Treinamentos Fechados'!D5:D51,"Outubro")),"-") -> - | P22: =IFERROR(SUMIFS('Treinamentos Fechados'!H5:H51,'Treinamentos Fechados'!D5:D51,"Novembro",'Treinamentos Fechados'!A5:A51,"CTC")/(SUMIFS('Treinamentos Fechados'!F5:F51,'Treinamentos Fechados'!A5:A51,"CTC",'Treinamentos Fechados'!D5:D51,"Novembro")),"-") -> - | Q22: =IFERROR(SUMIFS('Treinamentos Fechados'!H5:H51,'Treinamentos Fechados'!D5:D51,"Dezembro",'Treinamentos Fechados'!A5:A51,"CTC")/(SUMIFS('Treinamentos Fechados'!F5:F51,'Treinamentos Fechados'!A5:A51,"CTC",'Treinamentos Fechados'!D5:D51,"Dezembro")),"-") -> - | R22: =D22 -> ---
A23: DG | B23: =SUMIF('Treinamentos Fechados'!A5:A51,"DG",'Treinamentos Fechados'!H5:H51) -> 0 | C23: =SUMIF('Treinamentos Fechados'!A5:A51,"DG",'Treinamentos Fechados'!F5:F51) -> 0 | D23: =IFERROR(B23/C23,"---") -> --- | E23: =SUMIF('Treinamentos Fechados'!A5:A51,"DG",'Treinamentos Fechados'!E5:E51) -> 0 | F23: =IFERROR(SUMIFS('Treinamentos Fechados'!H5:H51,'Treinamentos Fechados'!D5:D51,"Janeiro",'Treinamentos Fechados'!A5:A51,"DG")/(SUMIFS('Treinamentos Fechados'!F5:F51,'Treinamentos Fechados'!A5:A51,"DG",'Treinamentos Fechados'!D5:D51,"Janeiro")),"-") -> - | G23: =IFERROR(SUMIFS('Treinamentos Fechados'!H5:H51,'Treinamentos Fechados'!D5:D51,"Fevereiro",'Treinamentos Fechados'!A5:A51,"DG")/(SUMIFS('Treinamentos Fechados'!F5:F51,'Treinamentos Fechados'!A5:A51,"DG",'Treinamentos Fechados'!D5:D51,"Fevereiro")),"-") -> - | H23: =IFERROR(SUMIFS('Treinamentos Fechados'!H5:H51,'Treinamentos Fechados'!D5:D51,"Março",'Treinamentos Fechados'!A5:A51,"DG")/(SUMIFS('Treinamentos Fechados'!F5:F51,'Treinamentos Fechados'!A5:A51,"DG",'Treinamentos Fechados'!D5:D51,"Março")),"-") -> - | I23: =IFERROR(SUMIFS('Treinamentos Fechados'!H5:H51,'Treinamentos Fechados'!D5:D51,"Abril",'Treinamentos Fechados'!A5:A51,"DG")/(SUMIFS('Treinamentos Fechados'!F5:F51,'Treinamentos Fechados'!A5:A51,"DG",'Treinamentos Fechados'!D5:D51,"Abril")),"-") -> - | J23: =IFERROR(SUMIFS('Treinamentos Fechados'!H5:H51,'Treinamentos Fechados'!D5:D51,"Maio",'Treinamentos Fechados'!A5:A51,"DG")/(SUMIFS('Treinamentos Fechados'!F5:F51,'Treinamentos Fechados'!A5:A51,"DG",'Treinamentos Fechados'!D5:D51,"Maio")),"-") -> - | K23: =IFERROR(SUMIFS('Treinamentos Fechados'!H5:H51,'Treinamentos Fechados'!D5:D51,"Junho",'Treinamentos Fechados'!A5:A51,"DG")/(SUMIFS('Treinamentos Fechados'!F5:F51,'Treinamentos Fechados'!A5:A51,"DG",'Treinamentos Fechados'!D5:D51,"Junho")),"-") -> - | L23: =IFERROR(SUMIFS('Treinamentos Fechados'!H5:H51,'Treinamentos Fechados'!D5:D51,"Julho",'Treinamentos Fechados'!A5:A51,"DG")/(SUMIFS('Treinamentos Fechados'!F5:F51,'Treinamentos Fechados'!A5:A51,"DG",'Treinamentos Fechados'!D5:D51,"Julho")),"-") -> - | M23: =IFERROR(SUMIFS('Treinamentos Fechados'!H5:H51,'Treinamentos Fechados'!D5:D51,"Agosto",'Treinamentos Fechados'!A5:A51,"DG")/(SUMIFS('Treinamentos Fechados'!F5:F51,'Treinamentos Fechados'!A5:A51,"DG",'Treinamentos Fechados'!D5:D51,"Agosto")),"-") -> - | N23: =IFERROR(SUMIFS('Treinamentos Fechados'!H5:H51,'Treinamentos Fechados'!D5:D51,"Setembro",'Treinamentos Fechados'!A5:A51,"DG")/(SUMIFS('Treinamentos Fechados'!F5:F51,'Treinamentos Fechados'!A5:A51,"DG",'Treinamentos Fechados'!D5:D51,"Setembro")),"-") -> - | O23: =IFERROR(SUMIFS('Treinamentos Fechados'!H5:H51,'Treinamentos Fechados'!D5:D51,"Outubro",'Treinamentos Fechados'!A5:A51,"DG")/(SUMIFS('Treinamentos Fechados'!F5:F51,'Treinamentos Fechados'!A5:A51,"DG",'Treinamentos Fechados'!D5:D51,"Outubro")),"-") -> - | P23: =IFERROR(SUMIFS('Treinamentos Fechados'!H5:H51,'Treinamentos Fechados'!D5:D51,"Novembro",'Treinamentos Fechados'!A5:A51,"DG")/(SUMIFS('Treinamentos Fechados'!F5:F51,'Treinamentos Fechados'!A5:A51,"DG",'Treinamentos Fechados'!D5:D51,"Novembro")),"-") -> - | Q23: =IFERROR(SUMIFS('Treinamentos Fechados'!H5:H51,'Treinamentos Fechados'!D5:D51,"Dezembro",'Treinamentos Fechados'!A5:A51,"DG")/(SUMIFS('Treinamentos Fechados'!F5:F51,'Treinamentos Fechados'!A5:A51,"DG",'Treinamentos Fechados'!D5:D51,"Dezembro")),"-") -> - | R23: =D23 -> ---
A24: Fruthotec | B24: =SUMIF('Treinamentos Fechados'!A5:A51,"Fruthotec",'Treinamentos Fechados'!H5:H51) -> 0 | C24: =SUMIF('Treinamentos Fechados'!A5:A51,"Fruthotec",'Treinamentos Fechados'!F5:F51) -> 0 | D24: =IFERROR(B24/C24,"---") -> --- | E24: =SUMIF('Treinamentos Fechados'!A5:A51,"Fruthotec",'Treinamentos Fechados'!E5:E51) -> 0 | F24: =IFERROR(SUMIFS('Treinamentos Fechados'!H5:H51,'Treinamentos Fechados'!D5:D51,"Janeiro",'Treinamentos Fechados'!A5:A51,"Fruthotec")/(SUMIFS('Treinamentos Fechados'!F5:F51,'Treinamentos Fechados'!A5:A51,"Fruthotec",'Treinamentos Fechados'!D5:D51,"Janeiro")),"-") -> - | G24: =IFERROR(SUMIFS('Treinamentos Fechados'!H5:H51,'Treinamentos Fechados'!D5:D51,"Fevereiro",'Treinamentos Fechados'!A5:A51,"Fruthotec")/(SUMIFS('Treinamentos Fechados'!F5:F51,'Treinamentos Fechados'!A5:A51,"Fruthotec",'Treinamentos Fechados'!D5:D51,"Fevereiro")),"-") -> - | H24: =IFERROR(SUMIFS('Treinamentos Fechados'!H5:H51,'Treinamentos Fechados'!D5:D51,"Março",'Treinamentos Fechados'!A5:A51,"Fruthotec")/(SUMIFS('Treinamentos Fechados'!F5:F51,'Treinamentos Fechados'!A5:A51,"Fruthotec",'Treinamentos Fechados'!D5:D51,"Março")),"-") -> - | I24: =IFERROR(SUMIFS('Treinamentos Fechados'!H5:H51,'Treinamentos Fechados'!D5:D51,"Abril",'Treinamentos Fechados'!A5:A51,"Fruthotec")/(SUMIFS('Treinamentos Fechados'!F5:F51,'Treinamentos Fechados'!A5:A51,"Fruthotec",'Treinamentos Fechados'!D5:D51,"Abril")),"-") -> - | J24: =IFERROR(SUMIFS('Treinamentos Fechados'!H5:H51,'Treinamentos Fechados'!D5:D51,"Maio",'Treinamentos Fechados'!A5:A51,"Fruthotec")/(SUMIFS('Treinamentos Fechados'!F5:F51,'Treinamentos Fechados'!A5:A51,"Fruthotec",'Treinamentos Fechados'!D5:D51,"Maio")),"-") -> - | K24: =IFERROR(SUMIFS('Treinamentos Fechados'!H5:H51,'Treinamentos Fechados'!D5:D51,"Junho",'Treinamentos Fechados'!A5:A51,"Fruthotec")/(SUMIFS('Treinamentos Fechados'!F5:F51,'Treinamentos Fechados'!A5:A51,"Fruthotec",'Treinamentos Fechados'!D5:D51,"Junho")),"-") -> - | L24: =IFERROR(SUMIFS('Treinamentos Fechados'!H5:H51,'Treinamentos Fechados'!D5:D51,"Julho",'Treinamentos Fechados'!A5:A51,"Fruthotec")/(SUMIFS('Treinamentos Fechados'!F5:F51,'Treinamentos Fechados'!A5:A51,"Fruthotec",'Treinamentos Fechados'!D5:D51,"Julho")),"-") -> - | M24: =IFERROR(SUMIFS('Treinamentos Fechados'!H5:H51,'Treinamentos Fechados'!D5:D51,"Agosto",'Treinamentos Fechados'!A5:A51,"Fruthotec")/(SUMIFS('Treinamentos Fechados'!F5:F51,'Treinamentos Fechados'!A5:A51,"Fruthotec",'Treinamentos Fechados'!D5:D51,"Agosto")),"-") -> - | N24: =IFERROR(SUMIFS('Treinamentos Fechados'!H5:H51,'Treinamentos Fechados'!D5:D51,"Setembro",'Treinamentos Fechados'!A5:A51,"Fruthotec")/(SUMIFS('Treinamentos Fechados'!F5:F51,'Treinamentos Fechados'!A5:A51,"Fruthotec",'Treinamentos Fechados'!D5:D51,"Setembro")),"-") -> - | O24: =IFERROR(SUMIFS('Treinamentos Fechados'!H5:H51,'Treinamentos Fechados'!D5:D51,"Outubro",'Treinamentos Fechados'!A5:A51,"Fruthotec")/(SUMIFS('Treinamentos Fechados'!F5:F51,'Treinamentos Fechados'!A5:A51,"Fruthotec",'Treinamentos Fechados'!D5:D51,"Outubro")),"-") -> - | P24: =IFERROR(SUMIFS('Treinamentos Fechados'!H5:H51,'Treinamentos Fechados'!D5:D51,"Novembro",'Treinamentos Fechados'!A5:A51,"Fruthotec")/(SUMIFS('Treinamentos Fechados'!F5:F51,'Treinamentos Fechados'!A5:A51,"Fruthotec",'Treinamentos Fechados'!D5:D51,"Novembro")),"-") -> - | Q24: =IFERROR(SUMIFS('Treinamentos Fechados'!H5:H51,'Treinamentos Fechados'!D5:D51,"Dezembro",'Treinamentos Fechados'!A5:A51,"Fruthotec")/(SUMIFS('Treinamentos Fechados'!F5:F51,'Treinamentos Fechados'!A5:A51,"Fruthotec",'Treinamentos Fechados'!D5:D51,"Dezembro")),"-") -> - | R24: =D24 -> ---
A25: Tecnolat | B25: =SUMIF('Treinamentos Fechados'!A5:A51,"Tecnolat",'Treinamentos Fechados'!H5:H51) -> 0 | C25: =SUMIF('Treinamentos Fechados'!A5:A51,"Tecnolat",'Treinamentos Fechados'!F5:F51) -> 0 | D25: =IFERROR(B25/C25,"---") -> --- | E25: =SUMIF('Treinamentos Fechados'!A5:A51,"Tecnolat",'Treinamentos Fechados'!E5:E51) -> 0 | F25: =IFERROR(SUMIFS('Treinamentos Fechados'!H5:H51,'Treinamentos Fechados'!D5:D51,"Janeiro",'Treinamentos Fechados'!A5:A51,"Tecnolat")/(SUMIFS('Treinamentos Fechados'!F5:F51,'Treinamentos Fechados'!A5:A51,"Tecnolat",'Treinamentos Fechados'!D5:D51,"Janeiro")),"-") -> - | G25: =IFERROR(SUMIFS('Treinamentos Fechados'!H5:H51,'Treinamentos Fechados'!D5:D51,"Fevereiro",'Treinamentos Fechados'!A5:A51,"Tecnolat")/(SUMIFS('Treinamentos Fechados'!F5:F51,'Treinamentos Fechados'!A5:A51,"Tecnolat",'Treinamentos Fechados'!D5:D51,"Fevereiro")),"-") -> - | H25: =IFERROR(SUMIFS('Treinamentos Fechados'!H5:H51,'Treinamentos Fechados'!D5:D51,"Março",'Treinamentos Fechados'!A5:A51,"Tecnolat")/(SUMIFS('Treinamentos Fechados'!F5:F51,'Treinamentos Fechados'!A5:A51,"Tecnolat",'Treinamentos Fechados'!D5:D51,"Março")),"-") -> - | I25: =IFERROR(SUMIFS('Treinamentos Fechados'!H5:H51,'Treinamentos Fechados'!D5:D51,"Abril",'Treinamentos Fechados'!A5:A51,"Tecnolat")/(SUMIFS('Treinamentos Fechados'!F5:F51,'Treinamentos Fechados'!A5:A51,"Tecnolat",'Treinamentos Fechados'!D5:D51,"Abril")),"-") -> - | J25: =IFERROR(SUMIFS('Treinamentos Fechados'!H5:H51,'Treinamentos Fechados'!D5:D51,"Maio",'Treinamentos Fechados'!A5:A51,"Tecnolat")/(SUMIFS('Treinamentos Fechados'!F5:F51,'Treinamentos Fechados'!A5:A51,"Tecnolat",'Treinamentos Fechados'!D5:D51,"Maio")),"-") -> - | K25: =IFERROR(SUMIFS('Treinamentos Fechados'!H5:H51,'Treinamentos Fechados'!D5:D51,"Junho",'Treinamentos Fechados'!A5:A51,"Tecnolat")/(SUMIFS('Treinamentos Fechados'!F5:F51,'Treinamentos Fechados'!A5:A51,"Tecnolat",'Treinamentos Fechados'!D5:D51,"Junho")),"-") -> - | L25: =IFERROR(SUMIFS('Treinamentos Fechados'!H5:H51,'Treinamentos Fechados'!D5:D51,"Julho",'Treinamentos Fechados'!A5:A51,"Tecnolat")/(SUMIFS('Treinamentos Fechados'!F5:F51,'Treinamentos Fechados'!A5:A51,"Tecnolat",'Treinamentos Fechados'!D5:D51,"Julho")),"-") -> - | M25: =IFERROR(SUMIFS('Treinamentos Fechados'!H5:H51,'Treinamentos Fechados'!D5:D51,"Agosto",'Treinamentos Fechados'!A5:A51,"Tecnolat")/(SUMIFS('Treinamentos Fechados'!F5:F51,'Treinamentos Fechados'!A5:A51,"Tecnolat",'Treinamentos Fechados'!D5:D51,"Agosto")),"-") -> - | N25: =IFERROR(SUMIFS('Treinamentos Fechados'!H5:H51,'Treinamentos Fechados'!D5:D51,"Setembro",'Treinamentos Fechados'!A5:A51,"Tecnolat")/(SUMIFS('Treinamentos Fechados'!F5:F51,'Treinamentos Fechados'!A5:A51,"Tecnolat",'Treinamentos Fechados'!D5:D51,"Setembro")),"-") -> - | O25: =IFERROR(SUMIFS('Treinamentos Fechados'!H5:H51,'Treinamentos Fechados'!D5:D51,"Outubro",'Treinamentos Fechados'!A5:A51,"Tecnolat")/(SUMIFS('Treinamentos Fechados'!F5:F51,'Treinamentos Fechados'!A5:A51,"Tecnolat",'Treinamentos Fechados'!D5:D51,"Outubro")),"-") -> - | P25: =IFERROR(SUMIFS('Treinamentos Fechados'!H5:H51,'Treinamentos Fechados'!D5:D51,"Novembro",'Treinamentos Fechados'!A5:A51,"Tecnolat")/(SUMIFS('Treinamentos Fechados'!F5:F51,'Treinamentos Fechados'!A5:A51,"Tecnolat",'Treinamentos Fechados'!D5:D51,"Novembro")),"-") -> - | Q25: =IFERROR(SUMIFS('Treinamentos Fechados'!H5:H51,'Treinamentos Fechados'!D5:D51,"Dezembro",'Treinamentos Fechados'!A5:A51,"Tecnolat")/(SUMIFS('Treinamentos Fechados'!F5:F51,'Treinamentos Fechados'!A5:A51,"Tecnolat",'Treinamentos Fechados'!D5:D51,"Dezembro")),"-") -> - | R25: =D25 -> ---
A26: Ital | B26: =SUM(B19:B25) -> 0 | C26: =SUM(C19:C25) -> 0 | D26: =IFERROR(B26/C26,"---") -> --- | E26: =SUM(E19:E25) -> 0 | F26: =IFERROR(SUMIF('Treinamentos Fechados'!D5:D51,"Janeiro",'Treinamentos Fechados'!H5:H51)/(SUMIF('Treinamentos Fechados'!D5:D51,"Janeiro",'Treinamentos Fechados'!F5:F51)),"-") -> - | G26: =IFERROR(SUMIF('Treinamentos Fechados'!D5:D51,"Fevereiro",'Treinamentos Fechados'!H5:H51)/(SUMIF('Treinamentos Fechados'!D5:D51,"Fevereiro",'Treinamentos Fechados'!F5:F51)),"-") -> - | H26: =IFERROR(SUMIF('Treinamentos Fechados'!D5:D51,"Março",'Treinamentos Fechados'!H5:H51)/(SUMIF('Treinamentos Fechados'!D5:D51,"Março",'Treinamentos Fechados'!F5:F51)),"-") -> - | I26: =IFERROR(SUMIF('Treinamentos Fechados'!D5:D51,"Abril",'Treinamentos Fechados'!H5:H51)/(SUMIF('Treinamentos Fechados'!D5:D51,"Abril",'Treinamentos Fechados'!F5:F51)),"-") -> - | J26: =IFERROR(SUMIF('Treinamentos Fechados'!D5:D51,"Maio",'Treinamentos Fechados'!H5:H51)/(SUMIF('Treinamentos Fechados'!D5:D51,"Maio",'Treinamentos Fechados'!F5:F51)),"-") -> - | K26: =IFERROR(SUMIF('Treinamentos Fechados'!D5:D51,"Junho",'Treinamentos Fechados'!H5:H51)/(SUMIF('Treinamentos Fechados'!D5:D51,"Junho",'Treinamentos Fechados'!F5:F51)),"-") -> - | L26: =IFERROR(SUMIF('Treinamentos Fechados'!D5:D51,"Julho",'Treinamentos Fechados'!H5:H51)/(SUMIF('Treinamentos Fechados'!D5:D51,"Julho",'Treinamentos Fechados'!F5:F51)),"-") -> - | M26: =IFERROR(SUMIF('Treinamentos Fechados'!D5:D51,"Agosto",'Treinamentos Fechados'!H5:H51)/(SUMIF('Treinamentos Fechados'!D5:D51,"Agosto",'Treinamentos Fechados'!F5:F51)),"-") -> - | N26: =IFERROR(SUMIF('Treinamentos Fechados'!D5:D51,"Setembro",'Treinamentos Fechados'!H5:H51)/(SUMIF('Treinamentos Fechados'!D5:D51,"Setembro",'Treinamentos Fechados'!F5:F51)),"-") -> - | O26: =IFERROR(SUMIF('Treinamentos Fechados'!D5:D51,"Outubro",'Treinamentos Fechados'!H5:H51)/(SUMIF('Treinamentos Fechados'!D5:D51,"Outubro",'Treinamentos Fechados'!F5:F51)),"-") -> - | P26: =IFERROR(SUMIF('Treinamentos Fechados'!D5:D51,"Novembro",'Treinamentos Fechados'!H5:H51)/(SUMIF('Treinamentos Fechados'!D5:D51,"Novembro",'Treinamentos Fechados'!F5:F51)),"-") -> - | Q26: =IFERROR(SUMIF('Treinamentos Fechados'!D5:D51,"Dezembro",'Treinamentos Fechados'!H5:H51)/(SUMIF('Treinamentos Fechados'!D5:D51,"Dezembro",'Treinamentos Fechados'!F5:F51)),"-") -> - | R26: =D26 -> ---
A28: I24 - Eventos realizados
A30: Unidade | B30: Janeiro | C30: Fevereiro | D30: Março | E30: Abril | F30: Maio | G30: Junho | H30: Julho | I30: Agosto | J30: Setembro | K30: Outubro | L30: Novembro | M30: Dezembro | N30: Ano
A31: Cereal Chocotec | B31: =COUNTIFS(Eventos!A5:A51,"C.Chocotec",Eventos!D5:D51,"Janeiro") -> 0 | C31: =COUNTIFS(Eventos!A5:A51,"C.Chocotec",Eventos!D5:D51,"Fevereiro") -> 0 | D31: =COUNTIFS(Eventos!A5:A51,"C.Chocotec",Eventos!D5:D51,"Março") -> 0 | E31: =COUNTIFS(Eventos!A5:A51,"C.Chocotec",Eventos!D5:D51,"Abril") -> 0 | F31: =COUNTIFS(Eventos!A5:A51,"C.Chocotec",Eventos!D5:D51,"Maio") -> 0 | G31: =COUNTIFS(Eventos!A5:A51,"C.Chocotec",Eventos!D5:D51,"Junho") -> 0 | H31: =COUNTIFS(Eventos!A5:A51,"C.Chocotec",Eventos!D5:D51,"Julho") -> 0 | I31: =COUNTIFS(Eventos!A5:A51,"C.Chocotec",Eventos!D5:D51,"Agosto") -> 0 | J31: =COUNTIFS(Eventos!A5:A51,"C.Chocotec",Eventos!D5:D51,"Setembro") -> 0 | K31: =COUNTIFS(Eventos!A5:A51,"C.Chocotec",Eventos!D5:D51,"Outubro") -> 0 | L31: =COUNTIFS(Eventos!A5:A51,"C.Chocotec",Eventos!D5:D51,"Novembro") -> 0 | M31: =COUNTIFS(Eventos!A5:A51,"C.Chocotec",Eventos!D5:D51,"Dezembro") -> 0 | N31: =COUNTIF(Eventos!A5:A51,"C.Chocotec") -> 0
A32: CCQA | B32: =COUNTIFS(Eventos!A5:A51,"CCQA",Eventos!D5:D51,"Janeiro") -> 0 | C32: =COUNTIFS(Eventos!A5:A51,"CCQA",Eventos!D5:D51,"Fevereiro") -> 0 | D32: =COUNTIFS(Eventos!A5:A51,"CCQA",Eventos!D5:D51,"Março") -> 0 | E32: =COUNTIFS(Eventos!A5:A51,"CCQA",Eventos!D5:D51,"Abril") -> 0 | F32: =COUNTIFS(Eventos!A5:A51,"CCQA",Eventos!D5:D51,"Maio") -> 0 | G32: =COUNTIFS(Eventos!A5:A51,"CCQA",Eventos!D5:D51,"Junho") -> 0 | H32: =COUNTIFS(Eventos!A5:A51,"CCQA",Eventos!D5:D51,"Julho") -> 0 | I32: =COUNTIFS(Eventos!A5:A51,"CCQA",Eventos!D5:D51,"Agosto") -> 0 | J32: =COUNTIFS(Eventos!A5:A51,"CCQA",Eventos!D5:D51,"Setembro") -> 0 | K32: =COUNTIFS(Eventos!A5:A51,"CCQA",Eventos!D5:D51,"Outubro") -> 0 | L32: =COUNTIFS(Eventos!A5:A51,"CCQA",Eventos!D5:D51,"Novembro") -> 0 | M32: =COUNTIFS(Eventos!A5:A51,"CCQA",Eventos!D5:D51,"Dezembro") -> 0 | N32: =COUNTIF(Eventos!A5:A51,"CCQA") -> 0
A33: Cetea | B33: =COUNTIFS(Eventos!A5:A51,"Cetea",Eventos!D5:D51,"Janeiro") -> 0 | C33: =COUNTIFS(Eventos!A5:A51,"Cetea",Eventos!D5:D51,"Fevereiro") -> 0 | D33: =COUNTIFS(Eventos!A5:A51,"Cetea",Eventos!D5:D51,"Março") -> 0 | E33: =COUNTIFS(Eventos!A5:A51,"Cetea",Eventos!D5:D51,"Abril") -> 0 | F33: =COUNTIFS(Eventos!A5:A51,"Cetea",Eventos!D5:D51,"Maio") -> 0 | G33: =COUNTIFS(Eventos!A5:A51,"Cetea",Eventos!D5:D51,"Junho") -> 0 | H33: =COUNTIFS(Eventos!A5:A51,"Cetea",Eventos!D5:D51,"Julho") -> 0 | I33: =COUNTIFS(Eventos!A5:A51,"Cetea",Eventos!D5:D51,"Agosto") -> 0 | J33: =COUNTIFS(Eventos!A5:A51,"Cetea",Eventos!D5:D51,"Setembro") -> 0 | K33: =COUNTIFS(Eventos!A5:A51,"Cetea",Eventos!D5:D51,"Outubro") -> 0 | L33: =COUNTIFS(Eventos!A5:A51,"Cetea",Eventos!D5:D51,"Novembro") -> 0 | M33: =COUNTIFS(Eventos!A5:A51,"Cetea",Eventos!D5:D51,"Dezembro") -> 0 | N33: =COUNTIF(Eventos!A5:A51,"Cetea") -> 0
A34: CTC | B34: =COUNTIFS(Eventos!A5:A51,"CTC",Eventos!D5:D51,"Janeiro") -> 0 | C34: =COUNTIFS(Eventos!A5:A51,"CTC",Eventos!D5:D51,"Fevereiro") -> 0 | D34: =COUNTIFS(Eventos!A5:A51,"CTC",Eventos!D5:D51,"Março") -> 0 | E34: =COUNTIFS(Eventos!A5:A51,"CTC",Eventos!D5:D51,"Abril") -> 0 | F34: =COUNTIFS(Eventos!A5:A51,"CTC",Eventos!D5:D51,"Maio") -> 0 | G34: =COUNTIFS(Eventos!A5:A51,"CTC",Eventos!D5:D51,"Junho") -> 0 | H34: =COUNTIFS(Eventos!A5:A51,"CTC",Eventos!D5:D51,"Julho") -> 0 | I34: =COUNTIFS(Eventos!A5:A51,"CTC",Eventos!D5:D51,"Agosto") -> 0 | J34: =COUNTIFS(Eventos!A5:A51,"CTC",Eventos!D5:D51,"Setembro") -> 0 | K34: =COUNTIFS(Eventos!A5:A51,"CTC",Eventos!D5:D51,"Outubro") -> 0 | L34: =COUNTIFS(Eventos!A5:A51,"CTC",Eventos!D5:D51,"Novembro") -> 0 | M34: =COUNTIFS(Eventos!A5:A51,"CTC",Eventos!D5:D51,"Dezembro") -> 0 | N34: =COUNTIF(Eventos!A5:A51,"CTC") -> 0
A35: DG | B35: =COUNTIFS(Eventos!A5:A51,"DG",Eventos!D5:D51,"Janeiro") -> 0 | C35: =COUNTIFS(Eventos!A5:A51,"DG",Eventos!D5:D51,"Fevereiro") -> 0 | D35: =COUNTIFS(Eventos!A5:A51,"DG",Eventos!D5:D51,"Março") -> 0 | E35: =COUNTIFS(Eventos!A5:A51,"DG",Eventos!D5:D51,"Abril") -> 0 | F35: =COUNTIFS(Eventos!A5:A51,"DG",Eventos!D5:D51,"Maio") -> 0 | G35: =COUNTIFS(Eventos!A5:A51,"DG",Eventos!D5:D51,"Junho") -> 0 | H35: =COUNTIFS(Eventos!A5:A51,"DG",Eventos!D5:D51,"Julho") -> 0 | I35: =COUNTIFS(Eventos!A5:A51,"DG",Eventos!D5:D51,"Agosto") -> 0 | J35: =COUNTIFS(Eventos!A5:A51,"DG",Eventos!D5:D51,"Setembro") -> 0 | K35: =COUNTIFS(Eventos!A5:A51,"DG",Eventos!D5:D51,"Outubro") -> 0 | L35: =COUNTIFS(Eventos!A5:A51,"DG",Eventos!D5:D51,"Novembro") -> 0 | M35: =COUNTIFS(Eventos!A5:A51,"DG",Eventos!D5:D51,"Dezembro") -> 0 | N35: =COUNTIF(Eventos!A5:A51,"DG") -> 0
A36: Fruthotec | B36: =COUNTIFS(Eventos!A5:A51,"Fruthotec",Eventos!D5:D51,"Janeiro") -> 0 | C36: =COUNTIFS(Eventos!A5:A51,"Fruthotec",Eventos!D5:D51,"Fevereiro") -> 0 | D36: =COUNTIFS(Eventos!A5:A51,"Fruthotec",Eventos!D5:D51,"Março") -> 0 | E36: =COUNTIFS(Eventos!A5:A51,"Fruthotec",Eventos!D5:D51,"Abril") -> 0 | F36: =COUNTIFS(Eventos!A5:A51,"Fruthotec",Eventos!D5:D51,"Maio") -> 0 | G36: =COUNTIFS(Eventos!A5:A51,"Fruthotec",Eventos!D5:D51,"Junho") -> 0 | H36: =COUNTIFS(Eventos!A5:A51,"Fruthotec",Eventos!D5:D51,"Julho") -> 0 | I36: =COUNTIFS(Eventos!A5:A51,"Fruthotec",Eventos!D5:D51,"Agosto") -> 0 | J36: =COUNTIFS(Eventos!A5:A51,"Fruthotec",Eventos!D5:D51,"Setembro") -> 0 | K36: =COUNTIFS(Eventos!A5:A51,"Fruthotec",Eventos!D5:D51,"Outubro") -> 0 | L36: =COUNTIFS(Eventos!A5:A51,"Fruthotec",Eventos!D5:D51,"Novembro") -> 0 | M36: =COUNTIFS(Eventos!A5:A51,"Fruthotec",Eventos!D5:D51,"Dezembro") -> 0 | N36: =COUNTIF(Eventos!A5:A51,"Fruthotec") -> 0
A37: Tecnolat | B37: =COUNTIFS(Eventos!A5:A51,"Tecnolat",Eventos!D5:D51,"Janeiro") -> 0 | C37: =COUNTIFS(Eventos!A5:A51,"Tecnolat",Eventos!D5:D51,"Fevereiro") -> 0 | D37: =COUNTIFS(Eventos!A5:A51,"Tecnolat",Eventos!D5:D51,"Março") -> 0 | E37: =COUNTIFS(Eventos!A5:A51,"Tecnolat",Eventos!D5:D51,"Abril") -> 0 | F37: =COUNTIFS(Eventos!A5:A51,"Tecnolat",Eventos!D5:D51,"Maio") -> 0 | G37: =COUNTIFS(Eventos!A5:A51,"Tecnolat",Eventos!D5:D51,"Junho") -> 0 | H37: =COUNTIFS(Eventos!A5:A51,"Tecnolat",Eventos!D5:D51,"Julho") -> 0 | I37: =COUNTIFS(Eventos!A5:A51,"Tecnolat",Eventos!D5:D51,"Agosto") -> 0 | J37: =COUNTIFS(Eventos!A5:A51,"Tecnolat",Eventos!D5:D51,"Setembro") -> 0 | K37: =COUNTIFS(Eventos!A5:A51,"Tecnolat",Eventos!D5:D51,"Outubro") -> 0 | L37: =COUNTIFS(Eventos!A5:A51,"Tecnolat",Eventos!D5:D51,"Novembro") -> 0 | M37: =COUNTIFS(Eventos!A5:A51,"Tecnolat",Eventos!D5:D51,"Dezembro") -> 0 | N37: =COUNTIF(Eventos!A5:A51,"Tecnolat") -> 0
A38: Ital | B38: =SUM(B31:B37) -> 0 | C38: =SUM(C31:C37) -> 0 | D38: =SUM(D31:D37) -> 0 | E38: =SUM(E31:E37) -> 0 | F38: =SUM(F31:F37) -> 0 | G38: =SUM(G31:G37) -> 0 | H38: =SUM(H31:H37) -> 0 | I38: =SUM(I31:I37) -> 0 | ... M38: =SUM(M31:M37) -> 0 | N38: =SUM(B38:M38) -> 0
A40: Quantidade de Treinamento/Curso Fechado
A42: Unidade | B42: Janeiro | C42: Fevereiro | D42: Março | E42: Abril | F42: Maio | G42: Junho | H42: Julho | I42: Agosto | J42: Setembro | K42: Outubro | L42: Novembro | M42: Dezembro | N42: Ano
A43: Cereal Chocotec | B43: =IFERROR(COUNTIFS('Treinamentos Fechados'!D5:D51,"Janeiro",'Treinamentos Fechados'!A5:A51,"C.Chocotec"),"-") -> 0 | C43: =IFERROR(COUNTIFS('Treinamentos Fechados'!D5:D51,"Fevereiro",'Treinamentos Fechados'!A5:A51,"C.Chocotec"),"-") -> 0 | D43: =IFERROR(COUNTIFS('Treinamentos Fechados'!D5:D51,"Março",'Treinamentos Fechados'!A5:A51,"C.Chocotec"),"-") -> 0 | E43: =IFERROR(COUNTIFS('Treinamentos Fechados'!D5:D51,"Abril",'Treinamentos Fechados'!A5:A51,"C.Chocotec"),"-") -> 0 | F43: =IFERROR(COUNTIFS('Treinamentos Fechados'!D5:D51,"Maio",'Treinamentos Fechados'!A5:A51,"C.Chocotec"),"-") -> 0 | G43: =IFERROR(COUNTIFS('Treinamentos Fechados'!D5:D51,"Junho",'Treinamentos Fechados'!A5:A51,"C.Chocotec"),"-") -> 0 | H43: =IFERROR(COUNTIFS('Treinamentos Fechados'!D5:D51,"Julho",'Treinamentos Fechados'!A5:A51,"C.Chocotec"),"-") -> 0 | I43: =IFERROR(COUNTIFS('Treinamentos Fechados'!D5:D51,"Agosto",'Treinamentos Fechados'!A5:A51,"C.Chocotec"),"-") -> 0 | J43: =IFERROR(COUNTIFS('Treinamentos Fechados'!D5:D51,"Setembro",'Treinamentos Fechados'!A5:A51,"C.Chocotec"),"-") -> 0 | K43: =IFERROR(COUNTIFS('Treinamentos Fechados'!D5:D51,"Outubro",'Treinamentos Fechados'!A5:A51,"C.Chocotec"),"-") -> 0 | L43: =IFERROR(COUNTIFS('Treinamentos Fechados'!D5:D51,"Novembro",'Treinamentos Fechados'!A5:A51,"C.Chocotec"),"-") -> 0 | M43: =IFERROR(COUNTIFS('Treinamentos Fechados'!D5:D51,"Dezembro",'Treinamentos Fechados'!A5:A51,"C.Chocotec"),"-") -> 0 | N43: =COUNTIF('Treinamentos Fechados'!A5:A51,"C.Chocotec") -> 0
A44: CCQA | B44: =IFERROR(COUNTIFS('Treinamentos Fechados'!D5:D51,"Janeiro",'Treinamentos Fechados'!A5:A51,"CCQA"),"-") -> 0 | C44: =IFERROR(COUNTIFS('Treinamentos Fechados'!D5:D51,"Fevereiro",'Treinamentos Fechados'!A5:A51,"CCQA"),"-") -> 0 | D44: =IFERROR(COUNTIFS('Treinamentos Fechados'!D5:D51,"Março",'Treinamentos Fechados'!A5:A51,"CCQA"),"-") -> 0 | E44: =IFERROR(COUNTIFS('Treinamentos Fechados'!D5:D51,"Abril",'Treinamentos Fechados'!A5:A51,"CCQA"),"-") -> 0 | F44: =IFERROR(COUNTIFS('Treinamentos Fechados'!D5:D51,"Maio",'Treinamentos Fechados'!A5:A51,"CCQA"),"-") -> 0 | G44: =IFERROR(COUNTIFS('Treinamentos Fechados'!D5:D51,"Junho",'Treinamentos Fechados'!A5:A51,"CCQA"),"-") -> 0 | H44: =IFERROR(COUNTIFS('Treinamentos Fechados'!D5:D51,"Julho",'Treinamentos Fechados'!A5:A51,"CCQA"),"-") -> 0 | I44: =IFERROR(COUNTIFS('Treinamentos Fechados'!D5:D51,"Agosto",'Treinamentos Fechados'!A5:A51,"CCQA"),"-") -> 0 | J44: =IFERROR(COUNTIFS('Treinamentos Fechados'!D5:D51,"Setembro",'Treinamentos Fechados'!A5:A51,"CCQA'"),"-") -> 0 | K44: =IFERROR(COUNTIFS('Treinamentos Fechados'!D5:D51,"Outubro",'Treinamentos Fechados'!A5:A51,"CCQA"),"-") -> 0 | L44: =IFERROR(COUNTIFS('Treinamentos Fechados'!D5:D51,"Novembro",'Treinamentos Fechados'!A5:A51,"CCQA"),"-") -> 0 | M44: =IFERROR(COUNTIFS('Treinamentos Fechados'!D5:D51,"Dezembro",'Treinamentos Fechados'!A5:A51,"CCQA"),"-") -> 0 | N44: =COUNTIF('Treinamentos Fechados'!A5:A51,"CCQA") -> 0
A45: Cetea | B45: =IFERROR(COUNTIFS('Treinamentos Fechados'!D5:D51,"Janeiro",'Treinamentos Fechados'!A5:A51,"Cetea"),"-") -> 0 | C45: =IFERROR(COUNTIFS('Treinamentos Fechados'!D5:D51,"Fevereiro",'Treinamentos Fechados'!A5:A51,"Cetea"),"-") -> 0 | D45: =IFERROR(COUNTIFS('Treinamentos Fechados'!D5:D51,"Março",'Treinamentos Fechados'!A5:A51,"Cetea"),"-") -> 0 | E45: =IFERROR(COUNTIFS('Treinamentos Fechados'!D5:D51,"Abril",'Treinamentos Fechados'!A5:A51,"Cetea"),"-") -> 0 | F45: =IFERROR(COUNTIFS('Treinamentos Fechados'!D5:D51,"Maio",'Treinamentos Fechados'!A5:A51,"Cetea"),"-") -> 0 | G45: =IFERROR(COUNTIFS('Treinamentos Fechados'!D5:D51,"Junho",'Treinamentos Fechados'!A5:A51,"Cetea"),"-") -> 0 | H45: =IFERROR(COUNTIFS('Treinamentos Fechados'!D5:D51,"Julho",'Treinamentos Fechados'!A5:A51,"Cetea"),"-") -> 0 | I45: =IFERROR(COUNTIFS('Treinamentos Fechados'!D5:D51,"Agosto",'Treinamentos Fechados'!A5:A51,"Cetea"),"-") -> 0 | J45: =IFERROR(COUNTIFS('Treinamentos Fechados'!D5:D51,"Setembro",'Treinamentos Fechados'!A5:A51,"Cetea"),"-") -> 0 | K45: =IFERROR(COUNTIFS('Treinamentos Fechados'!D5:D51,"Outubro",'Treinamentos Fechados'!A5:A51,"Cetea"),"-") -> 0 | L45: =IFERROR(COUNTIFS('Treinamentos Fechados'!D5:D51,"Novembro",'Treinamentos Fechados'!A5:A51,"Cetea"),"-") -> 0 | M45: =IFERROR(COUNTIFS('Treinamentos Fechados'!D5:D51,"Dezembro",'Treinamentos Fechados'!A5:A51,"Cetea"),"-") -> 0 | N45: =COUNTIF('Treinamentos Fechados'!A5:A51,"Cetea") -> 0
