Workbook

Sheet FQ0835_p01
A1: MONITORAMENTO DE OCORRÊNCIAS - FUNDAÇÃO DE APOIO | P1: Fundepag
A2: (ANO)
A3: 1. REGISTROS DE OCORRÊNCIAS
A5: Nº | B5: Data | C5: Responsabilidade | D5: Tipo de registro | E5: Descrição da ocorrência | F5: Responsável | G5: Ação tomada | H5: Impacto no processo* | I5: Comentários | J5: Data de encerramento | K5: MÊS | L5: ITAL | M5: IMPACTO
K6: =IFERROR(IF(B6=0,“”,MONTH(B6)),0) -> 0 | L6: =IF(C6=P$1,"Não","Sim") -> Sim | M6: =IF(H6="ALTO","Sim","Não") -> Não
K7: =IFERROR(IF(B7=0,“”,MONTH(B7)),0) -> 0 | L7: =IF(C7=P$1,"Não","Sim") -> Sim | M7: =IF(H7="ALTO","Sim","Não") -> Não
K8: =IFERROR(IF(B8=0,“”,MONTH(B8)),0) -> 0 | L8: =IF(C8=P$1,"Não","Sim") -> Sim | M8: =IF(H8="ALTO","Sim","Não") -> Não
K9: =IFERROR(IF(B9=0,“”,MONTH(B9)),0) -> 0 | L9: =IF(C9=P$1,"Não","Sim") -> Sim | M9: =IF(H9="ALTO","Sim","Não") -> Não
K10: =IFERROR(IF(B10=0,“”,MONTH(B10)),0) -> 0 | L10: =IF(C10=P$1,"Não","Sim") -> Sim | M10: =IF(H10="ALTO","Sim","Não") -> Não
K11: =IFERROR(IF(B11=0,“”,MONTH(B11)),0) -> 0 | L11: =IF(C11=P$1,"Não","Sim") -> Sim | M11: =IF(H11="ALTO","Sim","Não") -> Não
K12: =IFERROR(IF(B12=0,“”,MONTH(B12)),0) -> 0 | L12: =IF(C12=P$1,"Não","Sim") -> Sim | M12: =IF(H12="ALTO","Sim","Não") -> Não
K13: =IFERROR(IF(B13=0,“”,MONTH(B13)),0) -> 0 | L13: =IF(C13=P$1,"Não","Sim") -> Sim | M13: =IF(H13="ALTO","Sim","Não") -> Não
K14: =IFERROR(IF(B14=0,“”,MONTH(B14)),0) -> 0 | L14: =IF(C14=P$1,"Não","Sim") -> Sim | M14: =IF(H14="ALTO","Sim","Não") -> Não
K15: =IFERROR(IF(B15=0,“”,MONTH(B15)),0) -> 0 | L15: =IF(C15=P$1,"Não","Sim") -> Sim | M15: =IF(H15="ALTO","Sim","Não") -> Não
K16: =IFERROR(IF(B16=0,“”,MONTH(B16)),0) -> 0 | L16: =IF(C16=P$1,"Não","Sim") -> Sim | M16: =IF(H16="ALTO","Sim","Não") -> Não
K17: =IFERROR(IF(B17=0,“”,MONTH(B17)),0) -> 0 | L17: =IF(C17=P$1,"Não","Sim") -> Sim | M17: =IF(H17="ALTO","Sim","Não") -> Não
... K30: =IFERROR(IF(B30=0,“”,MONTH(B30)),0) -> 0 | L30: =IF(C30=P$1,"Não","Sim") -> Sim | M30: =IF(H30="ALTO","Sim","Não") -> Não
A33: ORIENTAÇÕES:
A34: * Para preenchimento da coluna "Impacto no processo" considerar impacto gerado à PARTE INTERESSADA FA.
A36: FQ-08.35 (anexo à IT-08.01.04) - RA - revisão 05 de 02/01/24 - Página 1/2

Sheet FQ0835_p02
A1: MONITORAMENTO DE OCORRÊNCIAS - FUNDAÇÃO DE APOIO
A2: =FQ0835_p01!A2:J2 -> (ANO)
A4: 2. RELATÓRIO DE OCORRÊNCIAS - FUNDAÇÃO DE APOIO
A6: 2.1 Por tipo (Somente responsabilidade Ital - todos os níveis de impacto)
A8: Tipo | B8: MÊS
B9: JAN | C9: FEV | D9: MAR | E9: ABR | F9: MAI | G9: JUN | H9: JUL | I9: AGO | J9: SET | K9: OUT | L9: NOV | M9: DEZ | N9: Total
A10: Processo trabalhista | B10: =COUNTIFS(FQ0835_p01!K$6:K$30,1,FQ0835_p01!D$6:D$30,A10,FQ0835_p01!L$6:L$30,"Sim") -> 0 | C10: =COUNTIFS(FQ0835_p01!K$6:K$30,2,FQ0835_p01!D$6:D$30,A10,FQ0835_p01!L$6:L$30,"Sim") -> 0 | D10: =COUNTIFS(FQ0835_p01!K$6:K$30,3,FQ0835_p01!D$6:D$30,A10,FQ0835_p01!L$6:L$30,"Sim") -> 0 | E10: =COUNTIFS(FQ0835_p01!K$6:K$30,4,FQ0835_p01!D$6:D$30,A10,FQ0835_p01!L$6:L$30,"Sim") -> 0 | F10: =COUNTIFS(FQ0835_p01!K$6:K$30,5,FQ0835_p01!D$6:D$30,A10,FQ0835_p01!L$6:L$30,"Sim") -> 0 | G10: =COUNTIFS(FQ0835_p01!K$6:K$30,6,FQ0835_p01!D$6:D$30,A10,FQ0835_p01!L$6:L$30,"Sim") -> 0 | H10: =COUNTIFS(FQ0835_p01!K$6:K$30,7,FQ0835_p01!D$6:D$30,A10,FQ0835_p01!L$6:L$30,"Sim") -> 0 | I10: =COUNTIFS(FQ0835_p01!K$6:K$30,8,FQ0835_p01!D$6:D$30,A10,FQ0835_p01!L$6:L$30,"Sim") -> 0 | J10: =COUNTIFS(FQ0835_p01!K$6:K$30,9,FQ0835_p01!D$6:D$30,A10,FQ0835_p01!L$6:L$30,"Sim") -> 0 | K10: =COUNTIFS(FQ0835_p01!K$6:K$30,10,FQ0835_p01!D$6:D$30,A10,FQ0835_p01!L$6:L$30,"Sim") -> 0 | L10: =COUNTIFS(FQ0835_p01!K$6:K$30,11,FQ0835_p01!D$6:D$30,A10,FQ0835_p01!L$6:L$30,"Sim") -> 0 | M10: =COUNTIFS(FQ0835_p01!K$6:K$30,12,FQ0835_p01!D$6:D$30,A10,FQ0835_p01!L$6:L$30,"Sim") -> 0 | N10: =SUM(B10:M10) -> 0
A11: Atraso de pagamento com protesto | B11: =COUNTIFS(FQ0835_p01!K$6:K$30,1,FQ0835_p01!D$6:D$30,A11,FQ0835_p01!L$6:L$30,"Sim") -> 0 | C11: =COUNTIFS(FQ0835_p01!K$6:K$30,2,FQ0835_p01!D$6:D$30,A11,FQ0835_p01!L$6:L$30,"Sim") -> 0 | D11: =COUNTIFS(FQ0835_p01!K$6:K$30,3,FQ0835_p01!D$6:D$30,A11,FQ0835_p01!L$6:L$30,"Sim") -> 0 | E11: =COUNTIFS(FQ0835_p01!K$6:K$30,4,FQ0835_p01!D$6:D$30,A11,FQ0835_p01!L$6:L$30,"Sim") -> 0 | F11: =COUNTIFS(FQ0835_p01!K$6:K$30,5,FQ0835_p01!D$6:D$30,A11,FQ0835_p01!L$6:L$30,"Sim") -> 0 | G11: =COUNTIFS(FQ0835_p01!K$6:K$30,6,FQ0835_p01!D$6:D$30,A11,FQ0835_p01!L$6:L$30,"Sim") -> 0 | H11: =COUNTIFS(FQ0835_p01!K$6:K$30,7,FQ0835_p01!D$6:D$30,A11,FQ0835_p01!L$6:L$30,"Sim") -> 0 | I11: =COUNTIFS(FQ0835_p01!K$6:K$30,8,FQ0835_p01!D$6:D$30,A11,FQ0835_p01!L$6:L$30,"Sim") -> 0 | J11: =COUNTIFS(FQ0835_p01!K$6:K$30,9,FQ0835_p01!D$6:D$30,A11,FQ0835_p01!L$6:L$30,"Sim") -> 0 | K11: =COUNTIFS(FQ0835_p01!K$6:K$30,10,FQ0835_p01!D$6:D$30,A11,FQ0835_p01!L$6:L$30,"Sim") -> 0 | L11: =COUNTIFS(FQ0835_p01!K$6:K$30,11,FQ0835_p01!D$6:D$30,A11,FQ0835_p01!L$6:L$30,"Sim") -> 0 | M11: =COUNTIFS(FQ0835_p01!K$6:K$30,12,FQ0835_p01!D$6:D$30,A11,FQ0835_p01!L$6:L$30,"Sim") -> 0 | N11: =SUM(B11:M11) -> 0
A12: Atraso de pagamento sem protesto | B12: =COUNTIFS(FQ0835_p01!K$6:K$30,1,FQ0835_p01!D$6:D$30,A12,FQ0835_p01!L$6:L$30,"Sim") -> 0 | C12: =COUNTIFS(FQ0835_p01!K$6:K$30,2,FQ0835_p01!D$6:D$30,A12,FQ0835_p01!L$6:L$30,"Sim") -> 0 | D12: =COUNTIFS(FQ0835_p01!K$6:K$30,3,FQ0835_p01!D$6:D$30,A12,FQ0835_p01!L$6:L$30,"Sim") -> 0 | E12: =COUNTIFS(FQ0835_p01!K$6:K$30,4,FQ0835_p01!D$6:D$30,A12,FQ0835_p01!L$6:L$30,"Sim") -> 0 | F12: =COUNTIFS(FQ0835_p01!K$6:K$30,5,FQ0835_p01!D$6:D$30,A12,FQ0835_p01!L$6:L$30,"Sim") -> 0 | G12: =COUNTIFS(FQ0835_p01!K$6:K$30,6,FQ0835_p01!D$6:D$30,A12,FQ0835_p01!L$6:L$30,"Sim") -> 0 | H12: =COUNTIFS(FQ0835_p01!K$6:K$30,7,FQ0835_p01!D$6:D$30,A12,FQ0835_p01!L$6:L$30,"Sim") -> 0 | I12: =COUNTIFS(FQ0835_p01!K$6:K$30,8,FQ0835_p01!D$6:D$30,A12,FQ0835_p01!L$6:L$30,"Sim") -> 0 | J12: =COUNTIFS(FQ0835_p01!K$6:K$30,9,FQ0835_p01!D$6:D$30,A12,FQ0835_p01!L$6:L$30,"Sim") -> 0 | K12: =COUNTIFS(FQ0835_p01!K$6:K$30,10,FQ0835_p01!D$6:D$30,A12,FQ0835_p01!L$6:L$30,"Sim") -> 0 | L12: =COUNTIFS(FQ0835_p01!K$6:K$30,11,FQ0835_p01!D$6:D$30,A12,FQ0835_p01!L$6:L$30,"Sim") -> 0 | M12: =COUNTIFS(FQ0835_p01!K$6:K$30,12,FQ0835_p01!D$6:D$30,A12,FQ0835_p01!L$6:L$30,"Sim") -> 0 | N12: =SUM(B12:M12) -> 0
A13: Pessoal | B13: =COUNTIFS(FQ0835_p01!K$6:K$30,1,FQ0835_p01!D$6:D$30,A13,FQ0835_p01!L$6:L$30,"Sim") -> 0 | C13: =COUNTIFS(FQ0835_p01!K$6:K$30,2,FQ0835_p01!D$6:D$30,A13,FQ0835_p01!L$6:L$30,"Sim") -> 0 | D13: =COUNTIFS(FQ0835_p01!K$6:K$30,3,FQ0835_p01!D$6:D$30,A13,FQ0835_p01!L$6:L$30,"Sim") -> 0 | E13: =COUNTIFS(FQ0835_p01!K$6:K$30,4,FQ0835_p01!D$6:D$30,A13,FQ0835_p01!L$6:L$30,"Sim") -> 0 | F13: =COUNTIFS(FQ0835_p01!K$6:K$30,5,FQ0835_p01!D$6:D$30,A13,FQ0835_p01!L$6:L$30,"Sim") -> 0 | G13: =COUNTIFS(FQ0835_p01!K$6:K$30,6,FQ0835_p01!D$6:D$30,A13,FQ0835_p01!L$6:L$30,"Sim") -> 0 | H13: =COUNTIFS(FQ0835_p01!K$6:K$30,7,FQ0835_p01!D$6:D$30,A13,FQ0835_p01!L$6:L$30,"Sim") -> 0 | I13: =COUNTIFS(FQ0835_p01!K$6:K$30,8,FQ0835_p01!D$6:D$30,A13,FQ0835_p01!L$6:L$30,"Sim") -> 0 | J13: =COUNTIFS(FQ0835_p01!K$6:K$30,9,FQ0835_p01!D$6:D$30,A13,FQ0835_p01!L$6:L$30,"Sim") -> 0 | K13: =COUNTIFS(FQ0835_p01!K$6:K$30,10,FQ0835_p01!D$6:D$30,A13,FQ0835_p01!L$6:L$30,"Sim") -> 0 | L13: =COUNTIFS(FQ0835_p01!K$6:K$30,11,FQ0835_p01!D$6:D$30,A13,FQ0835_p01!L$6:L$30,"Sim") -> 0 | M13: =COUNTIFS(FQ0835_p01!K$6:K$30,12,FQ0835_p01!D$6:D$30,A13,FQ0835_p01!L$6:L$30,"Sim") -> 0 | N13: =SUM(B13:M13) -> 0
A14: Fornecedor | B14: =COUNTIFS(FQ0835_p01!K$6:K$30,1,FQ0835_p01!D$6:D$30,A14,FQ0835_p01!L$6:L$30,"Sim") -> 0 | C14: =COUNTIFS(FQ0835_p01!K$6:K$30,2,FQ0835_p01!D$6:D$30,A14,FQ0835_p01!L$6:L$30,"Sim") -> 0 | D14: =COUNTIFS(FQ0835_p01!K$6:K$30,3,FQ0835_p01!D$6:D$30,A14,FQ0835_p01!L$6:L$30,"Sim") -> 0 | E14: =COUNTIFS(FQ0835_p01!K$6:K$30,4,FQ0835_p01!D$6:D$30,A14,FQ0835_p01!L$6:L$30,"Sim") -> 0 | F14: =COUNTIFS(FQ0835_p01!K$6:K$30,5,FQ0835_p01!D$6:D$30,A14,FQ0835_p01!L$6:L$30,"Sim") -> 0 | G14: =COUNTIFS(FQ0835_p01!K$6:K$30,6,FQ0835_p01!D$6:D$30,A14,FQ0835_p01!L$6:L$30,"Sim") -> 0 | H14: =COUNTIFS(FQ0835_p01!K$6:K$30,7,FQ0835_p01!D$6:D$30,A14,FQ0835_p01!L$6:L$30,"Sim") -> 0 | I14: =COUNTIFS(FQ0835_p01!K$6:K$30,8,FQ0835_p01!D$6:D$30,A14,FQ0835_p01!L$6:L$30,"Sim") -> 0 | J14: =COUNTIFS(FQ0835_p01!K$6:K$30,9,FQ0835_p01!D$6:D$30,A14,FQ0835_p01!L$6:L$30,"Sim") -> 0 | K14: =COUNTIFS(FQ0835_p01!K$6:K$30,10,FQ0835_p01!D$6:D$30,A14,FQ0835_p01!L$6:L$30,"Sim") -> 0 | L14: =COUNTIFS(FQ0835_p01!K$6:K$30,11,FQ0835_p01!D$6:D$30,A14,FQ0835_p01!L$6:L$30,"Sim") -> 0 | M14: =COUNTIFS(FQ0835_p01!K$6:K$30,12,FQ0835_p01!D$6:D$30,A14,FQ0835_p01!L$6:L$30,"Sim") -> 0 | N14: =SUM(B14:M14) -> 0
A15: Cliente | B15: =COUNTIFS(FQ0835_p01!K$6:K$30,1,FQ0835_p01!D$6:D$30,A15,FQ0835_p01!L$6:L$30,"Sim") -> 0 | C15: =COUNTIFS(FQ0835_p01!K$6:K$30,2,FQ0835_p01!D$6:D$30,A15,FQ0835_p01!L$6:L$30,"Sim") -> 0 | D15: =COUNTIFS(FQ0835_p01!K$6:K$30,3,FQ0835_p01!D$6:D$30,A15,FQ0835_p01!L$6:L$30,"Sim") -> 0 | E15: =COUNTIFS(FQ0835_p01!K$6:K$30,4,FQ0835_p01!D$6:D$30,A15,FQ0835_p01!L$6:L$30,"Sim") -> 0 | F15: =COUNTIFS(FQ0835_p01!K$6:K$30,5,FQ0835_p01!D$6:D$30,A15,FQ0835_p01!L$6:L$30,"Sim") -> 0 | G15: =COUNTIFS(FQ0835_p01!K$6:K$30,6,FQ0835_p01!D$6:D$30,A15,FQ0835_p01!L$6:L$30,"Sim") -> 0 | H15: =COUNTIFS(FQ0835_p01!K$6:K$30,7,FQ0835_p01!D$6:D$30,A15,FQ0835_p01!L$6:L$30,"Sim") -> 0 | I15: =COUNTIFS(FQ0835_p01!K$6:K$30,8,FQ0835_p01!D$6:D$30,A15,FQ0835_p01!L$6:L$30,"Sim") -> 0 | J15: =COUNTIFS(FQ0835_p01!K$6:K$30,9,FQ0835_p01!D$6:D$30,A15,FQ0835_p01!L$6:L$30,"Sim") -> 0 | K15: =COUNTIFS(FQ0835_p01!K$6:K$30,10,FQ0835_p01!D$6:D$30,A15,FQ0835_p01!L$6:L$30,"Sim") -> 0 | L15: =COUNTIFS(FQ0835_p01!K$6:K$30,11,FQ0835_p01!D$6:D$30,A15,FQ0835_p01!L$6:L$30,"Sim") -> 0 | M15: =COUNTIFS(FQ0835_p01!K$6:K$30,12,FQ0835_p01!D$6:D$30,A15,FQ0835_p01!L$6:L$30,"Sim") -> 0 | N15: =SUM(B15:M15) -> 0
A16: Total | B16: =SUM(B10:B15) -> 0 | C16: =SUM(C10:C15) -> 0 | D16: =SUM(D10:D15) -> 0 | E16: =SUM(E10:E15) -> 0 | F16: =SUM(F10:F15) -> 0 | G16: =SUM(G10:G15) -> 0 | H16: =SUM(H10:H15) -> 0 | I16: =SUM(I10:I15) -> 0 | ... M16: =SUM(M10:M15) -> 0 | N16: =SUM(B16:M16) -> 0
A18: 2.1.1 Por tipo (Somente responsabilidade Ital - ALTO IMPACTO)
A20: Tipo | B20: MÊS
B21: JAN | C21: FEV | D21: MAR | E21: ABR | F21: MAI | G21: JUN | H21: JUL | I21: AGO | J21: SET | K21: OUT | L21: NOV | M21: DEZ | N21: Total
A22: Processo trabalhista | B22: =COUNTIFS(FQ0835_p01!K$6:K$30,1,FQ0835_p01!D$6:D$30,A22,FQ0835_p01!L$6:L$30,"Sim",FQ0835_p01!M$6:M$30,"Sim") -> 0 | C22: =COUNTIFS(FQ0835_p01!K$6:K$30,2,FQ0835_p01!D$6:D$30,A22,FQ0835_p01!L$6:L$30,"Sim",FQ0835_p01!M$6:M$30,"Sim") -> 0 | D22: =COUNTIFS(FQ0835_p01!K$6:K$30,3,FQ0835_p01!D$6:D$30,A22,FQ0835_p01!L$6:L$30,"Sim",FQ0835_p01!M$6:M$30,"Sim") -> 0 | E22: =COUNTIFS(FQ0835_p01!K$6:K$30,4,FQ0835_p01!D$6:D$30,A22,FQ0835_p01!L$6:L$30,"Sim",FQ0835_p01!M$6:M$30,"Sim") -> 0 | F22: =COUNTIFS(FQ0835_p01!K$6:K$30,5,FQ0835_p01!D$6:D$30,A22,FQ0835_p01!L$6:L$30,"Sim",FQ0835_p01!M$6:M$30,"Sim") -> 0 | G22: =COUNTIFS(FQ0835_p01!K$6:K$30,6,FQ0835_p01!D$6:D$30,A22,FQ0835_p01!L$6:L$30,"Sim",FQ0835_p01!M$6:M$30,"Sim") -> 0 | H22: =COUNTIFS(FQ0835_p01!K$6:K$30,7,FQ0835_p01!D$6:D$30,A22,FQ0835_p01!L$6:L$30,"Sim",FQ0835_p01!M$6:M$30,"Sim") -> 0 | I22: =COUNTIFS(FQ0835_p01!K$6:K$30,8,FQ0835_p01!D$6:D$30,A22,FQ0835_p01!L$6:L$30,"Sim",FQ0835_p01!M$6:M$30,"Sim") -> 0 | J22: =COUNTIFS(FQ0835_p01!K$6:K$30,9,FQ0835_p01!D$6:D$30,A22,FQ0835_p01!L$6:L$30,"Sim",FQ0835_p01!M$6:M$30,"Sim") -> 0 | K22: =COUNTIFS(FQ0835_p01!K$6:K$30,10,FQ0835_p01!D$6:D$30,A22,FQ0835_p01!L$6:L$30,"Sim",FQ0835_p01!M$6:M$30,"Sim") -> 0 | L22: =COUNTIFS(FQ0835_p01!K$6:K$30,11,FQ0835_p01!D$6:D$30,A22,FQ0835_p01!L$6:L$30,"Sim",FQ0835_p01!M$6:M$30,"Sim") -> 0 | M22: =COUNTIFS(FQ0835_p01!K$6:K$30,12,FQ0835_p01!D$6:D$30,A22,FQ0835_p01!L$6:L$30,"Sim",FQ0835_p01!M$6:M$30,"Sim") -> 0 | N22: =SUM(B22:M22) -> 0
A23: Atraso de pagamento com protesto | B23: =COUNTIFS(FQ0835_p01!K$6:K$30,1,FQ0835_p01!D$6:D$30,A23,FQ0835_p01!L$6:L$30,"Sim",FQ0835_p01!M$6:M$30,"Sim") -> 0 | C23: =COUNTIFS(FQ0835_p01!K$6:K$30,2,FQ0835_p01!D$6:D$30,A23,FQ0835_p01!L$6:L$30,"Sim",FQ0835_p01!M$6:M$30,"Sim") -> 0 | D23: =COUNTIFS(FQ0835_p01!K$6:K$30,3,FQ0835_p01!D$6:D$30,A23,FQ0835_p01!L$6:L$30,"Sim") -> 0 | E23: =COUNTIFS(FQ0835_p01!K$6:K$30,4,FQ0835_p01!D$6:D$30,A23,FQ0835_p01!L$6:L$30,"Sim",FQ0835_p01!M$6:M$30,"Sim") -> 0 | F23: =COUNTIFS(FQ0835_p01!K$6:K$30,5,FQ0835_p01!D$6:D$30,A23,FQ0835_p01!L$6:L$30,"Sim",FQ0835_p01!M$6:M$30,"Sim") -> 0 | G23: =COUNTIFS(FQ0835_p01!K$6:K$30,6,FQ0835_p01!D$6:D$30,A23,FQ0835_p01!L$6:L$30,"Sim",FQ0835_p01!M$6:M$30,"Sim") -> 0 | H23: =COUNTIFS(FQ0835_p01!K$6:K$30,7,FQ0835_p01!D$6:D$30,A23,FQ0835_p01!L$6:L$30,"Sim",FQ0835_p01!M$6:M$30,"Sim") -> 0 | I23: =COUNTIFS(FQ0835_p01!K$6:K$30,8,FQ0835_p01!D$6:D$30,A23,FQ0835_p01!L$6:L$30,"Sim",FQ0835_p01!M$6:M$30,"Sim") -> 0 | J23: =COUNTIFS(FQ0835_p01!K$6:K$30,9,FQ0835_p01!D$6:D$30,A23,FQ0835_p01!L$6:L$30,"Sim",FQ0835_p01!M$6:M$30,"Sim") -> 0 | K23: =COUNTIFS(FQ0835_p01!K$6:K$30,10,FQ0835_p01!D$6:D$30,A23,FQ0835_p01!L$6:L$30,"Sim",FQ0835_p01!M$6:M$30,"Sim") -> 0 | L23: =COUNTIFS(FQ0835_p01!K$6:K$30,11,FQ0835_p01!D$6:D$30,A23,FQ0835_p01!L$6:L$30,"Sim",FQ0835_p01!M$6:M$30,"Sim") -> 0 | M23: =COUNTIFS(FQ0835_p01!K$6:K$30,12,FQ0835_p01!D$6:D$30,A23,FQ0835_p01!L$6:L$30,"Sim",FQ0835_p01!M$6:M$30,"Sim") -> 0 | N23: =SUM(B23:M23) -> 0
A24: Atraso de pagamento sem protesto | B24: =COUNTIFS(FQ0835_p01!K$6:K$30,1,FQ0835_p01!D$6:D$30,A24,FQ0835_p01!L$6:L$30,"Sim",FQ0835_p01!M$6:M$30,"Sim") -> 0 | C24: =COUNTIFS(FQ0835_p01!K$6:K$30,2,FQ0835_p01!D$6:D$30,A24,FQ0835_p01!L$6:L$30,"Sim",FQ0835_p01!M$6:M$30,"Sim") -> 0 | D24: =COUNTIFS(FQ0835_p01!K$6:K$30,3,FQ0835_p01!D$6:D$30,A24,FQ0835_p01!L$6:L$30,"Sim") -> 0 | E24: =COUNTIFS(FQ0835_p01!K$6:K$30,4,FQ0835_p01!D$6:D$30,A24,FQ0835_p01!L$6:L$30,"Sim",FQ0835_p01!M$6:M$30,"Sim") -> 0 | F24: =COUNTIFS(FQ0835_p01!K$6:K$30,5,FQ0835_p01!D$6:D$30,A24,FQ0835_p01!L$6:L$30,"Sim",FQ0835_p01!M$6:M$30,"Sim") -> 0 | G24: =COUNTIFS(FQ0835_p01!K$6:K$30,6,FQ0835_p01!D$6:D$30,A24,FQ0835_p01!L$6:L$30,"Sim",FQ0835_p01!M$6:M$30,"Sim") -> 0 | H24: =COUNTIFS(FQ0835_p01!K$6:K$30,7,FQ0835_p01!D$6:D$30,A24,FQ0835_p01!L$6:L$30,"Sim",FQ0835_p01!M$6:M$30,"Sim") -> 0 | I24: =COUNTIFS(FQ0835_p01!K$6:K$30,8,FQ0835_p01!D$6:D$30,A24,FQ0835_p01!L$6:L$30,"Sim",FQ0835_p01!M$6:M$30,"Sim") -> 0 | J24: =COUNTIFS(FQ0835_p01!K$6:K$30,9,FQ0835_p01!D$6:D$30,A24,FQ0835_p01!L$6:L$30,"Sim",FQ0835_p01!M$6:M$30,"Sim") -> 0 | K24: =COUNTIFS(FQ0835_p01!K$6:K$30,10,FQ0835_p01!D$6:D$30,A24,FQ0835_p01!L$6:L$30,"Sim",FQ0835_p01!M$6:M$30,"Sim") -> 0 | L24: =COUNTIFS(FQ0835_p01!K$6:K$30,11,FQ0835_p01!D$6:D$30,A24,FQ0835_p01!L$6:L$30,"Sim",FQ0835_p01!M$6:M$30,"Sim") -> 0 | M24: =COUNTIFS(FQ0835_p01!K$6:K$30,12,FQ0835_p01!D$6:D$30,A24,FQ0835_p01!L$6:L$30,"Sim",FQ0835_p01!M$6:M$30,"Sim") -> 0 | N24: =SUM(B24:M24) -> 0
A25: Pessoal | B25: =COUNTIFS(FQ0835_p01!K$6:K$30,1,FQ0835_p01!D$6:D$30,A25,FQ0835_p01!L$6:L$30,"Sim",FQ0835_p01!M$6:M$30,"Sim") -> 0 | C25: =COUNTIFS(FQ0835_p01!K$6:K$30,2,FQ0835_p01!D$6:D$30,A25,FQ0835_p01!L$6:L$30,"Sim",FQ0835_p01!M$6:M$30,"Sim") -> 0 | D25: =COUNTIFS(FQ0835_p01!K$6:K$30,3,FQ0835_p01!D$6:D$30,A25,FQ0835_p01!L$6:L$30,"Sim") -> 0 | E25: =COUNTIFS(FQ0835_p01!K$6:K$30,4,FQ0835_p01!D$6:D$30,A25,FQ0835_p01!L$6:L$30,"Sim",FQ0835_p01!M$6:M$30,"Sim") -> 0 | F25: =COUNTIFS(FQ0835_p01!K$6:K$30,5,FQ0835_p01!D$6:D$30,A25,FQ0835_p01!L$6:L$30,"Sim",FQ0835_p01!M$6:M$30,"Sim") -> 0 | G25: =COUNTIFS(FQ0835_p01!K$6:K$30,6,FQ0835_p01!D$6:D$30,A25,FQ0835_p01!L$6:L$30,"Sim",FQ0835_p01!M$6:M$30,"Sim") -> 0 | H25: =COUNTIFS(FQ0835_p01!K$6:K$30,7,FQ0835_p01!D$6:D$30,A25,FQ0835_p01!L$6:L$30,"Sim",FQ0835_p01!M$6:M$30,"Sim") -> 0 | I25: =COUNTIFS(FQ0835_p01!K$6:K$30,8,FQ0835_p01!D$6:D$30,A25,FQ0835_p01!L$6:L$30,"Sim",FQ0835_p01!M$6:M$30,"Sim") -> 0 | J25: =COUNTIFS(FQ0835_p01!K$6:K$30,9,FQ0835_p01!D$6:D$30,A25,FQ0835_p01!L$6:L$30,"Sim",FQ0835_p01!M$6:M$30,"Sim") -> 0 | K25: =COUNTIFS(FQ0835_p01!K$6:K$30,10,FQ0835_p01!D$6:D$30,A25,FQ0835_p01!L$6:L$30,"Sim",FQ0835_p01!M$6:M$30,"Sim") -> 0 | L25: =COUNTIFS(FQ0835_p01!K$6:K$30,11,FQ0835_p01!D$6:D$30,A25,FQ0835_p01!L$6:L$30,"Sim",FQ0835_p01!M$6:M$30,"Sim") -> 0 | M25: =COUNTIFS(FQ0835_p01!K$6:K$30,12,FQ0835_p01!D$6:D$30,A25,FQ0835_p01!L$6:L$30,"Sim",FQ0835_p01!M$6:M$30,"Sim") -> 0 | N25: =SUM(B25:M25) -> 0
A26: Fornecedor | B26: =COUNTIFS(FQ0835_p01!K$6:K$30,1,FQ0835_p01!D$6:D$30,A26,FQ0835_p01!L$6:L$30,"Sim",FQ0835_p01!M$6:M$30,"Sim") -> 0 | C26: =COUNTIFS(FQ0835_p01!K$6:K$30,2,FQ0835_p01!D$6:D$30,A26,FQ0835_p01!L$6:L$30,"Sim",FQ0835_p01!M$6:M$30,"Sim") -> 0 | D26: =COUNTIFS(FQ0835_p01!K$6:K$30,3,FQ0835_p01!D$6:D$30,A26,FQ0835_p01!L$6:L$30,"Sim") -> 0 | E26: =COUNTIFS(FQ0835_p01!K$6:K$30,4,FQ0835_p01!D$6:D$30,A26,FQ0835_p01!L$6:L$30,"Sim",FQ0835_p01!M$6:M$30,"Sim") -> 0 | F26: =COUNTIFS(FQ0835_p01!K$6:K$30,5,FQ0835_p01!D$6:D$30,A26,FQ0835_p01!L$6:L$30,"Sim",FQ0835_p01!M$6:M$30,"Sim") -> 0 | G26: =COUNTIFS(FQ0835_p01!K$6:K$30,6,FQ0835_p01!D$6:D$30,A26,FQ0835_p01!L$6:L$30,"Sim",FQ0835_p01!M$6:M$30,"Sim") -> 0 | H26: =COUNTIFS(FQ0835_p01!K$6:K$30,7,FQ0835_p01!D$6:D$30,A26,FQ0835_p01!L$6:L$30,"Sim",FQ0835_p01!M$6:M$30,"Sim") -> 0 | I26: =COUNTIFS(FQ0835_p01!K$6:K$30,8,FQ0835_p01!D$6:D$30,A26,FQ0835_p01!L$6:L$30,"Sim",FQ0835_p01!M$6:M$30,"Sim") -> 0 | J26: =COUNTIFS(FQ0835_p01!K$6:K$30,9,FQ0835_p01!D$6:D$30,A26,FQ0835_p01!L$6:L$30,"Sim",FQ0835_p01!M$6:M$30,"Sim") -> 0 | K26: =COUNTIFS(FQ0835_p01!K$6:K$30,10,FQ0835_p01!D$6:D$30,A26,FQ0835_p01!L$6:L$30,"Sim",FQ0835_p01!M$6:M$30,"Sim") -> 0 | L26: =COUNTIFS(FQ0835_p01!K$6:K$30,11,FQ0835_p01!D$6:D$30,A26,FQ0835_p01!L$6:L$30,"Sim",FQ0835_p01!M$6:M$30,"Sim") -> 0 | M26: =COUNTIFS(FQ0835_p01!K$6:K$30,12,FQ0835_p01!D$6:D$30,A26,FQ0835_p01!L$6:L$30,"Sim",FQ0835_p01!M$6:M$30,"Sim") -> 0 | N26: =SUM(B26:M26) -> 0
A27: Cliente | B27: =COUNTIFS(FQ0835_p01!K$6:K$30,1,FQ0835_p01!D$6:D$30,A27,FQ0835_p01!L$6:L$30,"Sim",FQ0835_p01!M$6:M$30,"Sim") -> 0 | C27: =COUNTIFS(FQ0835_p01!K$6:K$30,2,FQ0835_p01!D$6:D$30,A27,FQ0835_p01!L$6:L$30,"Sim",FQ0835_p01!M$6:M$30,"Sim") -> 0 | D27: =COUNTIFS(FQ0835_p01!K$6:K$30,3,FQ0835_p01!D$6:D$30,A27,FQ0835_p01!L$6:L$30,"Sim",FQ0835_p01!M$6:M$30,"Sim") -> 0 | E27: =COUNTIFS(FQ0835_p01!K$6:K$30,4,FQ0835_p01!D$6:D$30,A27,FQ0835_p01!L$6:L$30,"Sim",FQ0835_p01!M$6:M$30,"Sim") -> 0 | F27: =COUNTIFS(FQ0835_p01!K$6:K$30,5,FQ0835_p01!D$6:D$30,A27,FQ0835_p01!L$6:L$30,"Sim",FQ0835_p01!M$6:M$30,"Sim") -> 0 | G27: =COUNTIFS(FQ0835_p01!K$6:K$30,6,FQ0835_p01!D$6:D$30,A27,FQ0835_p01!L$6:L$30,"Sim",FQ0835_p01!M$6:M$30,"Sim") -> 0 | H27: =COUNTIFS(FQ0835_p01!K$6:K$30,7,FQ0835_p01!D$6:D$30,A27,FQ0835_p01!L$6:L$30,"Sim",FQ0835_p01!M$6:M$30,"Sim") -> 0 | I27: =COUNTIFS(FQ0835_p01!K$6:K$30,8,FQ0835_p01!D$6:D$30,A27,FQ0835_p01!L$6:L$30,"Sim",FQ0835_p01!M$6:M$30,"Sim") -> 0 | J27: =COUNTIFS(FQ0835_p01!K$6:K$30,9,FQ0835_p01!D$6:D$30,A27,FQ0835_p01!L$6:L$30,"Sim",FQ0835_p01!M$6:M$30,"Sim") -> 0 | K27: =COUNTIFS(FQ0835_p01!K$6:K$30,10,FQ0835_p01!D$6:D$30,A27,FQ0835_p01!L$6:L$30,"Sim",FQ0835_p01!M$6:M$30,"Sim") -> 0 | L27: =COUNTIFS(FQ0835_p01!K$6:K$30,11,FQ0835_p01!D$6:D$30,A27,FQ0835_p01!L$6:L$30,"Sim",FQ0835_p01!M$6:M$30,"Sim") -> 0 | M27: =COUNTIFS(FQ0835_p01!K$6:K$30,12,FQ0835_p01!D$6:D$30,A27,FQ0835_p01!L$6:L$30,"Sim",FQ0835_p01!M$6:M$30,"Sim") -> 0 | N27: =SUM(B27:M27) -> 0
A28: Total | B28: =SUM(B22:B27) -> 0 | C28: =SUM(C22:C27) -> 0 | D28: =SUM(D22:D27) -> 0 | E28: =SUM(E22:E27) -> 0 | F28: =SUM(F22:F27) -> 0 | G28: =SUM(G22:G27) -> 0 | H28: =SUM(H22:H27) -> 0 | I28: =SUM(I22:I27) -> 0 | ... M28: =SUM(M22:M27) -> 0 | N28: =SUM(B28:M28) -> 0
A30: 2.2 Por tipo (Somente responsabilidade Fundepag - todos os níveis de impacto)
A32: Tipo | B32: MÊS
B33: JAN | C33: FEV | D33: MAR | E33: ABR | F33: MAI | G33: JUN | H33: JUL | I33: AGO | J33: SET | K33: OUT | L33: NOV | M33: DEZ | N33: Total
A34: Processo trabalhista | B34: =COUNTIFS(FQ0835_p01!K$6:K$30,1,FQ0835_p01!D$6:D$30,A34,FQ0835_p01!L$6:L$30,"Não") -> 0 | C34: =COUNTIFS(FQ0835_p01!K$6:K$30,2,FQ0835_p01!D$6:D$30,A34,FQ0835_p01!L$6:L$30,"Não") -> 0 | D34: =COUNTIFS(FQ0835_p01!K$6:K$30,3,FQ0835_p01!D$6:D$30,A34,FQ0835_p01!L$6:L$30,"Não") -> 0 | E34: =COUNTIFS(FQ0835_p01!K$6:K$30,4,FQ0835_p01!D$6:D$30,A34,FQ0835_p01!L$6:L$30,"Não") -> 0 | F34: =COUNTIFS(FQ0835_p01!K$6:K$30,5,FQ0835_p01!D$6:D$30,A34,FQ0835_p01!L$6:L$30,"Não") -> 0 | G34: =COUNTIFS(FQ0835_p01!K$6:K$30,6,FQ0835_p01!D$6:D$30,A34,FQ0835_p01!L$6:L$30,"Não") -> 0 | H34: =COUNTIFS(FQ0835_p01!K$6:K$30,7,FQ0835_p01!D$6:D$30,A34,FQ0835_p01!L$6:L$30,"Não") -> 0 | I34: =COUNTIFS(FQ0835_p01!K$6:K$30,8,FQ0835_p01!D$6:D$30,A34,FQ0835_p01!L$6:L$30,"Não") -> 0 | J34: =COUNTIFS(FQ0835_p01!K$6:K$30,9,FQ0835_p01!D$6:D$30,A34,FQ0835_p01!L$6:L$30,"Não") -> 0 | K34: =COUNTIFS(FQ0835_p01!K$6:K$30,10,FQ0835_p01!D$6:D$30,A34,FQ0835_p01!L$6:L$30,"Não") -> 0 | L34: =COUNTIFS(FQ0835_p01!K$6:K$30,11,FQ0835_p01!D$6:D$30,A34,FQ0835_p01!L$6:L$30,"Não") -> 0 | M34: =COUNTIFS(FQ0835_p01!K$6:K$30,12,FQ0835_p01!D$6:D$30,A34,FQ0835_p01!L$6:L$30,"Não") -> 0 | N34: =SUM(B34:M34) -> 0
A35: Atraso de pagamento com protesto | B35: =COUNTIFS(FQ0835_p01!K$6:K$30,1,FQ0835_p01!D$6:D$30,A35,FQ0835_p01!L$6:L$30,"Não") -> 0 | C35: =COUNTIFS(FQ0835_p01!K$6:K$30,2,FQ0835_p01!D$6:D$30,A35,FQ0835_p01!L$6:L$30,"Não") -> 0 | D35: =COUNTIFS(FQ0835_p01!K$6:K$30,3,FQ0835_p01!D$6:D$30,A35,FQ0835_p01!L$6:L$30,"Não") -> 0 | E35: =COUNTIFS(FQ0835_p01!K$6:K$30,4,FQ0835_p01!D$6:D$30,A35,FQ0835_p01!L$6:L$30,"Não") -> 0 | F35: =COUNTIFS(FQ0835_p01!K$6:K$30,5,FQ0835_p01!D$6:D$30,A35,FQ0835_p01!L$6:L$30,"Não") -> 0 | G35: =COUNTIFS(FQ0835_p01!K$6:K$30,6,FQ0835_p01!D$6:D$30,A35,FQ0835_p01!L$6:L$30,"Não") -> 0 | H35: =COUNTIFS(FQ0835_p01!K$6:K$30,7,FQ0835_p01!D$6:D$30,A35,FQ0835_p01!L$6:L$30,"Não") -> 0 | I35: =COUNTIFS(FQ0835_p01!K$6:K$30,8,FQ0835_p01!D$6:D$30,A35,FQ0835_p01!L$6:L$30,"Não") -> 0 | J35: =COUNTIFS(FQ0835_p01!K$6:K$30,9,FQ0835_p01!D$6:D$30,A35,FQ0835_p01!L$6:L$30,"Não") -> 0 | K35: =COUNTIFS(FQ0835_p01!K$6:K$30,10,FQ0835_p01!D$6:D$30,A35,FQ0835_p01!L$6:L$30,"Não") -> 0 | L35: =COUNTIFS(FQ0835_p01!K$6:K$30,11,FQ0835_p01!D$6:D$30,A35,FQ0835_p01!L$6:L$30,"Não") -> 0 | M35: =COUNTIFS(FQ0835_p01!K$6:K$30,12,FQ0835_p01!D$6:D$30,A35,FQ0835_p01!L$6:L$30,"Não") -> 0 | N35: =SUM(B35:M35) -> 0
A36: Atraso de pagamento sem protesto | B36: =COUNTIFS(FQ0835_p01!K$6:K$30,1,FQ0835_p01!D$6:D$30,A36,FQ0835_p01!L$6:L$30,"Não") -> 0 | C36: =COUNTIFS(FQ0835_p01!K$6:K$30,2,FQ0835_p01!D$6:D$30,A36,FQ0835_p01!L$6:L$30,"Não") -> 0 | D36: =COUNTIFS(FQ0835_p01!K$6:K$30,3,FQ0835_p01!D$6:D$30,A36,FQ0835_p01!L$6:L$30,"Não") -> 0 | E36: =COUNTIFS(FQ0835_p01!K$6:K$30,4,FQ0835_p01!D$6:D$30,A36,FQ0835_p01!L$6:L$30,"Não") -> 0 | F36: =COUNTIFS(FQ0835_p01!K$6:K$30,5,FQ0835_p01!D$6:D$30,A36,FQ0835_p01!L$6:L$30,"Não") -> 0 | G36: =COUNTIFS(FQ0835_p01!K$6:K$30,6,FQ0835_p01!D$6:D$30,A36,FQ0835_p01!L$6:L$30,"Não") -> 0 | H36: =COUNTIFS(FQ0835_p01!K$6:K$30,7,FQ0835_p01!D$6:D$30,A36,FQ0835_p01!L$6:L$30,"Não") -> 0 | I36: =COUNTIFS(FQ0835_p01!K$6:K$30,8,FQ0835_p01!D$6:D$30,A36,FQ0835_p01!L$6:L$30,"Não") -> 0 | J36: =COUNTIFS(FQ0835_p01!K$6:K$30,9,FQ0835_p01!D$6:D$30,A36,FQ0835_p01!L$6:L$30,"Não") -> 0 | K36: =COUNTIFS(FQ0835_p01!K$6:K$30,10,FQ0835_p01!D$6:D$30,A36,FQ0835_p01!L$6:L$30,"Não") -> 0 | L36: =COUNTIFS(FQ0835_p01!K$6:K$30,11,FQ0835_p01!D$6:D$30,A36,FQ0835_p01!L$6:L$30,"Não") -> 0 | M36: =COUNTIFS(FQ0835_p01!K$6:K$30,12,FQ0835_p01!D$6:D$30,A36,FQ0835_p01!L$6:L$30,"Não") -> 0 | N36: =SUM(B36:M36) -> 0
A37: Pessoal | B37: =COUNTIFS(FQ0835_p01!K$6:K$30,1,FQ0835_p01!D$6:D$30,A37,FQ0835_p01!L$6:L$30,"Não") -> 0 | C37: =COUNTIFS(FQ0835_p01!K$6:K$30,2,FQ0835_p01!D$6:D$30,A37,FQ0835_p01!L$6:L$30,"Não") -> 0 | D37: =COUNTIFS(FQ0835_p01!K$6:K$30,3,FQ0835_p01!D$6:D$30,A37,FQ0835_p01!L$6:L$30,"Não") -> 0 | E37: =COUNTIFS(FQ0835_p01!K$6:K$30,4,FQ0835_p01!D$6:D$30,A37,FQ0835_p01!L$6:L$30,"Não") -> 0 | F37: =COUNTIFS(FQ0835_p01!K$6:K$30,5,FQ0835_p01!D$6:D$30,A37,FQ0835_p01!L$6:L$30,"Não") -> 0 | G37: =COUNTIFS(FQ0835_p01!K$6:K$30,6,FQ0835_p01!D$6:D$30,A37,FQ0835_p01!L$6:L$30,"Não") -> 0 | H37: =COUNTIFS(FQ0835_p01!K$6:K$30,7,FQ0835_p01!D$6:D$30,A37,FQ0835_p01!L$6:L$30,"Não") -> 0 | I37: =COUNTIFS(FQ0835_p01!K$6:K$30,8,FQ0835_p01!D$6:D$30,A37,FQ0835_p01!L$6:L$30,"Não") -> 0 | J37: =COUNTIFS(FQ0835_p01!K$6:K$30,9,FQ0835_p01!D$6:D$30,A37,FQ0835_p01!L$6:L$30,"Não") -> 0 | K37: =COUNTIFS(FQ0835_p01!K$6:K$30,10,FQ0835_p01!D$6:D$30,A37,FQ0835_p01!L$6:L$30,"Não") -> 0 | L37: =COUNTIFS(FQ0835_p01!K$6:K$30,11,FQ0835_p01!D$6:D$30,A37,FQ0835_p01!L$6:L$30,"Não") -> 0 | M37: =COUNTIFS(FQ0835_p01!K$6:K$30,12,FQ0835_p01!D$6:D$30,A37,FQ0835_p01!L$6:L$30,"Não") -> 0 | N37: =SUM(B37:M37) -> 0
A38: Fornecedor | B38: =COUNTIFS(FQ0835_p01!K$6:K$30,1,FQ0835_p01!D$6:D$30,A38,FQ0835_p01!L$6:L$30,"Não") -> 0 | C38: =COUNTIFS(FQ0835_p01!K$6:K$30,2,FQ0835_p01!D$6:D$30,A38,FQ0835_p01!L$6:L$30,"Não") -> 0 | D38: =COUNTIFS(FQ0835_p01!K$6:K$30,3,FQ0835_p01!D$6:D$30,A38,FQ0835_p01!L$6:L$30,"Não") -> 0 | E38: =COUNTIFS(FQ0835_p01!K$6:K$30,4,FQ0835_p01!D$6:D$30,A38,FQ0835_p01!L$6:L$30,"Não") -> 0 | F38: =COUNTIFS(FQ0835_p01!K$6:K$30,5,FQ0835_p01!D$6:D$30,A38,FQ0835_p01!L$6:L$30,"Não") -> 0 | G38: =COUNTIFS(FQ0835_p01!K$6:K$30,6,FQ0835_p01!D$6:D$30,A38,FQ0835_p01!L$6:L$30,"Não") -> 0 | H38: =COUNTIFS(FQ0835_p01!K$6:K$30,7,FQ0835_p01!D$6:D$30,A38,FQ0835_p01!L$6:L$30,"Não") -> 0 | I38: =COUNTIFS(FQ0835_p01!K$6:K$30,8,FQ0835_p01!D$6:D$30,A38,FQ0835_p01!L$6:L$30,"Não") -> 0 | J38: =COUNTIFS(FQ0835_p01!K$6:K$30,9,FQ0835_p01!D$6:D$30,A38,FQ0835_p01!L$6:L$30,"Não") -> 0 | K38: =COUNTIFS(FQ0835_p01!K$6:K$30,10,FQ0835_p01!D$6:D$30,A38,FQ0835_p01!L$6:L$30,"Não") -> 0 | L38: =COUNTIFS(FQ0835_p01!K$6:K$30,11,FQ0835_p01!D$6:D$30,A38,FQ0835_p01!L$6:L$30,"Não") -> 0 | M38: =COUNTIFS(FQ0835_p01!K$6:K$30,12,FQ0835_p01!D$6:D$30,A38,FQ0835_p01!L$6:L$30,"Não") -> 0 | N38: =SUM(B38:M38) -> 0
A39: Cliente | B39: =COUNTIFS(FQ0835_p01!K$6:K$30,1,FQ0835_p01!D$6:D$30,A39,FQ0835_p01!L$6:L$30,"Não") -> 0 | C39: =COUNTIFS(FQ0835_p01!K$6:K$30,2,FQ0835_p01!D$6:D$30,A39,FQ0835_p01!L$6:L$30,"Não") -> 0 | D39: =COUNTIFS(FQ0835_p01!K$6:K$30,3,FQ0835_p01!D$6:D$30,A39,FQ0835_p01!L$6:L$30,"Não") -> 0 | E39: =COUNTIFS(FQ0835_p01!K$6:K$30,4,FQ0835_p01!D$6:D$30,A39,FQ0835_p01!L$6:L$30,"Não") -> 0 | F39: =COUNTIFS(FQ0835_p01!K$6:K$30,5,FQ0835_p01!D$6:D$30,A39,FQ0835_p01!L$6:L$30,"Não") -> 0 | G39: =COUNTIFS(FQ0835_p01!K$6:K$30,6,FQ0835_p01!D$6:D$30,A39,FQ0835_p01!L$6:L$30,"Não") -> 0 | H39: =COUNTIFS(FQ0835_p01!K$6:K$30,7,FQ0835_p01!D$6:D$30,A39,FQ0835_p01!L$6:L$30,"Não") -> 0 | I39: =COUNTIFS(FQ0835_p01!K$6:K$30,8,FQ0835_p01!D$6:D$30,A39,FQ0835_p01!L$6:L$30,"Não") -> 0 | J39: =COUNTIFS(FQ0835_p01!K$6:K$30,9,FQ0835_p01!D$6:D$30,A39,FQ0835_p01!L$6:L$30,"Não") -> 0 | K39: =COUNTIFS(FQ0835_p01!K$6:K$30,10,FQ0835_p01!D$6:D$30,A39,FQ0835_p01!L$6:L$30,"Não") -> 0 | L39: =COUNTIFS(FQ0835_p01!K$6:K$30,11,FQ0835_p01!D$6:D$30,A39,FQ0835_p01!L$6:L$30,"Não") -> 0 | M39: =COUNTIFS(FQ0835_p01!K$6:K$30,12,FQ0835_p01!D$6:D$30,A39,FQ0835_p01!L$6:L$30,"Não") -> 0 | N39: =SUM(B39:M39) -> 0
A40: Total | B40: =SUM(B34:B39) -> 0 | C40: =SUM(C34:C39) -> 0 | D40: =SUM(D34:D39) -> 0 | E40: =SUM(E34:E39) -> 0 | F40: =SUM(F34:F39) -> 0 | G40: =SUM(G34:G39) -> 0 | H40: =SUM(H34:H39) -> 0 | I40: =SUM(I34:I39) -> 0 | ... M40: =SUM(M34:M39) -> 0 | N40: =SUM(B40:M40) -> 0
A42: 2.2.1 Por tipo (Somente responsabilidade Fundepag - ALTO IMPACTO)
A44: Tipo | B44: MÊS
B45: JAN | C45: FEV | D45: MAR | E45: ABR | F45: MAI | G45: JUN | H45: JUL | I45: AGO | J45: SET | K45: OUT | L45: NOV | M45: DEZ | N45: Total
A46: Processo trabalhista | B46: =COUNTIFS(FQ0835_p01!K$6:K$30,1,FQ0835_p01!D$6:D$30,A46,FQ0835_p01!L$6:L$30,"Não",FQ0835_p01!M$6:M$30,"Sim") -> 0 | C46: =COUNTIFS(FQ0835_p01!K$6:K$30,2,FQ0835_p01!D$6:D$30,A46,FQ0835_p01!L$6:L$30,"Não",FQ0835_p01!M$6:M$30,"Sim") -> 0 | D46: =COUNTIFS(FQ0835_p01!K$6:K$30,3,FQ0835_p01!D$6:D$30,A46,FQ0835_p01!L$6:L$30,"Não",FQ0835_p01!M$6:M$30,"Sim") -> 0 | E46: =COUNTIFS(FQ0835_p01!K$6:K$30,4,FQ0835_p01!D$6:D$30,A46,FQ0835_p01!L$6:L$30,"Não",FQ0835_p01!M$6:M$30,"Sim") -> 0 | F46: =COUNTIFS(FQ0835_p01!K$6:K$30,5,FQ0835_p01!D$6:D$30,A46,FQ0835_p01!L$6:L$30,"Não",FQ0835_p01!M$6:M$30,"Sim") -> 0 | G46: =COUNTIFS(FQ0835_p01!K$6:K$30,6,FQ0835_p01!D$6:D$30,A46,FQ0835_p01!L$6:L$30,"Não",FQ0835_p01!M$6:M$30,"Sim") -> 0 | H46: =COUNTIFS(FQ0835_p01!K$6:K$30,7,FQ0835_p01!D$6:D$30,A46,FQ0835_p01!L$6:L$30,"Não",FQ0835_p01!M$6:M$30,"Sim") -> 0 | I46: =COUNTIFS(FQ0835_p01!K$6:K$30,8,FQ0835_p01!D$6:D$30,A46,FQ0835_p01!L$6:L$30,"Não",FQ0835_p01!M$6:M$30,"Sim") -> 0 | J46: =COUNTIFS(FQ0835_p01!K$6:K$30,9,FQ0835_p01!D$6:D$30,A46,FQ0835_p01!L$6:L$30,"Não",FQ0835_p01!M$6:M$30,"Sim") -> 0 | K46: =COUNTIFS(FQ0835_p01!K$6:K$30,10,FQ0835_p01!D$6:D$30,A46,FQ0835_p01!L$6:L$30,"Não",FQ0835_p01!M$6:M$30,"Sim") -> 0 | L46: =COUNTIFS(FQ0835_p01!K$6:K$30,11,FQ0835_p01!D$6:D$30,A46,FQ0835_p01!L$6:L$30,"Não",FQ0835_p01!M$6:M$30,"Sim") -> 0 | M46: =COUNTIFS(FQ0835_p01!K$6:K$30,12,FQ0835_p01!D$6:D$30,A46,FQ0835_p01!L$6:L$30,"Não",FQ0835_p01!M$6:M$30,"Sim") -> 0 | N46: =SUM(B46:M46) -> 0
A47: Atraso de pagamento com protesto | B47: =COUNTIFS(FQ0835_p01!K$6:K$30,1,FQ0835_p01!D$6:D$30,A47,FQ0835_p01!L$6:L$30,"Não",FQ0835_p01!M$6:M$30,"Sim") -> 0 | C47: =COUNTIFS(FQ0835_p01!K$6:K$30,2,FQ0835_p01!D$6:D$30,A47,FQ0835_p01!L$6:L$30,"Não",FQ0835_p01!M$6:M$30,"Sim") -> 0 | D47: =COUNTIFS(FQ0835_p01!K$6:K$30,3,FQ0835_p01!D$6:D$30,A47,FQ0835_p01!L$6:L$30,"Não") -> 0 | E47: =COUNTIFS(FQ0835_p01!K$6:K$30,4,FQ0835_p01!D$6:D$30,A47,FQ0835_p01!L$6:L$30,"Não",FQ0835_p01!M$6:M$30,"Sim") -> 0 | F47: =COUNTIFS(FQ0835_p01!K$6:K$30,5,FQ0835_p01!D$6:D$30,A47,FQ0835_p01!L$6:L$30,"Não",FQ0835_p01!M$6:M$30,"Sim") -> 0 | G47: =COUNTIFS(FQ0835_p01!K$6:K$30,6,FQ0835_p01!D$6:D$30,A47,FQ0835_p01!L$6:L$30,"Não",FQ0835_p01!M$6:M$30,"Sim") -> 0 | H47: =COUNTIFS(FQ0835_p01!K$6:K$30,7,FQ0835_p01!D$6:D$30,A47,FQ0835_p01!L$6:L$30,"Não",FQ0835_p01!M$6:M$30,"Sim") -> 0 | I47: =COUNTIFS(FQ0835_p01!K$6:K$30,8,FQ0835_p01!D$6:D$30,A47,FQ0835_p01!L$6:L$30,"Não",FQ0835_p01!M$6:M$30,"Sim") -> 0 | J47: =COUNTIFS(FQ0835_p01!K$6:K$30,9,FQ0835_p01!D$6:D$30,A47,FQ0835_p01!L$6:L$30,"Não",FQ0835_p01!M$6:M$30,"Sim") -> 0 | K47: =COUNTIFS(FQ0835_p01!K$6:K$30,10,FQ0835_p01!D$6:D$30,A47,FQ0835_p01!L$6:L$30,"Não",FQ0835_p01!M$6:M$30,"Sim") -> 0 | L47: =COUNTIFS(FQ0835_p01!K$6:K$30,11,FQ0835_p01!D$6:D$30,A47,FQ0835_p01!L$6:L$30,"Não",FQ0835_p01!M$6:M$30,"Sim") -> 0 | M47: =COUNTIFS(FQ0835_p01!K$6:K$30,12,FQ0835_p01!D$6:D$30,A47,FQ0835_p01!L$6:L$30,"Não",FQ0835_p01!M$6:M$30,"Sim") -> 0 | N47: =SUM(B47:M47) -> 0
A48: Atraso de pagamento sem protesto | B48: =COUNTIFS(FQ0835_p01!K$6:K$30,1,FQ0835_p01!D$6:D$30,A48,FQ0835_p01!L$6:L$30,"Não",FQ0835_p01!M$6:M$30,"Sim") -> 0 | C48: =COUNTIFS(FQ0835_p01!K$6:K$30,2,FQ0835_p01!D$6:D$30,A48,FQ0835_p01!L$6:L$30,"Não",FQ0835_p01!M$6:M$30,"Sim") -> 0 | D48: =COUNTIFS(FQ0835_p01!K$6:K$30,3,FQ0835_p01!D$6:D$30,A48,FQ0835_p01!L$6:L$30,"Não") -> 0 | E48: =COUNTIFS(FQ0835_p01!K$6:K$30,4,FQ0835_p01!D$6:D$30,A48,FQ0835_p01!L$6:L$30,"Não",FQ0835_p01!M$6:M$30,"Sim") -> 0 | F48: =COUNTIFS(FQ0835_p01!K$6:K$30,5,FQ0835_p01!D$6:D$30,A48,FQ0835_p01!L$6:L$30,"Não",FQ0835_p01!M$6:M$30,"Sim") -> 0 | G48: =COUNTIFS(FQ0835_p01!K$6:K$30,6,FQ0835_p01!D$6:D$30,A48,FQ0835_p01!L$6:L$30,"Não",FQ0835_p01!M$6:M$30,"Sim") -> 0 | H48: =COUNTIFS(FQ0835_p01!K$6:K$30,7,FQ0835_p01!D$6:D$30,A48,FQ0835_p01!L$6:L$30,"Não",FQ0835_p01!M$6:M$30,"Sim") -> 0 | I48: =COUNTIFS(FQ0835_p01!K$6:K$30,8,FQ0835_p01!D$6:D$30,A48,FQ0835_p01!L$6:L$30,"Não",FQ0835_p01!M$6:M$30,"Sim") -> 0 | J48: =COUNTIFS(FQ0835_p01!K$6:K$30,9,FQ0835_p01!D$6:D$30,A48,FQ0835_p01!L$6:L$30,"Não",FQ0835_p01!M$6:M$30,"Sim") -> 0 | K48: =COUNTIFS(FQ0835_p01!K$6:K$30,10,FQ0835_p01!D$6:D$30,A48,FQ0835_p01!L$6:L$30,"Não",FQ0835_p01!M$6:M$30,"Sim") -> 0 | L48: =COUNTIFS(FQ0835_p01!K$6:K$30,11,FQ0835_p01!D$6:D$30,A48,FQ0835_p01!L$6:L$30,"Não",FQ0835_p01!M$6:M$30,"Sim") -> 0 | M48: =COUNTIFS(FQ0835_p01!K$6:K$30,12,FQ0835_p01!D$6:D$30,A48,FQ0835_p01!L$6:L$30,"Não",FQ0835_p01!M$6:M$30,"Sim") -> 0 | N48: =SUM(B48:M48) -> 0
A49: Pessoal | B49: =COUNTIFS(FQ0835_p01!K$6:K$30,1,FQ0835_p01!D$6:D$30,A49,FQ0835_p01!L$6:L$30,"Não",FQ0835_p01!M$6:M$30,"Sim") -> 0 | C49: =COUNTIFS(FQ0835_p01!K$6:K$30,2,FQ0835_p01!D$6:D$30,A49,FQ0835_p01!L$6:L$30,"Não",FQ0835_p01!M$6:M$30,"Sim") -> 0 | D49: =COUNTIFS(FQ0835_p01!K$6:K$30,3,FQ0835_p01!D$6:D$30,A49,FQ0835_p01!L$6:L$30,"Não") -> 0 | E49: =COUNTIFS(FQ0835_p01!K$6:K$30,4,FQ0835_p01!D$6:D$30,A49,FQ0835_p01!L$6:L$30,"Não",FQ0835_p01!M$6:M$30,"Sim") -> 0 | F49: =COUNTIFS(FQ0835_p01!K$6:K$30,5,FQ0835_p01!D$6:D$30,A49,FQ0835_p01!L$6:L$30,"Não",FQ0835_p01!M$6:M$30,"Sim") -> 0 | G49: =COUNTIFS(FQ0835_p01!K$6:K$30,6,FQ0835_p01!D$6:D$30,A49,FQ0835_p01!L$6:L$30,"Não",FQ0835_p01!M$6:M$30,"Sim") -> 0 | H49: =COUNTIFS(FQ0835_p01!K$6:K$30,7,FQ0835_p01!D$6:D$30,A49,FQ0835_p01!L$6:L$30,"Não",FQ0835_p01!M$6:M$30,"Sim") -> 0 | I49: =COUNTIFS(FQ0835_p01!K$6:K$30,8,FQ0835_p01!D$6:D$30,A49,FQ0835_p01!L$6:L$30,"Não",FQ0835_p01!M$6:M$30,"Sim") -> 0 | J49: =COUNTIFS(FQ0835_p01!K$6:K$30,9,FQ0835_p01!D$6:D$30,A49,FQ0835_p01!L$6:L$30,"Não",FQ0835_p01!M$6:M$30,"Sim") -> 0 | K49: =COUNTIFS(FQ0835_p01!K$6:K$30,10,FQ0835_p01!D$6:D$30,A49,FQ0835_p01!L$6:L$30,"Não",FQ0835_p01!M$6:M$30,"Sim") -> 0 | L49: =COUNTIFS(FQ0835_p01!K$6:K$30,11,FQ0835_p01!D$6:D$30,A49,FQ0835_p01!L$6:L$30,"Não",FQ0835_p01!M$6:M$30,"Sim") -> 0 | M49: =COUNTIFS(FQ0835_p01!K$6:K$30,12,FQ0835_p01!D$6:D$30,A49,FQ0835_p01!L$6:L$30,"Não",FQ0835_p01!M$6:M$30,"Sim") -> 0 | N49: =SUM(B49:M49) -> 0
...
