Workbook

Sheet Folha 1_13
A1: INDICADORES DO SISTEMA DE GESTÃO DA QUALIDADE
A3: ANO: | F3: Mês: JANEIRO | I3: Atualizado em:
A5: 1. INDICADORES/DADOS POR UNIDADE - COLETA MENSAL
A6: Nº | B6: Item | C6: TC | D6: CH | E6: TL | F6: FH | G6: CQ | H6: CE | I6: DG | J6: ITAL | K6: Observações
A7: I46 | B7: SAC solucionadas (%) | K7: -----------------------------------------------------------------
A8: I47 | B8: SAP solucionadas (%) | K8: -----------------------------------------------------------------
A9: I48 | B9: NCBI solucionadas (%) | K9: -----------------------------------------------------------------
A10: ------ | B10: Número de gestores | K10: -----------------------------------------------------------------
A11: 2. INDICADORES/DADOS ITAL - MENSAIS E/OU RESULTADOS GERAIS
A12: Nº | B12: Item | C12: JAN | D12: FEV | E12: MAR | F12: ABR | G12: MAI | H12: JUN | I12: JUL | J12: AGO | K12: SET | L12: OUT | M12: NOV | N12: DEZ | O12: TOTAL
A13: I12 | B13: Cumprimento às exigências fiscais municipais, federais e estaduais (número de falhas) | D13: ------------ | E13: ------------ | F13: ------------ | G13: ------------ | H13: ------------ | I13: ------------ | J13: ------------ | K13: ------------ | L13: ------------ | M13: ------------ | N13: ------------ | O13: =C13 -> 0
A14: I49 | B14: Ensaios acreditados na ABNT NBR ISO/IEC 17025. (Nº) | D14: ------------ | E14: ------------ | F14: ------------ | G14: ------------ | H14: ------------ | I14: ------------ | J14: ------------ | K14: ------------ | L14: ------------ | M14: ------------ | N14: ------------ | O14: =C14 -> 0
A15: I50 | B15: Habilitação do Ital junto à Reblas - Anvisa | D15: ------------ | E15: ------------ | F15: ------------ | G15: ------------ | H15: ------------ | I15: ------------ | J15: ------------ | K15: ------------ | L15: ------------ | M15: ------------ | N15: ------------ | O15: =C15 -> 0
A16: I51 | B16: Certificação do Sistema de Gestão da Qualidade - NBR ISO 9001 (Nº) | D16: ------------ | E16: ------------ | F16: ------------ | G16: ------------ | H16: ------------ | I16: ------------ | J16: ------------ | K16: ------------ | L16: ------------ | M16: ------------ | N16: ------------ | O16: =C16 -> 0
A17: I53 | B17: Qualificação de fornecedores (%) | D17: ------------ | E17: ------------ | F17: ------------ | G17: ------------ | H17: ------------ | I17: ------------ | J17: ------------ | K17: ------------ | L17: ------------ | M17: ------------ | N17: ------------ | O17: =C17 -> 0
A18: I60 | B18: Consumo de água (m3) | D18: ------------ | E18: ------------ | F18: ------------ | G18: ------------ | H18: ------------ | I18: ------------ | J18: ------------ | K18: ------------ | L18: ------------ | M18: ------------ | N18: ------------ | O18: =C18 -> 0
A19: I61 | B19: Consumo de energia elétrica (kWh) | D19: ------------ | E19: ------------ | F19: ------------ | G19: ------------ | H19: ------------ | I19: ------------ | J19: ------------ | K19: ------------ | L19: ------------ | M19: ------------ | N19: ------------ | O19: =C19 -> 0
A20: I62 | B20: Ações de conscientização - meio ambiente por ano (Nº) | D20: ------------ | E20: ------------ | F20: ------------ | G20: ------------ | H20: ------------ | I20: ------------ | J20: ------------ | K20: ------------ | L20: ------------ | M20: ------------ | N20: ------------ | O20: =C20 -> 0
A21: I63 | B21: Denúncias procedentes registradas pela CIC (Ética) | D21: ------------ | E21: ------------ | F21: ------------ | G21: ------------ | H21: ------------ | I21: ------------ | J21: ------------ | K21: ------------ | L21: ------------ | M21: ------------ | N21: ------------ | O21: =C21 -> 0
A22: D95 | B22: Inflação ano | D22: ------------ | E22: ------------ | F22: ------------ | G22: ------------ | H22: ------------ | I22: ------------ | J22: ------------ | K22: ------------ | L22: ------------ | M22: ------------ | N22: ------------ | O22: =C22 -> 0
A23: D78 | B23: Número de não conformidades registradas em auditoria de terceria parte (NBR ISO 9001) | D23: ------------ | E23: ------------ | F23: ------------ | G23: ------------ | H23: ------------ | I23: ------------ | J23: ------------ | K23: ------------ | L23: ------------ | M23: ------------ | N23: ------------ | O23: =C23 -> 0
A24: FQ-08.33 (anexo à IT-08.01.04) - RA - revisão 04 de 05/06/24 - Página 1/13

Sheet Folha 2_13 
A1: INDICADORES DO SISTEMA DE GESTÃO DA QUALIDADE
A3: ANO: | F3: Mês: FEVEREIRO | I3: Atualizado em:
A5: 1. INDICADORES/DADOS POR UNIDADE - COLETA MENSAL
A6: Nº | B6: Item | C6: TC | D6: CH | E6: TL | F6: FH | G6: CQ | H6: CE | I6: DG | J6: ITAL | K6: Observações
A7: ='Folha 1_13'!A7 -> I46 | B7: ='Folha 1_13'!B7 -> SAC solucionadas (%) | K7: -----------------------------------------------------------------
A8: ='Folha 1_13'!A8 -> I47 | B8: ='Folha 1_13'!B8 -> SAP solucionadas (%) | K8: -----------------------------------------------------------------
A9: ='Folha 1_13'!A9 -> I48 | B9: ='Folha 1_13'!B9 -> NCBI solucionadas (%) | K9: -----------------------------------------------------------------
A10: ='Folha 1_13'!A10 -> ------ | B10: ='Folha 1_13'!B10 -> Número de gestores | K10: -----------------------------------------------------------------
A11: 2. INDICADORES/DADOS ITAL - MENSAIS E/OU RESULTADOS GERAIS
A12: Nº | B12: Item | C12: JAN | D12: FEV | E12: MAR | F12: ABR | G12: MAI | H12: JUN | I12: JUL | J12: AGO | K12: SET | L12: OUT | M12: NOV | N12: DEZ | O12: TOTAL
A13: ='Folha 1_13'!A13 -> I12 | B13: ='Folha 1_13'!B13 -> Cumprimento às exigências fiscais municipais, federais e estaduais (número de falhas) | C13: ='Folha 1_13'!C13 -> 0 | E13: ------------ | F13: ------------ | G13: ------------ | H13: ------------ | I13: ------------ | J13: ------------ | K13: ------------ | L13: ------------ | M13: ------------ | N13: ------------ | O13: =C13 -> 0
A14: ='Folha 1_13'!A14 -> I49 | B14: ='Folha 1_13'!B14 -> Ensaios acreditados na ABNT NBR ISO/IEC 17025. (Nº) | C14: ='Folha 1_13'!C14 -> 0 | E14: ------------ | F14: ------------ | G14: ------------ | H14: ------------ | I14: ------------ | J14: ------------ | K14: ------------ | L14: ------------ | M14: ------------ | N14: ------------ | O14: =C14 -> 0
A15: ='Folha 1_13'!A15 -> I50 | B15: ='Folha 1_13'!B15 -> Habilitação do Ital junto à Reblas - Anvisa | C15: ='Folha 1_13'!C15 -> 0 | E15: ------------ | F15: ------------ | G15: ------------ | H15: ------------ | I15: ------------ | J15: ------------ | K15: ------------ | L15: ------------ | M15: ------------ | N15: ------------ | O15: =C15 -> 0
A16: ='Folha 1_13'!A16 -> I51 | B16: ='Folha 1_13'!B16 -> Certificação do Sistema de Gestão da Qualidade - NBR ISO 9001 (Nº) | C16: ='Folha 1_13'!C16 -> 0 | E16: ------------ | F16: ------------ | G16: ------------ | H16: ------------ | I16: ------------ | J16: ------------ | K16: ------------ | L16: ------------ | M16: ------------ | N16: ------------ | O16: =C16 -> 0
A17: ='Folha 1_13'!A17 -> I53 | B17: ='Folha 1_13'!B17 -> Qualificação de fornecedores (%) | C17: ='Folha 1_13'!C17 -> 0 | E17: ------------ | F17: ------------ | G17: ------------ | H17: ------------ | I17: ------------ | J17: ------------ | K17: ------------ | L17: ------------ | M17: ------------ | N17: ------------ | O17: =C17 -> 0
A18: ='Folha 1_13'!A18 -> I60 | B18: ='Folha 1_13'!B18 -> Consumo de água (m3) | C18: ='Folha 1_13'!C18 -> 0 | E18: ------------ | F18: ------------ | G18: ------------ | H18: ------------ | I18: ------------ | J18: ------------ | K18: ------------ | L18: ------------ | M18: ------------ | N18: ------------ | O18: =SUM(C18:D18) -> 0
A19: ='Folha 1_13'!A19 -> I61 | B19: ='Folha 1_13'!B19 -> Consumo de energia elétrica (kWh) | C19: ='Folha 1_13'!C19 -> 0 | E19: ------------ | F19: ------------ | G19: ------------ | H19: ------------ | I19: ------------ | J19: ------------ | K19: ------------ | L19: ------------ | M19: ------------ | N19: ------------ | O19: =SUM(C19:D19) -> 0
A20: ='Folha 1_13'!A20 -> I62 | B20: ='Folha 1_13'!B20 -> Ações de conscientização - meio ambiente por ano (Nº) | C20: ='Folha 1_13'!C20 -> 0 | E20: ------------ | F20: ------------ | G20: ------------ | H20: ------------ | I20: ------------ | J20: ------------ | K20: ------------ | L20: ------------ | M20: ------------ | N20: ------------ | O20: =SUM(C20:D20) -> 0
A21: ='Folha 1_13'!A21 -> I63 | B21: ='Folha 1_13'!B21 -> Denúncias procedentes registradas pela CIC (Ética) | C21: ='Folha 1_13'!C21 -> 0 | E21: ------------ | F21: ------------ | G21: ------------ | H21: ------------ | I21: ------------ | J21: ------------ | K21: ------------ | L21: ------------ | M21: ------------ | N21: ------------ | O21: =SUM(C21:D21) -> 0
A22: ='Folha 1_13'!A22 -> D95 | B22: ='Folha 1_13'!B22 -> Inflação ano | C22: ='Folha 1_13'!C22 -> 0 | E22: ------------ | F22: ------------ | G22: ------------ | H22: ------------ | I22: ------------ | J22: ------------ | K22: ------------ | L22: ------------ | M22: ------------ | N22: ------------ | O22: =SUM(C22:D22) -> 0
A23: ='Folha 1_13'!A23 -> D78 | B23: ='Folha 1_13'!B23 -> Número de não conformidades registradas em auditoria de terceria parte (NBR ISO 9001) | C23: ='Folha 1_13'!C23 -> 0 | E23: ------------ | F23: ------------ | G23: ------------ | H23: ------------ | I23: ------------ | J23: ------------ | K23: ------------ | L23: ------------ | M23: ------------ | N23: ------------ | O23: =SUM(C23:D23) -> 0
A24: FQ-08.33 (anexo à IT-08.01.04) - RA - revisão 04 de 05/06/24 - Página 2/13

Sheet Folha 3_13
A1: INDICADORES DO SISTEMA DE GESTÃO DA QUALIDADE
A3: ='Folha 1_13'!$A$3 -> ANO: | F3: Mês: MARÇO | I3: Atualizado em:
A5: 1. INDICADORES POR UNIDADE
A6: Nº | B6: Item | C6: TC | D6: CH | E6: TL | F6: FH | G6: CQ | H6: CE | I6: DG | J6: ITAL | K6: Observações
A7: ='Folha 1_13'!A7 -> I46 | B7: ='Folha 1_13'!B7 -> SAC solucionadas (%) | K7: -----------------------------------------------------------------
A8: ='Folha 1_13'!A8 -> I47 | B8: ='Folha 1_13'!B8 -> SAP solucionadas (%) | K8: -----------------------------------------------------------------
A9: ='Folha 1_13'!A9 -> I48 | B9: ='Folha 1_13'!B9 -> NCBI solucionadas (%) | K9: -----------------------------------------------------------------
A10: ='Folha 1_13'!A10 -> ------ | B10: ='Folha 1_13'!B10 -> Número de gestores | K10: -----------------------------------------------------------------
A11: 2. INDICADORES MENSAIS E/OU RESULTADOS GERAIS
A12: Nº | B12: Item | C12: JAN | D12: FEV | E12: MAR | F12: ABR | G12: MAI | H12: JUN | I12: JUL | J12: AGO | K12: SET | L12: OUT | M12: NOV | N12: DEZ | O12: TOTAL
A13: ='Folha 1_13'!A13 -> I12 | B13: ='Folha 1_13'!B13 -> Cumprimento às exigências fiscais municipais, federais e estaduais (número de falhas) | C13: ='Folha 1_13'!C13 -> 0 | D13: ='Folha 2_13 '!D13 -> 0 | F13: ------------ | G13: ------------ | H13: ------------ | I13: ------------ | J13: ------------ | K13: ------------ | L13: ------------ | M13: ------------ | N13: ------------ | O13: =E13 -> 0
A14: ='Folha 1_13'!A14 -> I49 | B14: ='Folha 1_13'!B14 -> Ensaios acreditados na ABNT NBR ISO/IEC 17025. (Nº) | C14: ='Folha 1_13'!C14 -> 0 | D14: ='Folha 2_13 '!D14 -> 0 | F14: ------------ | G14: ------------ | H14: ------------ | I14: ------------ | J14: ------------ | K14: ------------ | L14: ------------ | M14: ------------ | N14: ------------ | O14: =E14 -> 0
A15: ='Folha 1_13'!A15 -> I50 | B15: ='Folha 1_13'!B15 -> Habilitação do Ital junto à Reblas - Anvisa | C15: ='Folha 1_13'!C15 -> 0 | D15: ='Folha 2_13 '!D15 -> 0 | F15: ------------ | G15: ------------ | H15: ------------ | I15: ------------ | J15: ------------ | K15: ------------ | L15: ------------ | M15: ------------ | N15: ------------ | O15: =E15 -> 0
A16: ='Folha 1_13'!A16 -> I51 | B16: ='Folha 1_13'!B16 -> Certificação do Sistema de Gestão da Qualidade - NBR ISO 9001 (Nº) | C16: ='Folha 1_13'!C16 -> 0 | D16: ='Folha 2_13 '!D16 -> 0 | F16: ------------ | G16: ------------ | H16: ------------ | I16: ------------ | J16: ------------ | K16: ------------ | L16: ------------ | M16: ------------ | N16: ------------ | O16: =E16 -> 0
A17: ='Folha 1_13'!A17 -> I53 | B17: ='Folha 1_13'!B17 -> Qualificação de fornecedores (%) | C17: ='Folha 1_13'!C17 -> 0 | D17: ='Folha 2_13 '!D17 -> 0 | F17: ------------ | G17: ------------ | H17: ------------ | I17: ------------ | J17: ------------ | K17: ------------ | L17: ------------ | M17: ------------ | N17: ------------ | O17: =E17 -> 0
A18: ='Folha 1_13'!A18 -> I60 | B18: ='Folha 1_13'!B18 -> Consumo de água (m3) | C18: ='Folha 1_13'!C18 -> 0 | D18: ='Folha 2_13 '!D18 -> 0 | F18: ------------ | G18: ------------ | H18: ------------ | I18: ------------ | J18: ------------ | K18: ------------ | L18: ------------ | M18: ------------ | N18: ------------ | O18: =SUM(C18:E18) -> 0
A19: ='Folha 1_13'!A19 -> I61 | B19: ='Folha 1_13'!B19 -> Consumo de energia elétrica (kWh) | C19: ='Folha 1_13'!C19 -> 0 | D19: ='Folha 2_13 '!D19 -> 0 | F19: ------------ | G19: ------------ | H19: ------------ | I19: ------------ | J19: ------------ | K19: ------------ | L19: ------------ | M19: ------------ | N19: ------------ | O19: =SUM(C19:E19) -> 0
A20: ='Folha 1_13'!A20 -> I62 | B20: ='Folha 1_13'!B20 -> Ações de conscientização - meio ambiente por ano (Nº) | C20: ='Folha 1_13'!C20 -> 0 | D20: ='Folha 2_13 '!D20 -> 0 | F20: ------------ | G20: ------------ | H20: ------------ | I20: ------------ | J20: ------------ | K20: ------------ | L20: ------------ | M20: ------------ | N20: ------------ | O20: =SUM(C20:E20) -> 0
A21: ='Folha 1_13'!A21 -> I63 | B21: ='Folha 1_13'!B21 -> Denúncias procedentes registradas pela CIC (Ética) | C21: ='Folha 1_13'!C21 -> 0 | D21: ='Folha 2_13 '!D21 -> 0 | F21: ------------ | G21: ------------ | H21: ------------ | I21: ------------ | J21: ------------ | K21: ------------ | L21: ------------ | M21: ------------ | N21: ------------ | O21: =SUM(C21:E21) -> 0
A22: ='Folha 1_13'!A22 -> D95 | B22: ='Folha 1_13'!B22 -> Inflação ano | C22: ='Folha 1_13'!C21 -> 0 | D22: ='Folha 2_13 '!D21 -> 0 | F22: ------------ | G22: ------------ | H22: ------------ | I22: ------------ | J22: ------------ | K22: ------------ | L22: ------------ | M22: ------------ | N22: ------------ | O22: =SUM(C22:E22) -> 0
A23: ='Folha 1_13'!A23 -> D78 | B23: ='Folha 1_13'!B23 -> Número de não conformidades registradas em auditoria de terceria parte (NBR ISO 9001) | C23: ='Folha 1_13'!C22 -> 0 | D23: ='Folha 2_13 '!D22 -> 0 | F23: ------------ | G23: ------------ | H23: ------------ | I23: ------------ | J23: ------------ | K23: ------------ | L23: ------------ | M23: ------------ | N23: ------------ | O23: =SUM(C23:E23) -> 0
A24: FQ-08.33 (anexo à IT-08.01.04) - RA - revisão 04 de 05/06/24 - Página 3/13

Sheet Folha 4_13
A1: INDICADORES DO SISTEMA DE GESTÃO DA QUALIDADE
A3: ='Folha 1_13'!$A$3 -> ANO: | F3: Mês: ABRIL | I3: Atualizado em:
A5: 1. INDICADORES POR UNIDADE
A6: Nº | B6: Item | C6: TC | D6: CH | E6: TL | F6: FH | G6: CQ | H6: CE | I6: DG | J6: ITAL | K6: Observações
A7: ='Folha 1_13'!A7 -> I46 | B7: ='Folha 1_13'!B7 -> SAC solucionadas (%) | K7: -----------------------------------------------------------------
A8: ='Folha 1_13'!A8 -> I47 | B8: ='Folha 1_13'!B8 -> SAP solucionadas (%) | K8: -----------------------------------------------------------------
A9: ='Folha 1_13'!A9 -> I48 | B9: ='Folha 1_13'!B9 -> NCBI solucionadas (%) | K9: -----------------------------------------------------------------
A10: ='Folha 1_13'!A10 -> ------ | B10: ='Folha 1_13'!B10 -> Número de gestores | K10: -----------------------------------------------------------------
A11: 2. INDICADORES MENSAIS E/OU RESULTADOS GERAIS
A12: Nº | B12: Item | C12: JAN | D12: FEV | E12: MAR | F12: ABR | G12: MAI | H12: JUN | I12: JUL | J12: AGO | K12: SET | L12: OUT | M12: NOV | N12: DEZ | O12: TOTAL
A13: ='Folha 1_13'!A13 -> I12 | B13: ='Folha 1_13'!B13 -> Cumprimento às exigências fiscais municipais, federais e estaduais (número de falhas) | C13: ='Folha 3_13'!C13 -> 0 | D13: ='Folha 3_13'!D13 -> 0 | E13: ='Folha 3_13'!E13 -> 0 | G13: ------------ | H13: ------------ | I13: ------------ | J13: ------------ | K13: ------------ | L13: ------------ | M13: ------------ | N13: ------------ | O13: =F13 -> 0
A14: ='Folha 1_13'!A14 -> I49 | B14: ='Folha 1_13'!B14 -> Ensaios acreditados na ABNT NBR ISO/IEC 17025. (Nº) | C14: ='Folha 3_13'!C14 -> 0 | D14: ='Folha 3_13'!D14 -> 0 | E14: ='Folha 3_13'!E14 -> 0 | G14: ------------ | H14: ------------ | I14: ------------ | J14: ------------ | K14: ------------ | L14: ------------ | M14: ------------ | N14: ------------ | O14: =F14 -> 0
A15: ='Folha 1_13'!A15 -> I50 | B15: ='Folha 1_13'!B15 -> Habilitação do Ital junto à Reblas - Anvisa | C15: ='Folha 3_13'!C15 -> 0 | D15: ='Folha 3_13'!D15 -> 0 | E15: ='Folha 3_13'!E15 -> 0 | G15: ------------ | H15: ------------ | I15: ------------ | J15: ------------ | K15: ------------ | L15: ------------ | M15: ------------ | N15: ------------ | O15: =F15 -> 0
A16: ='Folha 1_13'!A16 -> I51 | B16: ='Folha 1_13'!B16 -> Certificação do Sistema de Gestão da Qualidade - NBR ISO 9001 (Nº) | C16: ='Folha 3_13'!C16 -> 0 | D16: ='Folha 3_13'!D16 -> 0 | E16: ='Folha 3_13'!E16 -> 0 | G16: ------------ | H16: ------------ | I16: ------------ | J16: ------------ | K16: ------------ | L16: ------------ | M16: ------------ | N16: ------------ | O16: =F16 -> 0
A17: ='Folha 1_13'!A17 -> I53 | B17: ='Folha 1_13'!B17 -> Qualificação de fornecedores (%) | C17: ='Folha 3_13'!C17 -> 0 | D17: ='Folha 3_13'!D17 -> 0 | E17: ='Folha 3_13'!E17 -> 0 | G17: ------------ | H17: ------------ | I17: ------------ | J17: ------------ | K17: ------------ | L17: ------------ | M17: ------------ | N17: ------------ | O17: =F17 -> 0
A18: ='Folha 1_13'!A18 -> I60 | B18: ='Folha 1_13'!B18 -> Consumo de água (m3) | C18: ='Folha 3_13'!C18 -> 0 | D18: ='Folha 3_13'!D18 -> 0 | E18: ='Folha 3_13'!E18 -> 0 | G18: ------------ | H18: ------------ | I18: ------------ | J18: ------------ | K18: ------------ | L18: ------------ | M18: ------------ | N18: ------------ | O18: =SUM(C18:F18) -> 0
A19: ='Folha 1_13'!A19 -> I61 | B19: ='Folha 1_13'!B19 -> Consumo de energia elétrica (kWh) | C19: ='Folha 3_13'!C19 -> 0 | D19: ='Folha 3_13'!D19 -> 0 | E19: ='Folha 3_13'!E19 -> 0 | G19: ------------ | H19: ------------ | I19: ------------ | J19: ------------ | K19: ------------ | L19: ------------ | M19: ------------ | N19: ------------ | O19: =SUM(C19:F19) -> 0
A20: ='Folha 1_13'!A20 -> I62 | B20: ='Folha 1_13'!B20 -> Ações de conscientização - meio ambiente por ano (Nº) | C20: ='Folha 3_13'!C20 -> 0 | D20: ='Folha 3_13'!D20 -> 0 | E20: ='Folha 3_13'!E20 -> 0 | G20: ------------ | H20: ------------ | I20: ------------ | J20: ------------ | K20: ------------ | L20: ------------ | M20: ------------ | N20: ------------ | O20: =SUM(C20:F20) -> 0
A21: ='Folha 1_13'!A21 -> I63 | B21: ='Folha 1_13'!B21 -> Denúncias procedentes registradas pela CIC (Ética) | C21: ='Folha 3_13'!C22 -> 0 | D21: ='Folha 3_13'!D22 -> 0 | E21: ='Folha 3_13'!E22 -> 0 | G21: ------------ | H21: ------------ | I21: ------------ | J21: ------------ | K21: ------------ | L21: ------------ | M21: ------------ | N21: ------------ | O21: =SUM(C21:F21) -> 0
A22: ='Folha 1_13'!A22 -> D95 | B22: ='Folha 1_13'!B22 -> Inflação ano | C22: ='Folha 3_13'!C22 -> 0 | D22: ='Folha 3_13'!D22 -> 0 | E22: ='Folha 3_13'!E22 -> 0 | G22: ------------ | H22: ------------ | I22: ------------ | J22: ------------ | K22: ------------ | L22: ------------ | M22: ------------ | N22: ------------ | O22: =SUM(C22:F22) -> 0
A23: ='Folha 1_13'!A23 -> D78 | B23: ='Folha 1_13'!B23 -> Número de não conformidades registradas em auditoria de terceria parte (NBR ISO 9001) | C23: ='Folha 3_13'!C23 -> 0 | D23: ='Folha 3_13'!D23 -> 0 | E23: ='Folha 3_13'!E23 -> 0 | G23: ------------ | H23: ------------ | I23: ------------ | J23: ------------ | K23: ------------ | L23: ------------ | M23: ------------ | N23: ------------ | O23: =SUM(C23:F23) -> 0
A24: FQ-08.33 (anexo à IT-08.01.04) - RA - revisão 04 de 05/06/24 - Página 4/13

Sheet Folha 5_13
A1: INDICADORES DO SISTEMA DE GESTÃO DA QUALIDADE
A3: ='Folha 1_13'!$A$3 -> ANO: | F3: Mês: MAIO | I3: Atualizado em:
A5: 1. INDICADORES POR UNIDADE
A6: Nº | B6: Item | C6: TC | D6: CH | E6: TL | F6: FH | G6: CQ | H6: CE | I6: DG | J6: ITAL | K6: Observações
A7: ='Folha 1_13'!A7 -> I46 | B7: ='Folha 1_13'!B7 -> SAC solucionadas (%) | K7: -----------------------------------------------------------------
A8: ='Folha 1_13'!A8 -> I47 | B8: ='Folha 1_13'!B8 -> SAP solucionadas (%) | K8: -----------------------------------------------------------------
A9: ='Folha 1_13'!A9 -> I48 | B9: ='Folha 1_13'!B9 -> NCBI solucionadas (%) | K9: -----------------------------------------------------------------
A10: ='Folha 1_13'!A10 -> ------ | B10: ='Folha 1_13'!B10 -> Número de gestores | K10: -----------------------------------------------------------------
A11: 2. INDICADORES MENSAIS E/OU RESULTADOS GERAIS
A12: Nº | B12: Item | C12: JAN | D12: FEV | E12: MAR | F12: ABR | G12: MAI | H12: JUN | I12: JUL | J12: AGO | K12: SET | L12: OUT | M12: NOV | N12: DEZ | O12: TOTAL
A13: ='Folha 1_13'!A13 -> I12 | B13: ='Folha 1_13'!B13 -> Cumprimento às exigências fiscais municipais, federais e estaduais (número de falhas) | C13: ='Folha 4_13'!C13 -> 0 | D13: ='Folha 4_13'!D13 -> 0 | E13: ='Folha 4_13'!E13 -> 0 | F13: ='Folha 4_13'!F13 -> 0 | H13: ------------ | I13: ------------ | J13: ------------ | K13: ------------ | L13: ------------ | M13: ------------ | N13: ------------ | O13: =G13 -> 0
A14: ='Folha 1_13'!A14 -> I49 | B14: ='Folha 1_13'!B14 -> Ensaios acreditados na ABNT NBR ISO/IEC 17025. (Nº) | C14: ='Folha 4_13'!C14 -> 0 | D14: ='Folha 4_13'!D14 -> 0 | E14: ='Folha 4_13'!E14 -> 0 | F14: ='Folha 4_13'!F14 -> 0 | H14: ------------ | I14: ------------ | J14: ------------ | K14: ------------ | L14: ------------ | M14: ------------ | N14: ------------ | O14: =G14 -> 0
A15: ='Folha 1_13'!A15 -> I50 | B15: ='Folha 1_13'!B15 -> Habilitação do Ital junto à Reblas - Anvisa | C15: ='Folha 4_13'!C15 -> 0 | D15: ='Folha 4_13'!D15 -> 0 | E15: ='Folha 4_13'!E15 -> 0 | F15: ='Folha 4_13'!F15 -> 0 | H15: ------------ | I15: ------------ | J15: ------------ | K15: ------------ | L15: ------------ | M15: ------------ | N15: ------------ | O15: =G15 -> 0
A16: ='Folha 1_13'!A16 -> I51 | B16: ='Folha 1_13'!B16 -> Certificação do Sistema de Gestão da Qualidade - NBR ISO 9001 (Nº) | C16: ='Folha 4_13'!C16 -> 0 | D16: ='Folha 4_13'!D16 -> 0 | E16: ='Folha 4_13'!E16 -> 0 | F16: ='Folha 4_13'!F16 -> 0 | H16: ------------ | I16: ------------ | J16: ------------ | K16: ------------ | L16: ------------ | M16: ------------ | N16: ------------ | O16: =G16 -> 0
A17: ='Folha 1_13'!A17 -> I53 | B17: ='Folha 1_13'!B17 -> Qualificação de fornecedores (%) | C17: ='Folha 4_13'!C17 -> 0 | D17: ='Folha 4_13'!D17 -> 0 | E17: ='Folha 4_13'!E17 -> 0 | F17: ='Folha 4_13'!F17 -> 0 | H17: ------------ | I17: ------------ | J17: ------------ | K17: ------------ | L17: ------------ | M17: ------------ | N17: ------------ | O17: =G17 -> 0
A18: ='Folha 1_13'!A18 -> I60 | B18: ='Folha 1_13'!B18 -> Consumo de água (m3) | C18: ='Folha 4_13'!C18 -> 0 | D18: ='Folha 4_13'!D18 -> 0 | E18: ='Folha 4_13'!E18 -> 0 | F18: ='Folha 4_13'!F18 -> 0 | H18: ------------ | I18: ------------ | J18: ------------ | K18: ------------ | L18: ------------ | M18: ------------ | N18: ------------ | O18: =SUM(C18:G18) -> 0
A19: ='Folha 1_13'!A19 -> I61 | B19: ='Folha 1_13'!B19 -> Consumo de energia elétrica (kWh) | C19: ='Folha 4_13'!C19 -> 0 | D19: ='Folha 4_13'!D19 -> 0 | E19: ='Folha 4_13'!E19 -> 0 | F19: ='Folha 4_13'!F19 -> 0 | H19: ------------ | I19: ------------ | J19: ------------ | K19: ------------ | L19: ------------ | M19: ------------ | N19: ------------ | O19: =SUM(C19:G19) -> 0
A20: ='Folha 1_13'!A20 -> I62 | B20: ='Folha 1_13'!B20 -> Ações de conscientização - meio ambiente por ano (Nº) | C20: ='Folha 4_13'!C20 -> 0 | D20: ='Folha 4_13'!D20 -> 0 | E20: ='Folha 4_13'!E20 -> 0 | F20: ='Folha 4_13'!F20 -> 0 | H20: ------------ | I20: ------------ | J20: ------------ | K20: ------------ | L20: ------------ | M20: ------------ | N20: ------------ | O20: =SUM(C20:G20) -> 0
A21: ='Folha 1_13'!A21 -> I63 | B21: ='Folha 1_13'!B21 -> Denúncias procedentes registradas pela CIC (Ética) | C21: ='Folha 4_13'!C21 -> 0 | D21: ='Folha 4_13'!D21 -> 0 | E21: ='Folha 4_13'!E21 -> 0 | F21: ='Folha 4_13'!F21 -> 0 | H21: ------------ | I21: ------------ | J21: ------------ | K21: ------------ | L21: ------------ | M21: ------------ | N21: ------------ | O21: =SUM(C21:G21) -> 0
A22: ='Folha 1_13'!A22 -> D95 | B22: ='Folha 1_13'!B22 -> Inflação ano | C22: ='Folha 4_13'!C22 -> 0 | D22: ='Folha 4_13'!D22 -> 0 | E22: ='Folha 4_13'!E22 -> 0 | F22: ='Folha 4_13'!F22 -> 0 | H22: ------------ | I22: ------------ | J22: ------------ | K22: ------------ | L22: ------------ | M22: ------------ | N22: ------------ | O22: =SUM(C22:G22) -> 0
A23: ='Folha 1_13'!A23 -> D78 | B23: ='Folha 1_13'!B23 -> Número de não conformidades registradas em auditoria de terceria parte (NBR ISO 9001) | C23: ='Folha 4_13'!C23 -> 0 | D23: ='Folha 4_13'!D23 -> 0 | E23: ='Folha 4_13'!E23 -> 0 | F23: ='Folha 4_13'!F23 -> 0 | H23: ------------ | I23: ------------ | J23: ------------ | K23: ------------ | L23: ------------ | M23: ------------ | N23: ------------ | O23: =SUM(C23:G23) -> 0
A24: FQ-08.33 (anexo à IT-08.01.04) - RA - revisão 04 de 05/06/24 - Página 5/13

Sheet Folha 6_13
A1: INDICADORES DO SISTEMA DE GESTÃO DA QUALIDADE
A3: ='Folha 1_13'!$A$3 -> ANO: | F3: Mês: JUNHO | I3: Atualizado em:
A5: 1. INDICADORES POR UNIDADE
A6: Nº | B6: Item | C6: TC | D6: CH | E6: TL | F6: FH | G6: CQ | H6: CE | I6: DG | J6: ITAL | K6: Observações
A7: ='Folha 1_13'!A7 -> I46 | B7: ='Folha 1_13'!B7 -> SAC solucionadas (%) | K7: -----------------------------------------------------------------
A8: ='Folha 1_13'!A8 -> I47 | B8: ='Folha 1_13'!B8 -> SAP solucionadas (%) | K8: -----------------------------------------------------------------
A9: ='Folha 1_13'!A9 -> I48 | B9: ='Folha 1_13'!B9 -> NCBI solucionadas (%) | K9: -----------------------------------------------------------------
A10: ='Folha 1_13'!A10 -> ------ | B10: ='Folha 1_13'!B10 -> Número de gestores | K10: -----------------------------------------------------------------
A11: 2. INDICADORES MENSAIS E/OU RESULTADOS GERAIS
A12: Nº | B12: Item | C12: JAN | D12: FEV | E12: MAR | F12: ABR | G12: MAI | H12: JUN | I12: JUL | J12: AGO | K12: SET | L12: OUT | M12: NOV | N12: DEZ | O12: TOTAL
A13: ='Folha 1_13'!A13 -> I12 | B13: ='Folha 1_13'!B13 -> Cumprimento às exigências fiscais municipais, federais e estaduais (número de falhas) | C13: ='Folha 5_13'!C13 -> 0 | D13: ='Folha 5_13'!D13 -> 0 | E13: ='Folha 5_13'!E13 -> 0 | F13: ='Folha 5_13'!F13 -> 0 | G13: ='Folha 5_13'!G13 -> 0 | I13: ------------ | J13: ------------ | K13: ------------ | L13: ------------ | M13: ------------ | N13: ------------ | O13: =H13 -> 0
A14: ='Folha 1_13'!A14 -> I49 | B14: ='Folha 1_13'!B14 -> Ensaios acreditados na ABNT NBR ISO/IEC 17025. (Nº) | C14: ='Folha 5_13'!C14 -> 0 | D14: ='Folha 5_13'!D14 -> 0 | E14: ='Folha 5_13'!E14 -> 0 | F14: ='Folha 5_13'!F14 -> 0 | G14: ='Folha 5_13'!G14 -> 0 | I14: ------------ | J14: ------------ | K14: ------------ | L14: ------------ | M14: ------------ | N14: ------------ | O14: =H14 -> 0
A15: ='Folha 1_13'!A15 -> I50 | B15: ='Folha 1_13'!B15 -> Habilitação do Ital junto à Reblas - Anvisa | C15: ='Folha 5_13'!C15 -> 0 | D15: ='Folha 5_13'!D15 -> 0 | E15: ='Folha 5_13'!E15 -> 0 | F15: ='Folha 5_13'!F15 -> 0 | G15: ='Folha 5_13'!G15 -> 0 | I15: ------------ | J15: ------------ | K15: ------------ | L15: ------------ | M15: ------------ | N15: ------------ | O15: =H15 -> 0
A16: ='Folha 1_13'!A16 -> I51 | B16: ='Folha 1_13'!B16 -> Certificação do Sistema de Gestão da Qualidade - NBR ISO 9001 (Nº) | C16: ='Folha 5_13'!C16 -> 0 | D16: ='Folha 5_13'!D16 -> 0 | E16: ='Folha 5_13'!E16 -> 0 | F16: ='Folha 5_13'!F16 -> 0 | G16: ='Folha 5_13'!G16 -> 0 | I16: ------------ | J16: ------------ | K16: ------------ | L16: ------------ | M16: ------------ | N16: ------------ | O16: =H16 -> 0
A17: ='Folha 1_13'!A17 -> I53 | B17: ='Folha 1_13'!B17 -> Qualificação de fornecedores (%) | C17: ='Folha 5_13'!C17 -> 0 | D17: ='Folha 5_13'!D17 -> 0 | E17: ='Folha 5_13'!E17 -> 0 | F17: ='Folha 5_13'!F17 -> 0 | G17: ='Folha 5_13'!G17 -> 0 | I17: ------------ | J17: ------------ | K17: ------------ | L17: ------------ | M17: ------------ | N17: ------------ | O17: =H17 -> 0
A18: ='Folha 1_13'!A18 -> I60 | B18: ='Folha 1_13'!B18 -> Consumo de água (m3) | C18: ='Folha 5_13'!C18 -> 0 | D18: ='Folha 5_13'!D18 -> 0 | E18: ='Folha 5_13'!E18 -> 0 | F18: ='Folha 5_13'!F18 -> 0 | G18: ='Folha 5_13'!G18 -> 0 | I18: ------------ | J18: ------------ | K18: ------------ | L18: ------------ | M18: ------------ | N18: ------------ | O18: =SUM(C18:H18) -> 0
A19: ='Folha 1_13'!A19 -> I61 | B19: ='Folha 1_13'!B19 -> Consumo de energia elétrica (kWh) | C19: ='Folha 5_13'!C19 -> 0 | D19: ='Folha 5_13'!D19 -> 0 | E19: ='Folha 5_13'!E19 -> 0 | F19: ='Folha 5_13'!F19 -> 0 | G19: ='Folha 5_13'!G19 -> 0 | I19: ------------ | J19: ------------ | K19: ------------ | L19: ------------ | M19: ------------ | N19: ------------ | O19: =SUM(C19:H19) -> 0
A20: ='Folha 1_13'!A20 -> I62 | B20: ='Folha 1_13'!B20 -> Ações de conscientização - meio ambiente por ano (Nº) | C20: ='Folha 5_13'!C20 -> 0 | D20: ='Folha 5_13'!D20 -> 0 | E20: ='Folha 5_13'!E20 -> 0 | F20: ='Folha 5_13'!F20 -> 0 | G20: ='Folha 5_13'!G20 -> 0 | I20: ------------ | J20: ------------ | K20: ------------ | L20: ------------ | M20: ------------ | N20: ------------ | O20: =SUM(C20:H20) -> 0
A21: ='Folha 1_13'!A21 -> I63 | B21: ='Folha 1_13'!B21 -> Denúncias procedentes registradas pela CIC (Ética) | C21: ='Folha 5_13'!C21 -> 0 | D21: ='Folha 5_13'!D21 -> 0 | E21: ='Folha 5_13'!E21 -> 0 | F21: ='Folha 5_13'!F21 -> 0 | G21: ='Folha 5_13'!G21 -> 0 | I21: ------------ | J21: ------------ | K21: ------------ | L21: ------------ | M21: ------------ | N21: ------------ | O21: =SUM(C21:H21) -> 0
A22: ='Folha 1_13'!A22 -> D95 | B22: ='Folha 1_13'!B22 -> Inflação ano | C22: ='Folha 5_13'!C22 -> 0 | D22: ='Folha 5_13'!D22 -> 0 | E22: ='Folha 5_13'!E22 -> 0 | F22: ='Folha 5_13'!F22 -> 0 | G22: ='Folha 5_13'!G22 -> 0 | I22: ------------ | J22: ------------ | K22: ------------ | L22: ------------ | M22: ------------ | N22: ------------ | O22: =SUM(C22:H22) -> 0
A23: ='Folha 1_13'!A23 -> D78 | B23: ='Folha 1_13'!B23 -> Número de não conformidades registradas em auditoria de terceria parte (NBR ISO 9001) | C23: ='Folha 5_13'!C23 -> 0 | D23: ='Folha 5_13'!D23 -> 0 | E23: ='Folha 5_13'!E23 -> 0 | F23: ='Folha 5_13'!F23 -> 0 | G23: ='Folha 5_13'!G23 -> 0 | I23: ------------ | J23: ------------ | K23: ------------ | L23: ------------ | M23: ------------ | N23: ------------ | O23: =SUM(C23:H23) -> 0
A24: FQ-08.33 (anexo à IT-08.01.04) - RA - revisão 04 de 05/06/24 - Página 6/13

Sheet Folha 7_13
A1: INDICADORES DO SISTEMA DE GESTÃO DA QUALIDADE
A3: ='Folha 1_13'!$A$3 -> ANO: | F3: Mês: JULHO | I3: Atualizado em:
A5: 1. INDICADORES POR UNIDADE
A6: Nº | B6: Item | C6: TC | D6: CH | E6: TL | F6: FH | G6: CQ | H6: CE | I6: DG | J6: ITAL | K6: Observações
A7: ='Folha 1_13'!A7 -> I46 | B7: ='Folha 1_13'!B7 -> SAC solucionadas (%) | K7: -----------------------------------------------------------------
A8: ='Folha 1_13'!A8 -> I47 | B8: ='Folha 1_13'!B8 -> SAP solucionadas (%) | K8: -----------------------------------------------------------------
A9: ='Folha 1_13'!A9 -> I48 | B9: ='Folha 1_13'!B9 -> NCBI solucionadas (%) | K9: -----------------------------------------------------------------
A10: ='Folha 1_13'!A10 -> ------ | B10: ='Folha 1_13'!B10 -> Número de gestores | K10: -----------------------------------------------------------------
A11: 2. INDICADORES MENSAIS E/OU RESULTADOS GERAIS
A12: Nº | B12: Item | C12: JAN | D12: FEV | E12: MAR | F12: ABR | G12: MAI | H12: JUN | I12: JUL | J12: AGO | K12: SET | L12: OUT | M12: NOV | N12: DEZ | O12: TOTAL
A13: ='Folha 1_13'!A13 -> I12 | B13: ='Folha 1_13'!B13 -> Cumprimento às exigências fiscais municipais, federais e estaduais (número de falhas) | C13: ='Folha 6_13'!C13 -> 0 | D13: ='Folha 6_13'!D13 -> 0 | E13: ='Folha 6_13'!E13 -> 0 | F13: ='Folha 6_13'!F13 -> 0 | G13: ='Folha 6_13'!G13 -> 0 | H13: ='Folha 6_13'!H13 -> 0 | J13: ------------ | K13: ------------ | L13: ------------ | M13: ------------ | N13: ------------ | O13: =I13 -> 0
A14: ='Folha 1_13'!A14 -> I49 | B14: ='Folha 1_13'!B14 -> Ensaios acreditados na ABNT NBR ISO/IEC 17025. (Nº) | C14: ='Folha 6_13'!C14 -> 0 | D14: ='Folha 6_13'!D14 -> 0 | E14: ='Folha 6_13'!E14 -> 0 | F14: ='Folha 6_13'!F14 -> 0 | G14: ='Folha 6_13'!G14 -> 0 | H14: ='Folha 6_13'!H14 -> 0 | J14: ------------ | K14: ------------ | L14: ------------ | M14: ------------ | N14: ------------ | O14: =I14 -> 0
A15: ='Folha 1_13'!A15 -> I50 | B15: ='Folha 1_13'!B15 -> Habilitação do Ital junto à Reblas - Anvisa | C15: ='Folha 6_13'!C15 -> 0 | D15: ='Folha 6_13'!D15 -> 0 | E15: ='Folha 6_13'!E15 -> 0 | F15: ='Folha 6_13'!F15 -> 0 | G15: ='Folha 6_13'!G15 -> 0 | H15: ='Folha 6_13'!H15 -> 0 | J15: ------------ | K15: ------------ | L15: ------------ | M15: ------------ | N15: ------------ | O15: =I15 -> 0
A16: ='Folha 1_13'!A16 -> I51 | B16: ='Folha 1_13'!B16 -> Certificação do Sistema de Gestão da Qualidade - NBR ISO 9001 (Nº) | C16: ='Folha 6_13'!C16 -> 0 | D16: ='Folha 6_13'!D16 -> 0 | E16: ='Folha 6_13'!E16 -> 0 | F16: ='Folha 6_13'!F16 -> 0 | G16: ='Folha 6_13'!G16 -> 0 | H16: ='Folha 6_13'!H16 -> 0 | J16: ------------ | K16: ------------ | L16: ------------ | M16: ------------ | N16: ------------ | O16: =I16 -> 0
A17: ='Folha 1_13'!A17 -> I53 | B17: ='Folha 1_13'!B17 -> Qualificação de fornecedores (%) | C17: ='Folha 6_13'!C17 -> 0 | D17: ='Folha 6_13'!D17 -> 0 | E17: ='Folha 6_13'!E17 -> 0 | F17: ='Folha 6_13'!F17 -> 0 | G17: ='Folha 6_13'!G17 -> 0 | H17: ='Folha 6_13'!H17 -> 0 | J17: ------------ | K17: ------------ | L17: ------------ | M17: ------------ | N17: ------------ | O17: =I17 -> 0
A18: ='Folha 1_13'!A18 -> I60 | B18: ='Folha 1_13'!B18 -> Consumo de água (m3) | C18: ='Folha 6_13'!C18 -> 0 | D18: ='Folha 6_13'!D18 -> 0 | E18: ='Folha 6_13'!E18 -> 0 | F18: ='Folha 6_13'!F18 -> 0 | G18: ='Folha 6_13'!G18 -> 0 | H18: ='Folha 6_13'!H18 -> 0 | J18: ------------ | K18: ------------ | L18: ------------ | M18: ------------ | N18: ------------ | O18: =SUM(C18:I18) -> 0
A19: ='Folha 1_13'!A19 -> I61 | B19: ='Folha 1_13'!B19 -> Consumo de energia elétrica (kWh) | C19: ='Folha 6_13'!C19 -> 0 | D19: ='Folha 6_13'!D19 -> 0 | E19: ='Folha 6_13'!E19 -> 0 | F19: ='Folha 6_13'!F19 -> 0 | G19: ='Folha 6_13'!G19 -> 0 | H19: ='Folha 6_13'!H19 -> 0 | J19: ------------ | K19: ------------ | L19: ------------ | M19: ------------ | N19: ------------ | O19: =SUM(C19:I19) -> 0
A20: ='Folha 1_13'!A20 -> I62 | B20: ='Folha 1_13'!B20 -> Ações de conscientização - meio ambiente por ano (Nº) | C20: ='Folha 6_13'!C20 -> 0 | D20: ='Folha 6_13'!D20 -> 0 | E20: ='Folha 6_13'!E20 -> 0 | F20: ='Folha 6_13'!F20 -> 0 | G20: ='Folha 6_13'!G20 -> 0 | H20: ='Folha 6_13'!H20 -> 0 | J20: ------------ | K20: ------------ | L20: ------------ | M20: ------------ | N20: ------------ | O20: =SUM(C20:I20) -> 0
A21: ='Folha 1_13'!A21 -> I63 | B21: ='Folha 1_13'!B21 -> Denúncias procedentes registradas pela CIC (Ética) | C21: ='Folha 6_13'!C21 -> 0 | D21: ='Folha 6_13'!D21 -> 0 | E21: ='Folha 6_13'!E21 -> 0 | F21: ='Folha 6_13'!F21 -> 0 | G21: ='Folha 6_13'!G21 -> 0 | H21: ='Folha 6_13'!H21 -> 0 | J21: ------------ | K21: ------------ | L21: ------------ | M21: ------------ | N21: ------------ | O21: =SUM(C21:I21) -> 0
A22: ='Folha 1_13'!A22 -> D95 | B22: ='Folha 1_13'!B22 -> Inflação ano | C22: ='Folha 6_13'!C22 -> 0 | D22: ='Folha 6_13'!D22 -> 0 | E22: ='Folha 6_13'!E22 -> 0 | F22: ='Folha 6_13'!F22 -> 0 | G22: ='Folha 6_13'!G22 -> 0 | H22: ='Folha 6_13'!H22 -> 0 | J22: ------------ | K22: ------------ | L22: ------------ | M22: ------------ | N22: ------------ | O22: =SUM(C22:I22) -> 0
A23: ='Folha 1_13'!A23 -> D78 | B23: ='Folha 1_13'!B23 -> Número de não conformidades registradas em auditoria de terceria parte (NBR ISO 9001) | C23: ='Folha 6_13'!C23 -> 0 | D23: ='Folha 6_13'!D23 -> 0 | E23: ='Folha 6_13'!E23 -> 0 | F23: ='Folha 6_13'!F23 -> 0 | G23: ='Folha 6_13'!G23 -> 0 | H23: ='Folha 6_13'!H23 -> 0 | J23: ------------ | K23: ------------ | L23: ------------ | M23: ------------ | N23: ------------ | O23: =SUM(C23:I23) -> 0
A24: FQ-08.33 (anexo à IT-08.01.04) - RA - revisão 04 de 05/06/24 - Página 7/13

Sheet Folha 8_13
A1: INDICADORES DO SISTEMA DE GESTÃO DA QUALIDADE
A3: ='Folha 1_13'!$A$3 -> ANO: | F3: Mês: AGOSTO | I3: Atualizado em:
A5: 1. INDICADORES POR UNIDADE
A6: Nº | B6: Item | C6: TC | D6: CH | E6: TL | F6: FH | G6: CQ | H6: CE | I6: DG | J6: ITAL | K6: Observações
A7: ='Folha 1_13'!A7 -> I46 | B7: ='Folha 1_13'!B7 -> SAC solucionadas (%) | K7: -----------------------------------------------------------------
A8: ='Folha 1_13'!A8 -> I47 | B8: ='Folha 1_13'!B8 -> SAP solucionadas (%) | K8: -----------------------------------------------------------------
A9: ='Folha 1_13'!A9 -> I48 | B9: ='Folha 1_13'!B9 -> NCBI solucionadas (%) | K9: -----------------------------------------------------------------
A10: ='Folha 1_13'!A10 -> ------ | B10: ='Folha 1_13'!B10 -> Número de gestores | K10: -----------------------------------------------------------------
A11: 2. INDICADORES MENSAIS E/OU RESULTADOS GERAIS
A12: Nº | B12: Item | C12: JAN | D12: FEV | E12: MAR | F12: ABR | G12: MAI | H12: JUN | I12: JUL | J12: AGO | K12: SET | L12: OUT | M12: NOV | N12: DEZ | O12: TOTAL
A13: ='Folha 1_13'!A13 -> I12 | B13: ='Folha 1_13'!B13 -> Cumprimento às exigências fiscais municipais, federais e estaduais (número de falhas) | C13: ='Folha 7_13'!C13 -> 0 | D13: ='Folha 7_13'!D13 -> 0 | E13: ='Folha 7_13'!E13 -> 0 | F13: ='Folha 7_13'!F13 -> 0 | G13: ='Folha 7_13'!G13 -> 0 | H13: ='Folha 7_13'!H13 -> 0 | I13: ='Folha 7_13'!I13 -> 0 | K13: ------------ | L13: ------------ | M13: ------------ | N13: ------------ | O13: =J13 -> 0
A14: ='Folha 1_13'!A14 -> I49 | B14: ='Folha 1_13'!B14 -> Ensaios acreditados na ABNT NBR ISO/IEC 17025. (Nº) | C14: ='Folha 7_13'!C14 -> 0 | D14: ='Folha 7_13'!D14 -> 0 | E14: ='Folha 7_13'!E14 -> 0 | F14: ='Folha 7_13'!F14 -> 0 | G14: ='Folha 7_13'!G14 -> 0 | H14: ='Folha 7_13'!H14 -> 0 | I14: ='Folha 7_13'!I14 -> 0 | K14: ------------ | L14: ------------ | M14: ------------ | N14: ------------ | O14: =J14 -> 0
A15: ='Folha 1_13'!A15 -> I50 | B15: ='Folha 1_13'!B15 -> Habilitação do Ital junto à Reblas - Anvisa | C15: ='Folha 7_13'!C15 -> 0 | D15: ='Folha 7_13'!D15 -> 0 | E15: ='Folha 7_13'!E15 -> 0 | F15: ='Folha 7_13'!F15 -> 0 | G15: ='Folha 7_13'!G15 -> 0 | H15: ='Folha 7_13'!H15 -> 0 | I15: ='Folha 7_13'!I15 -> 0 | K15: ------------ | L15: ------------ | M15: ------------ | N15: ------------ | O15: =J15 -> 0
A16: ='Folha 1_13'!A16 -> I51 | B16: ='Folha 1_13'!B16 -> Certificação do Sistema de Gestão da Qualidade - NBR ISO 9001 (Nº) | C16: ='Folha 7_13'!C16 -> 0 | D16: ='Folha 7_13'!D16 -> 0 | E16: ='Folha 7_13'!E16 -> 0 | F16: ='Folha 7_13'!F16 -> 0 | G16: ='Folha 7_13'!G16 -> 0 | H16: ='Folha 7_13'!H16 -> 0 | I16: ='Folha 7_13'!I16 -> 0 | K16: ------------ | L16: ------------ | M16: ------------ | N16: ------------ | O16: =J16 -> 0
A17: ='Folha 1_13'!A17 -> I53 | B17: ='Folha 1_13'!B17 -> Qualificação de fornecedores (%) | C17: ='Folha 7_13'!C17 -> 0 | D17: ='Folha 7_13'!D17 -> 0 | E17: ='Folha 7_13'!E17 -> 0 | F17: ='Folha 7_13'!F17 -> 0 | G17: ='Folha 7_13'!G17 -> 0 | H17: ='Folha 7_13'!H17 -> 0 | I17: ='Folha 7_13'!I17 -> 0 | K17: ------------ | L17: ------------ | M17: ------------ | N17: ------------ | O17: =J17 -> 0
A18: ='Folha 1_13'!A18 -> I60 | B18: ='Folha 1_13'!B18 -> Consumo de água (m3) | C18: ='Folha 7_13'!C18 -> 0 | D18: ='Folha 7_13'!D18 -> 0 | E18: ='Folha 7_13'!E18 -> 0 | F18: ='Folha 7_13'!F18 -> 0 | G18: ='Folha 7_13'!G18 -> 0 | H18: ='Folha 7_13'!H18 -> 0 | I18: ='Folha 7_13'!I18 -> 0 | K18: ------------ | L18: ------------ | M18: ------------ | N18: ------------ | O18: =SUM(C18:J18) -> 0
A19: ='Folha 1_13'!A19 -> I61 | B19: ='Folha 1_13'!B19 -> Consumo de energia elétrica (kWh) | C19: ='Folha 7_13'!C19 -> 0 | D19: ='Folha 7_13'!D19 -> 0 | E19: ='Folha 7_13'!E19 -> 0 | F19: ='Folha 7_13'!F19 -> 0 | G19: ='Folha 7_13'!G19 -> 0 | H19: ='Folha 7_13'!H19 -> 0 | I19: ='Folha 7_13'!I19 -> 0 | K19: ------------ | L19: ------------ | M19: ------------ | N19: ------------ | O19: =SUM(C19:J19) -> 0
A20: ='Folha 1_13'!A20 -> I62 | B20: ='Folha 1_13'!B20 -> Ações de conscientização - meio ambiente por ano (Nº) | C20: ='Folha 7_13'!C20 -> 0 | D20: ='Folha 7_13'!D20 -> 0 | E20: ='Folha 7_13'!E20 -> 0 | F20: ='Folha 7_13'!F20 -> 0 | G20: ='Folha 7_13'!G20 -> 0 | H20: ='Folha 7_13'!H20 -> 0 | I20: ='Folha 7_13'!I20 -> 0 | K20: ------------ | L20: ------------ | M20: ------------ | N20: ------------ | O20: =SUM(C20:J20) -> 0
A21: ='Folha 1_13'!A21 -> I63 | B21: ='Folha 1_13'!B21 -> Denúncias procedentes registradas pela CIC (Ética) | C21: ='Folha 7_13'!C21 -> 0 | D21: ='Folha 7_13'!D21 -> 0 | E21: ='Folha 7_13'!E21 -> 0 | F21: ='Folha 7_13'!F21 -> 0 | G21: ='Folha 7_13'!G21 -> 0 | H21: ='Folha 7_13'!H21 -> 0 | I21: ='Folha 7_13'!I21 -> 0 | K21: ------------ | L21: ------------ | M21: ------------ | N21: ------------ | O21: =SUM(C21:J21) -> 0
A22: ='Folha 1_13'!A22 -> D95 | B22: ='Folha 1_13'!B22 -> Inflação ano | C22: ='Folha 7_13'!C22 -> 0 | D22: ='Folha 7_13'!D22 -> 0 | E22: ='Folha 7_13'!E22 -> 0 | F22: ='Folha 7_13'!F22 -> 0 | G22: ='Folha 7_13'!G22 -> 0 | H22: ='Folha 7_13'!H22 -> 0 | I22: ='Folha 7_13'!I22 -> 0 | K22: ------------ | L22: ------------ | M22: ------------ | N22: ------------ | O22: =SUM(C22:J22) -> 0
A23: ='Folha 1_13'!A23 -> D78 | B23: ='Folha 1_13'!B23 -> Número de não conformidades registradas em auditoria de terceria parte (NBR ISO 9001) | C23: ='Folha 7_13'!C23 -> 0 | D23: ='Folha 7_13'!D23 -> 0 | E23: ='Folha 7_13'!E23 -> 0 | F23: ='Folha 7_13'!F23 -> 0 | G23: ='Folha 7_13'!G23 -> 0 | H23: ='Folha 7_13'!H23 -> 0 | I23: ='Folha 7_13'!I23 -> 0 | K23: ------------ | L23: ------------ | M23: ------------ | N23: ------------ | O23: =SUM(C23:J23) -> 0
A24: FQ-08.33 (anexo à IT-08.01.04) - RA - revisão 04 de 05/06/24 - Página 8/13

Sheet Folha 9_13
A1: INDICADORES DO SISTEMA DE GESTÃO DA QUALIDADE
A3: ='Folha 1_13'!$A$3 -> ANO: | F3: Mês: SETEMBRO | I3: Atualizado em:
A5: 1. INDICADORES POR UNIDADE
A6: Nº | B6: Item | C6: TC | D6: CH | E6: TL | F6: FH | G6: CQ | H6: CE | I6: DG | J6: ITAL | K6: Observações
A7: ='Folha 1_13'!A7 -> I46 | B7: ='Folha 1_13'!B7 -> SAC solucionadas (%) | K7: -----------------------------------------------------------------
A8: ='Folha 1_13'!A8 -> I47 | B8: ='Folha 1_13'!B8 -> SAP solucionadas (%) | K8: -----------------------------------------------------------------
A9: ='Folha 1_13'!A9 -> I48 | B9: ='Folha 1_13'!B9 -> NCBI solucionadas (%) | K9: -----------------------------------------------------------------
A10: ='Folha 1_13'!A10 -> ------ | B10: ='Folha 1_13'!B10 -> Número de gestores | K10: -----------------------------------------------------------------
A11: 2. INDICADORES MENSAIS E/OU RESULTADOS GERAIS
A12: Nº | B12: Item | C12: JAN | D12: FEV | E12: MAR | F12: ABR | G12: MAI | H12: JUN | I12: JUL | J12: AGO | K12: SET | L12: OUT | M12: NOV | N12: DEZ | O12: TOTAL
A13: ='Folha 1_13'!A13 -> I12 | B13: ='Folha 1_13'!B13 -> Cumprimento às exigências fiscais municipais, federais e estaduais (número de falhas) | C13: ='Folha 8_13'!C13 -> 0 | D13: ='Folha 8_13'!D13 -> 0 | E13: ='Folha 8_13'!E13 -> 0 | F13: ='Folha 8_13'!F13 -> 0 | G13: ='Folha 8_13'!G13 -> 0 | H13: ='Folha 8_13'!H13 -> 0 | I13: ='Folha 8_13'!I13 -> 0 | J13: ='Folha 8_13'!J13 -> 0 | L13: ------------ | M13: ------------ | N13: ------------ | O13: =K13 -> 0
A14: ='Folha 1_13'!A14 -> I49 | B14: ='Folha 1_13'!B14 -> Ensaios acreditados na ABNT NBR ISO/IEC 17025. (Nº) | C14: ='Folha 8_13'!C14 -> 0 | D14: ='Folha 8_13'!D14 -> 0 | E14: ='Folha 8_13'!E14 -> 0 | F14: ='Folha 8_13'!F14 -> 0 | G14: ='Folha 8_13'!G14 -> 0 | H14: ='Folha 8_13'!H14 -> 0 | I14: ='Folha 8_13'!I14 -> 0 | J14: ='Folha 8_13'!J14 -> 0 | L14: ------------ | M14: ------------ | N14: ------------ | O14: =K14 -> 0
A15: ='Folha 1_13'!A15 -> I50 | B15: ='Folha 1_13'!B15 -> Habilitação do Ital junto à Reblas - Anvisa | C15: ='Folha 8_13'!C15 -> 0 | D15: ='Folha 8_13'!D15 -> 0 | E15: ='Folha 8_13'!E15 -> 0 | F15: ='Folha 8_13'!F15 -> 0 | G15: ='Folha 8_13'!G15 -> 0 | H15: ='Folha 8_13'!H15 -> 0 | I15: ='Folha 8_13'!I15 -> 0 | J15: ='Folha 8_13'!J15 -> 0 | L15: ------------ | M15: ------------ | N15: ------------ | O15: =K15 -> 0
A16: ='Folha 1_13'!A16 -> I51 | B16: ='Folha 1_13'!B16 -> Certificação do Sistema de Gestão da Qualidade - NBR ISO 9001 (Nº) | C16: ='Folha 8_13'!C16 -> 0 | D16: ='Folha 8_13'!D16 -> 0 | E16: ='Folha 8_13'!E16 -> 0 | F16: ='Folha 8_13'!F16 -> 0 | G16: ='Folha 8_13'!G16 -> 0 | H16: ='Folha 8_13'!H16 -> 0 | I16: ='Folha 8_13'!I16 -> 0 | J16: ='Folha 8_13'!J16 -> 0 | L16: ------------ | M16: ------------ | N16: ------------ | O16: =K16 -> 0
A17: ='Folha 1_13'!A17 -> I53 | B17: ='Folha 1_13'!B17 -> Qualificação de fornecedores (%) | C17: ='Folha 8_13'!C17 -> 0 | D17: ='Folha 8_13'!D17 -> 0 | E17: ='Folha 8_13'!E17 -> 0 | F17: ='Folha 8_13'!F17 -> 0 | G17: ='Folha 8_13'!G17 -> 0 | H17: ='Folha 8_13'!H17 -> 0 | I17: ='Folha 8_13'!I17 -> 0 | J17: ='Folha 8_13'!J17 -> 0 | L17: ------------ | M17: ------------ | N17: ------------ | O17: =K17 -> 0
A18: ='Folha 1_13'!A18 -> I60 | B18: ='Folha 1_13'!B18 -> Consumo de água (m3) | C18: ='Folha 8_13'!C18 -> 0 | D18: ='Folha 8_13'!D18 -> 0 | E18: ='Folha 8_13'!E18 -> 0 | F18: ='Folha 8_13'!F18 -> 0 | G18: ='Folha 8_13'!G18 -> 0 | H18: ='Folha 8_13'!H18 -> 0 | I18: ='Folha 8_13'!I18 -> 0 | J18: ='Folha 8_13'!J18 -> 0 | L18: ------------ | M18: ------------ | N18: ------------ | O18: =SUM(C18:K18) -> 0
A19: ='Folha 1_13'!A19 -> I61 | B19: ='Folha 1_13'!B19 -> Consumo de energia elétrica (kWh) | C19: ='Folha 8_13'!C19 -> 0 | D19: ='Folha 8_13'!D19 -> 0 | E19: ='Folha 8_13'!E19 -> 0 | F19: ='Folha 8_13'!F19 -> 0 | G19: ='Folha 8_13'!G19 -> 0 | H19: ='Folha 8_13'!H19 -> 0 | I19: ='Folha 8_13'!I19 -> 0 | J19: ='Folha 8_13'!J19 -> 0 | L19: ------------ | M19: ------------ | N19: ------------ | O19: =SUM(C19:K19) -> 0
A20: ='Folha 1_13'!A20 -> I62 | B20: ='Folha 1_13'!B20 -> Ações de conscientização - meio ambiente por ano (Nº) | C20: ='Folha 8_13'!C20 -> 0 | D20: ='Folha 8_13'!D20 -> 0 | E20: ='Folha 8_13'!E20 -> 0 | F20: ='Folha 8_13'!F20 -> 0 | G20: ='Folha 8_13'!G20 -> 0 | H20: ='Folha 8_13'!H20 -> 0 | I20: ='Folha 8_13'!I20 -> 0 | J20: ='Folha 8_13'!J20 -> 0 | L20: ------------ | M20: ------------ | N20: ------------ | O20: =SUM(C20:K20) -> 0
A21: ='Folha 1_13'!A21 -> I63 | B21: ='Folha 1_13'!B21 -> Denúncias procedentes registradas pela CIC (Ética) | C21: ='Folha 8_13'!C21 -> 0 | D21: ='Folha 8_13'!D21 -> 0 | E21: ='Folha 8_13'!E21 -> 0 | F21: ='Folha 8_13'!F21 -> 0 | G21: ='Folha 8_13'!G21 -> 0 | H21: ='Folha 8_13'!H21 -> 0 | I21: ='Folha 8_13'!I21 -> 0 | J21: ='Folha 8_13'!J21 -> 0 | L21: ------------ | M21: ------------ | N21: ------------ | O21: =SUM(C21:K21) -> 0
A22: ='Folha 1_13'!A22 -> D95 | B22: ='Folha 1_13'!B22 -> Inflação ano | C22: ='Folha 8_13'!C22 -> 0 | D22: ='Folha 8_13'!D22 -> 0 | E22: ='Folha 8_13'!E22 -> 0 | F22: ='Folha 8_13'!F22 -> 0 | G22: ='Folha 8_13'!G22 -> 0 | H22: ='Folha 8_13'!H22 -> 0 | I22: ='Folha 8_13'!I22 -> 0 | J22: ='Folha 8_13'!J22 -> 0 | L22: ------------ | M22: ------------ | N22: ------------ | O22: =SUM(C22:K22) -> 0
A23: ='Folha 1_13'!A23 -> D78 | B23: ='Folha 1_13'!B23 -> Número de não conformidades registradas em auditoria de terceria parte (NBR ISO 9001) | C23: ='Folha 8_13'!C23 -> 0 | D23: ='Folha 8_13'!D23 -> 0 | E23: ='Folha 8_13'!E23 -> 0 | F23: ='Folha 8_13'!F23 -> 0 | G23: ='Folha 8_13'!G23 -> 0 | H23: ='Folha 8_13'!H23 -> 0 | I23: ='Folha 8_13'!I23 -> 0 | J23: ='Folha 8_13'!J23 -> 0 | L23: ------------ | M23: ------------ | N23: ------------ | O23: =SUM(C23:K23) -> 0
A24: FQ-08.33 (anexo à IT-08.01.04) - RA - revisão 04 de 05/06/24 - Página 9/13

Sheet Folha 10_13
A1: INDICADORES DO SISTEMA DE GESTÃO DA QUALIDADE
A3: ='Folha 1_13'!$A$3 -> ANO: | F3: Mês: OUTUBRO | I3: Atualizado em:
A5: 1. INDICADORES POR UNIDADE
A6: Nº | B6: Item | C6: TC | D6: CH | E6: TL | F6: FH | G6: CQ | H6: CE | I6: DG | J6: ITAL | K6: Observações
A7: ='Folha 1_13'!A7 -> I46 | B7: ='Folha 1_13'!B7 -> SAC solucionadas (%) | K7: -----------------------------------------------------------------
A8: ='Folha 1_13'!A8 -> I47 | B8: ='Folha 1_13'!B8 -> SAP solucionadas (%) | K8: -----------------------------------------------------------------
A9: ='Folha 1_13'!A9 -> I48 | B9: ='Folha 1_13'!B9 -> NCBI solucionadas (%) | K9: -----------------------------------------------------------------
A10: ='Folha 1_13'!A10 -> ------ | B10: ='Folha 1_13'!B10 -> Número de gestores | K10: -----------------------------------------------------------------
A11: 2. INDICADORES MENSAIS E/OU RESULTADOS GERAIS
A12: Nº | B12: Item | C12: JAN | D12: FEV | E12: MAR | F12: ABR | G12: MAI | H12: JUN | I12: JUL | J12: AGO | K12: SET | L12: OUT | M12: NOV | N12: DEZ | O12: TOTAL
A13: ='Folha 1_13'!A13 -> I12 | B13: ='Folha 1_13'!B13 -> Cumprimento às exigências fiscais municipais, federais e estaduais (número de falhas) | C13: ='Folha 9_13'!C13 -> 0 | D13: ='Folha 9_13'!D13 -> 0 | E13: ='Folha 9_13'!E13 -> 0 | F13: ='Folha 9_13'!F13 -> 0 | G13: ='Folha 9_13'!G13 -> 0 | H13: ='Folha 9_13'!H13 -> 0 | I13: ='Folha 9_13'!I13 -> 0 | J13: ='Folha 9_13'!J13 -> 0 | K13: ='Folha 9_13'!K13 -> 0 | M13: ------------ | N13: ------------ | O13: =L13 -> 0
A14: ='Folha 1_13'!A14 -> I49 | B14: ='Folha 1_13'!B14 -> Ensaios acreditados na ABNT NBR ISO/IEC 17025. (Nº) | C14: ='Folha 9_13'!C14 -> 0 | D14: ='Folha 9_13'!D14 -> 0 | E14: ='Folha 9_13'!E14 -> 0 | F14: ='Folha 9_13'!F14 -> 0 | G14: ='Folha 9_13'!G14 -> 0 | H14: ='Folha 9_13'!H14 -> 0 | I14: ='Folha 9_13'!I14 -> 0 | J14: ='Folha 9_13'!J14 -> 0 | K14: ='Folha 9_13'!K14 -> 0 | M14: ------------ | N14: ------------ | O14: =L14 -> 0
A15: ='Folha 1_13'!A15 -> I50 | B15: ='Folha 1_13'!B15 -> Habilitação do Ital junto à Reblas - Anvisa | C15: ='Folha 9_13'!C15 -> 0 | D15: ='Folha 9_13'!D15 -> 0 | E15: ='Folha 9_13'!E15 -> 0 | F15: ='Folha 9_13'!F15 -> 0 | G15: ='Folha 9_13'!G15 -> 0 | H15: ='Folha 9_13'!H15 -> 0 | I15: ='Folha 9_13'!I15 -> 0 | J15: ='Folha 9_13'!J15 -> 0 | K15: ='Folha 9_13'!K15 -> 0 | M15: ------------ | N15: ------------ | O15: =L15 -> 0
A16: ='Folha 1_13'!A16 -> I51 | B16: ='Folha 1_13'!B16 -> Certificação do Sistema de Gestão da Qualidade - NBR ISO 9001 (Nº) | C16: ='Folha 9_13'!C16 -> 0 | D16: ='Folha 9_13'!D16 -> 0 | E16: ='Folha 9_13'!E16 -> 0 | F16: ='Folha 9_13'!F16 -> 0 | G16: ='Folha 9_13'!G16 -> 0 | H16: ='Folha 9_13'!H16 -> 0 | I16: ='Folha 9_13'!I16 -> 0 | J16: ='Folha 9_13'!J16 -> 0 | K16: ='Folha 9_13'!K16 -> 0 | M16: ------------ | N16: ------------ | O16: =L16 -> 0
A17: ='Folha 1_13'!A17 -> I53 | B17: ='Folha 1_13'!B17 -> Qualificação de fornecedores (%) | C17: ='Folha 9_13'!C17 -> 0 | D17: ='Folha 9_13'!D17 -> 0 | E17: ='Folha 9_13'!E17 -> 0 | F17: ='Folha 9_13'!F17 -> 0 | G17: ='Folha 9_13'!G17 -> 0 | H17: ='Folha 9_13'!H17 -> 0 | I17: ='Folha 9_13'!I17 -> 0 | J17: ='Folha 9_13'!J17 -> 0 | K17: ='Folha 9_13'!K17 -> 0 | M17: ------------ | N17: ------------ | O17: =L17 -> 0
A18: ='Folha 1_13'!A18 -> I60 | B18: ='Folha 1_13'!B18 -> Consumo de água (m3) | C18: ='Folha 9_13'!C18 -> 0 | D18: ='Folha 9_13'!D18 -> 0 | E18: ='Folha 9_13'!E18 -> 0 | F18: ='Folha 9_13'!F18 -> 0 | G18: ='Folha 9_13'!G18 -> 0 | H18: ='Folha 9_13'!H18 -> 0 | I18: ='Folha 9_13'!I18 -> 0 | J18: ='Folha 9_13'!J18 -> 0 | K18: ='Folha 9_13'!K18 -> 0 | M18: ------------ | N18: ------------ | O18: =SUM(C18:L18) -> 0
A19: ='Folha 1_13'!A19 -> I61 | B19: ='Folha 1_13'!B19 -> Consumo de energia elétrica (kWh) | C19: ='Folha 9_13'!C19 -> 0 | D19: ='Folha 9_13'!D19 -> 0 | E19: ='Folha 9_13'!E19 -> 0 | F19: ='Folha 9_13'!F19 -> 0 | G19: ='Folha 9_13'!G19 -> 0 | H19: ='Folha 9_13'!H19 -> 0 | I19: ='Folha 9_13'!I19 -> 0 | J19: ='Folha 9_13'!J19 -> 0 | K19: ='Folha 9_13'!K19 -> 0 | M19: ------------ | N19: ------------ | O19: =SUM(C19:L19) -> 0
A20: ='Folha 1_13'!A20 -> I62 | B20: ='Folha 1_13'!B20 -> Ações de conscientização - meio ambiente por ano (Nº) | C20: ='Folha 9_13'!C20 -> 0 | D20: ='Folha 9_13'!D20 -> 0 | E20: ='Folha 9_13'!E20 -> 0 | F20: ='Folha 9_13'!F20 -> 0 | G20: ='Folha 9_13'!G20 -> 0 | H20: ='Folha 9_13'!H20 -> 0 | I20: ='Folha 9_13'!I20 -> 0 | J20: ='Folha 9_13'!J20 -> 0 | K20: ='Folha 9_13'!K20 -> 0 | M20: ------------ | N20: ------------ | O20: =SUM(C20:L20) -> 0
A21: ='Folha 1_13'!A21 -> I63 | B21: ='Folha 1_13'!B21 -> Denúncias procedentes registradas pela CIC (Ética) | C21: ='Folha 9_13'!C21 -> 0 | D21: ='Folha 9_13'!D21 -> 0 | E21: ='Folha 9_13'!E21 -> 0 | F21: ='Folha 9_13'!F21 -> 0 | G21: ='Folha 9_13'!G21 -> 0 | H21: ='Folha 9_13'!H21 -> 0 | I21: ='Folha 9_13'!I21 -> 0 | J21: ='Folha 9_13'!J21 -> 0 | K21: ='Folha 9_13'!K21 -> 0 | M21: ------------ | N21: ------------ | O21: =SUM(C21:L21) -> 0
A22: ='Folha 1_13'!A22 -> D95 | B22: ='Folha 1_13'!B22 -> Inflação ano | C22: ='Folha 9_13'!C22 -> 0 | D22: ='Folha 9_13'!D22 -> 0 | E22: ='Folha 9_13'!E22 -> 0 | F22: ='Folha 9_13'!F22 -> 0 | G22: ='Folha 9_13'!G22 -> 0 | H22: ='Folha 9_13'!H22 -> 0 | I22: ='Folha 9_13'!I22 -> 0 | J22: ='Folha 9_13'!J22 -> 0 | K22: ='Folha 9_13'!K22 -> 0 | M22: ------------ | N22: ------------ | O22: =SUM(C22:L22) -> 0
A23: ='Folha 1_13'!A23 -> D78 | B23: ='Folha 1_13'!B23 -> Número de não conformidades registradas em auditoria de terceria parte (NBR ISO 9001) | C23: ='Folha 9_13'!C23 -> 0 | D23: ='Folha 9_13'!D23 -> 0 | E23: ='Folha 9_13'!E23 -> 0 | F23: ='Folha 9_13'!F23 -> 0 | G23: ='Folha 9_13'!G23 -> 0 | H23: ='Folha 9_13'!H23 -> 0 | I23: ='Folha 9_13'!I23 -> 0 | J23: ='Folha 9_13'!J23 -> 0 | K23: ='Folha 9_13'!K23 -> 0 | M23: ------------ | N23: ------------ | O23: =SUM(C23:L23) -> 0
A24: FQ-08.33 (anexo à IT-08.01.04) - RA - revisão 04 de 05/06/24 - Página 10/13

Sheet Folha 11_13
A1: INDICADORES DO SISTEMA DE GESTÃO DA QUALIDADE
A3: ='Folha 1_13'!$A$3 -> ANO: | F3: Mês: NOVEMBRO | I3: Atualizado em:
A5: 1. INDICADORES POR UNIDADE
A6: Nº | B6: Item | C6: TC | D6: CH | E6: TL | F6: FH | G6: CQ | H6: CE | I6: DG | J6: ITAL | K6: Observações
A7: ='Folha 1_13'!A7 -> I46 | B7: ='Folha 1_13'!B7 -> SAC solucionadas (%) | K7: -----------------------------------------------------------------
A8: ='Folha 1_13'!A8 -> I47 | B8: ='Folha 1_13'!B8 -> SAP solucionadas (%) | K8: -----------------------------------------------------------------
A9: ='Folha 1_13'!A9 -> I48 | B9: ='Folha 1_13'!B9 -> NCBI solucionadas (%) | K9: -----------------------------------------------------------------
A10: ='Folha 1_13'!A10 -> ------ | B10: ='Folha 1_13'!B10 -> Número de gestores | K10: -----------------------------------------------------------------
A11: 2. INDICADORES MENSAIS E/OU RESULTADOS GERAIS
A12: Nº | B12: Item | C12: JAN | D12: FEV | E12: MAR | F12: ABR | G12: MAI | H12: JUN | I12: JUL | J12: AGO | K12: SET | L12: OUT | M12: NOV | N12: DEZ | O12: TOTAL
A13: ='Folha 1_13'!A13 -> I12 | B13: ='Folha 1_13'!B13 -> Cumprimento às exigências fiscais municipais, federais e estaduais (número de falhas) | C13: ='Folha 10_13'!C13 -> 0 | D13: ='Folha 10_13'!D13 -> 0 | E13: ='Folha 10_13'!E13 -> 0 | F13: ='Folha 10_13'!F13 -> 0 | G13: ='Folha 10_13'!G13 -> 0 | H13: ='Folha 10_13'!H13 -> 0 | I13: ='Folha 10_13'!I13 -> 0 | J13: ='Folha 10_13'!J13 -> 0 | ... L13: ='Folha 10_13'!L13 -> 0 | N13: ------------ | O13: =M13 -> 0
A14: ='Folha 1_13'!A14 -> I49 | B14: ='Folha 1_13'!B14 -> Ensaios acreditados na ABNT NBR ISO/IEC 17025. (Nº) | C14: ='Folha 10_13'!C14 -> 0 | D14: ='Folha 10_13'!D14 -> 0 | E14: ='Folha 10_13'!E14 -> 0 | F14: ='Folha 10_13'!F14 -> 0 | G14: ='Folha 10_13'!G14 -> 0 | H14: ='Folha 10_13'!H14 -> 0 | I14: ='Folha 10_13'!I14 -> 0 | J14: ='Folha 10_13'!J14 -> 0 | ... L14: ='Folha 10_13'!L14 -> 0 | N14: ------------ | O14: =M14 -> 0
A15: ='Folha 1_13'!A15 -> I50 | B15: ='Folha 1_13'!B15 -> Habilitação do Ital junto à Reblas - Anvisa | C15: ='Folha 10_13'!C15 -> 0 | D15: ='Folha 10_13'!D15 -> 0 | E15: ='Folha 10_13'!E15 -> 0 | F15: ='Folha 10_13'!F15 -> 0 | G15: ='Folha 10_13'!G15 -> 0 | H15: ='Folha 10_13'!H15 -> 0 | I15: ='Folha 10_13'!I15 -> 0 | J15: ='Folha 10_13'!J15 -> 0 | ... L15: ='Folha 10_13'!L15 -> 0 | N15: ------------ | O15: =M15 -> 0
A16: ='Folha 1_13'!A16 -> I51 | B16: ='Folha 1_13'!B16 -> Certificação do Sistema de Gestão da Qualidade - NBR ISO 9001 (Nº) | C16: ='Folha 10_13'!C16 -> 0 | D16: ='Folha 10_13'!D16 -> 0 | E16: ='Folha 10_13'!E16 -> 0 | F16: ='Folha 10_13'!F16 -> 0 | G16: ='Folha 10_13'!G16 -> 0 | H16: ='Folha 10_13'!H16 -> 0 | I16: ='Folha 10_13'!I16 -> 0 | J16: ='Folha 10_13'!J16 -> 0 | ... L16: ='Folha 10_13'!L16 -> 0 | N16: ------------ | O16: =M16 -> 0
A17: ='Folha 1_13'!A17 -> I53 | B17: ='Folha 1_13'!B17 -> Qualificação de fornecedores (%) | C17: ='Folha 10_13'!C17 -> 0 | D17: ='Folha 10_13'!D17 -> 0 | E17: ='Folha 10_13'!E17 -> 0 | F17: ='Folha 10_13'!F17 -> 0 | G17: ='Folha 10_13'!G17 -> 0 | H17: ='Folha 10_13'!H17 -> 0 | I17: ='Folha 10_13'!I17 -> 0 | J17: ='Folha 10_13'!J17 -> 0 | ... L17: ='Folha 10_13'!L17 -> 0 | N17: ------------ | O17: =M17 -> 0
A18: ='Folha 1_13'!A18 -> I60 | B18: ='Folha 1_13'!B18 -> Consumo de água (m3) | C18: ='Folha 10_13'!C18 -> 0 | D18: ='Folha 10_13'!D18 -> 0 | E18: ='Folha 10_13'!E18 -> 0 | F18: ='Folha 10_13'!F18 -> 0 | G18: ='Folha 10_13'!G18 -> 0 | H18: ='Folha 10_13'!H18 -> 0 | I18: ='Folha 10_13'!I18 -> 0 | J18: ='Folha 10_13'!J18 -> 0 | ... L18: ='Folha 10_13'!L18 -> 0 | N18: ------------ | O18: =SUM(C18:M18) -> 0
A19: ='Folha 1_13'!A19 -> I61 | B19: ='Folha 1_13'!B19 -> Consumo de energia elétrica (kWh) | C19: ='Folha 10_13'!C19 -> 0 | D19: ='Folha 10_13'!D19 -> 0 | E19: ='Folha 10_13'!E19 -> 0 | F19: ='Folha 10_13'!F19 -> 0 | G19: ='Folha 10_13'!G19 -> 0 | H19: ='Folha 10_13'!H19 -> 0 | I19: ='Folha 10_13'!I19 -> 0 | J19: ='Folha 10_13'!J19 -> 0 | ... L19: ='Folha 10_13'!L19 -> 0 | N19: ------------ | O19: =SUM(C19:M19) -> 0
A20: ='Folha 1_13'!A20 -> I62 | B20: ='Folha 1_13'!B20 -> Ações de conscientização - meio ambiente por ano (Nº) | C20: ='Folha 10_13'!C20 -> 0 | D20: ='Folha 10_13'!D20 -> 0 | E20: ='Folha 10_13'!E20 -> 0 | F20: ='Folha 10_13'!F20 -> 0 | G20: ='Folha 10_13'!G20 -> 0 | H20: ='Folha 10_13'!H20 -> 0 | I20: ='Folha 10_13'!I20 -> 0 | J20: ='Folha 10_13'!J20 -> 0 | ... L20: ='Folha 10_13'!L20 -> 0 | N20: ------------ | O20: =SUM(C20:M20) -> 0
A21: ='Folha 1_13'!A21 -> I63 | B21: ='Folha 1_13'!B21 -> Denúncias procedentes registradas pela CIC (Ética) | C21: ='Folha 10_13'!C21 -> 0 | D21: ='Folha 10_13'!D21 -> 0 | E21: ='Folha 10_13'!E21 -> 0 | F21: ='Folha 10_13'!F21 -> 0 | G21: ='Folha 10_13'!G21 -> 0 | H21: ='Folha 10_13'!H21 -> 0 | I21: ='Folha 10_13'!I21 -> 0 | J21: ='Folha 10_13'!J21 -> 0 | ... L21: ='Folha 10_13'!L21 -> 0 | N21: ------------ | O21: =SUM(C21:M21) -> 0
A22: ='Folha 1_13'!A22 -> D95 | B22: ='Folha 1_13'!B22 -> Inflação ano | C22: ='Folha 10_13'!C22 -> 0 | D22: ='Folha 10_13'!D22 -> 0 | E22: ='Folha 10_13'!E22 -> 0 | F22: ='Folha 10_13'!F22 -> 0 | G22: ='Folha 10_13'!G22 -> 0 | H22: ='Folha 10_13'!H22 -> 0 | I22: ='Folha 10_13'!I22 -> 0 | J22: ='Folha 10_13'!J22 -> 0 | ... L22: ='Folha 10_13'!L22 -> 0 | N22: ------------ | O22: =SUM(C22:M22) -> 0
